Workbook

Sheet Instructions
B2: How to use this schedule file
B3: Read this page once before you type anything. It takes about five minutes.
B5: WHAT THIS FILE IS
B6: This file holds the schedule for the whole weekend.
B7: The app reads this file. Then it shows each person only their own schedule on their phone.
B9: If you follow the rules on this page, the app reads the file correctly.
B10: If you break the rules, the app may show someone the wrong time, or show them nothing at all.
B12: STEP 1 — SET THE DATE
B13: Type the date of the Friday of your event in the yellow box.
B14: Event Friday date | C14: 46241
B15: You only do this once. Every day tab works out its own date from this one box.
B16: It even handles the hours after midnight, so nothing lands on the wrong day.
B18: STEP 2 — LEARN THE TABS
B19: The tabs are at the bottom of the window. Here is what each one holds.
B21: Instructions | C21: This page.
B22: Teams | C22: The eight teams. Also the show order, which you fill in later.
B23: People | C23: Every board member, liaison, judge, videographer and RAS rep.
B24: Roster | C24: Every dancer.
B25: Thursday, Friday, | C25: The schedule for each day. One row per person or group.
B26: Saturday, Sunday
B27: Sequences | C27: The recipe for anything that repeats team by team.
B28: Slot Times | C28: When each team starts its turn. Fix a running-late day here.
B29: Team Blocks | C29: Calculated for you. The team schedules the app reads. Never type here.
B30: Timeline | C30: Tells you whether the day still fits. Check it after any change.
B31: Airport | C31: Who is flying, when, and who is driving them.
B33: STEP 3 — FILL IN THE TABS, IN THIS ORDER
B34: Do not skip ahead. Each tab uses what you typed in the ones before it.
B36: 1. Teams | C36: Type each team name and short name. Leave Show Order empty for now.
B37: 2. People | C37: Add one row for each board member, liaison, judge, videographer and RAS rep. Do not put dancers here.
C38: Fill in ID, Full Name, Group, Phone, Email and Type.
C39: If the person is a liaison, you must also pick their Team from the dropdown. If you skip this, they will not show up on any day tab.
C40: Never type in the Key column. It fills itself in.
B41: 3. Roster | C41: Add one row for each dancer. Pick their team from the dropdown. Put Yes in the Captain? column for captains.
B42: 4. Day tabs | C42: Fill in Thursday, Friday, Saturday and Sunday. See the next two sections.
B43: 5. Show order | C43: After the draw, go back to Teams and type each team's number, 1 to 8. Saturday then fills itself in.
B44: 6. Check it | C44: Use the checklist at the bottom of this page before you upload.
B46: Spell each name on the People tab the way you want it to appear on that person's phone. The day tabs copy it exactly.
B48: STEP 4 — HOW TO ADD SOMETHING TO A DAY
B49: A day tab is a big grid. Times run across the top. Names run down the left side.
B51: 1. Find the person's row.
...

Sheet People
A1: ID | B1: Full Name | C1: Group | D1: Team | E1: Phone | F1: Email | G1: Type | H1: Key (auto)
A2: BRD-01 | B2: Example Director | C2: Directors | E2: 555-0100 | F2: director@example.edu | G2: board | H2: =IF(OR($G2<>"liaison",$D2=""),"",$D2&"#"&COUNTIFS($D$2:$D2,$D2,$G$2:$G2,"liaison"))
A3: LIA-01 | B3: Example Liaison One | C3: Liaisons | D3: UNC Taar Heel Raas | E3: 555-0101 | F3: lia1@example.edu | G3: liaison | H3: =IF(OR($G3<>"liaison",$D3=""),"",$D3&"#"&COUNTIFS($D$2:$D3,$D3,$G$2:$G3,"liaison")) -> UNC Taar Heel Raas#1
A4: LIA-02 | B4: Example Liaison Two | C4: Liaisons | D4: UNC Taar Heel Raas | E4: 555-0102 | F4: lia2@example.edu | G4: liaison | H4: =IF(OR($G4<>"liaison",$D4=""),"",$D4&"#"&COUNTIFS($D$2:$D4,$D4,$G$2:$G4,"liaison")) -> UNC Taar Heel Raas#2
A5: LIA-03 | B5: Example Liaison Three | C5: Liaisons | D5: UNC Taar Heel Raas | E5: 555-0103 | F5: lia3@example.edu | G5: liaison | H5: =IF(OR($G5<>"liaison",$D5=""),"",$D5&"#"&COUNTIFS($D$2:$D5,$D5,$G$2:$G5,"liaison")) -> UNC Taar Heel Raas#3
A6: JDG-01 | B6: Example Judge | C6: Judging | E6: 555-0104 | F6: judge@example.com | G6: judge | H6: =IF(OR($G6<>"liaison",$D6=""),"",$D6&"#"&COUNTIFS($D$2:$D6,$D6,$G$2:$G6,"liaison"))
A7: VID-01 | B7: Example Videographer | C7: External | E7: 555-0105 | F7: video@example.com | G7: videographer | H7: =IF(OR($G7<>"liaison",$D7=""),"",$D7&"#"&COUNTIFS($D$2:$D7,$D7,$G$2:$G7,"liaison"))
H8: =IF(OR($G8<>"liaison",$D8=""),"",$D8&"#"&COUNTIFS($D$2:$D8,$D8,$G$2:$G8,"liaison"))
H9: =IF(OR($G9<>"liaison",$D9=""),"",$D9&"#"&COUNTIFS($D$2:$D9,$D9,$G$2:$G9,"liaison"))
H10: =IF(OR($G10<>"liaison",$D10=""),"",$D10&"#"&COUNTIFS($D$2:$D10,$D10,$G$2:$G10,"liaison"))
H11: =IF(OR($G11<>"liaison",$D11=""),"",$D11&"#"&COUNTIFS($D$2:$D11,$D11,$G$2:$G11,"liaison"))
H12: =IF(OR($G12<>"liaison",$D12=""),"",$D12&"#"&COUNTIFS($D$2:$D12,$D12,$G$2:$G12,"liaison"))
H13: =IF(OR($G13<>"liaison",$D13=""),"",$D13&"#"&COUNTIFS($D$2:$D13,$D13,$G$2:$G13,"liaison"))
H14: =IF(OR($G14<>"liaison",$D14=""),"",$D14&"#"&COUNTIFS($D$2:$D14,$D14,$G$2:$G14,"liaison"))
H15: =IF(OR($G15<>"liaison",$D15=""),"",$D15&"#"&COUNTIFS($D$2:$D15,$D15,$G$2:$G15,"liaison"))
H16: =IF(OR($G16<>"liaison",$D16=""),"",$D16&"#"&COUNTIFS($D$2:$D16,$D16,$G$2:$G16,"liaison"))
H17: =IF(OR($G17<>"liaison",$D17=""),"",$D17&"#"&COUNTIFS($D$2:$D17,$D17,$G$2:$G17,"liaison"))
H18: =IF(OR($G18<>"liaison",$D18=""),"",$D18&"#"&COUNTIFS($D$2:$D18,$D18,$G$2:$G18,"liaison"))
H19: =IF(OR($G19<>"liaison",$D19=""),"",$D19&"#"&COUNTIFS($D$2:$D19,$D19,$G$2:$G19,"liaison"))
... H199: =IF(OR($G199<>"liaison",$D199=""),"",$D199&"#"&COUNTIFS($D$2:$D199,$D199,$G$2:$G199,"liaison"))
A201: Set Type to "liaison" and pick a Team, and that person appears on every day tab automatically — the first five rows for a team become its liaisons 1 to 5.
A202: Key is computed. Do not type in it.

Sheet Teams
A1: ID | B1: Team Name | C1: Abbrev | D1: Show Order | E1: Check | F1: Captain(s) | G1: Liaison Contact
A2: TM-UNC | B2: UNC Taar Heel Raas | C2: UNC | E2: =IF($D2="","",IF(COUNTIF($D$2:$D$9,$D2)>1,"DUPLICATE","OK"))
A3: TM-ILL | B3: Illini Raas | C3: Illini | E3: =IF($D3="","",IF(COUNTIF($D$2:$D$9,$D3)>1,"DUPLICATE","OK"))
A4: TM-UTD | B4: UTD Taraas | C4: UTD | E4: =IF($D4="","",IF(COUNTIF($D$2:$D$9,$D4)>1,"DUPLICATE","OK"))
A5: TM-UVA | B5: UVA Hooraas | C5: UVA | E5: =IF($D5="","",IF(COUNTIF($D$2:$D$9,$D5)>1,"DUPLICATE","OK"))
A6: TM-UMD | B6: UMD Entouraas | C6: UMD | E6: =IF($D6="","",IF(COUNTIF($D$2:$D$9,$D6)>1,"DUPLICATE","OK"))
A7: TM-UMI | B7: Michigan Wolveraas | C7: UMich | E7: =IF($D7="","",IF(COUNTIF($D$2:$D$9,$D7)>1,"DUPLICATE","OK"))
A8: TM-MSU | B8: MSU Raasparty | C8: MSU | E8: =IF($D8="","",IF(COUNTIF($D$2:$D$9,$D8)>1,"DUPLICATE","OK"))
A9: TM-GT | B9: GT Ramblin Raas | C9: GT | E9: =IF($D9="","",IF(COUNTIF($D$2:$D$9,$D9)>1,"DUPLICATE","OK"))
A11: Show Order is the running order, 1-8. Leave it blank until the draw — Saturday's grid is built against slots, not teams, so it can be filled in before you know who is where.
A12: Fill this column in and Saturday resolves itself: every "Show Order N" row picks up the team sitting in slot N, and the app imports it as that team's schedule.
A13: Check flags a slot given to two teams. Every row must read OK before you upload.

Sheet Roster
A1: First Name | B1: Last Name | C1: Team | D1: Phone | E1: Email | F1: Captain? | G1: Dietary Restrictions | H1: T-Shirt Size
A2: Example | B2: Dancer | C2: UNC Taar Heel Raas | D2: 555-0110 | E2: dancer@example.edu | F2: No | G2: Vegetarian | H2: M
A261: One row per dancer, Team as a column — replaces last year's eight per-team tabs. Captain? replaces the asterisk on the first name.

Sheet Thursday
A1: Group | B1: Name | C1: ID | D1: =Instructions!$C$14-1 -> 46240 | AZ1: =Instructions!$C$14 -> 46241
D2: 0.5 | E2: 0.51041667 | F2: 0.52083333 | G2: 0.53125 | H2: 0.54166667 | I2: 0.55208333 | J2: 0.5625 | K2: 0.57291667 | L2: 0.58333333 | M2: 0.59375 | N2: 0.60416667 | O2: 0.61458333 | P2: 0.625 | Q2: 0.63541667 | R2: 0.64583333 | S2: 0.65625 | T2: 0.66666667 | U2: 0.67708333 | V2: 0.6875 | W2: 0.69791667 | X2: 0.70833333 | Y2: 0.71875 | Z2: 0.72916667 | AA2: 0.73958333 | AB2: 0.75 | AC2: 0.76041667 | AD2: 0.77083333 | AE2: 0.78125 | AF2: 0.79166667 | AG2: 0.80208333 | AH2: 0.8125 | AI2: 0.82291667 | AJ2: 0.83333333 | AK2: 0.84375 | AL2: 0.85416667 | AM2: 0.86458333 | AN2: 0.875 | AO2: 0.88541667 | AP2: 0.89583333 | AQ2: 0.90625 | AR2: 0.91666667 | AS2: 0.92708333 | AT2: 0.9375 | AU2: 0.94791667 | AV2: 0.95833333 | AW2: 0.96875 | AX2: 0.97916667 | AY2: 0.98958333 | AZ2: 0 | BA2: 0.010416667 | BB2: 0.020833333 | BC2: 0.03125 | BD2: 0.041666667 | BE2: 0.052083333 | BF2: 0.0625 | BG2: 0.072916667 | BH2: 0.083333333 | BI2: 0.09375 | BJ2: 0.10416667 | BK2: 0.11458333
A3: BOARD MEMBERS
A4: Directors | C4: =IF(TRIM($B4)="","",IFERROR(INDEX(People!$A$2:$A$199,MATCH(TRIM($B4),People!$B$2:$B$199,0)),IFERROR(INDEX(Teams!$A$2:$A$9,MATCH(TRIM($B4),Teams!$B$2:$B$9,0)),"?? CHECK NAME")))
C5: =IF(TRIM($B5)="","",IFERROR(INDEX(People!$A$2:$A$199,MATCH(TRIM($B5),People!$B$2:$B$199,0)),IFERROR(INDEX(Teams!$A$2:$A$9,MATCH(TRIM($B5),Teams!$B$2:$B$9,0)),"?? CHECK NAME")))
C6: =IF(TRIM($B6)="","",IFERROR(INDEX(People!$A$2:$A$199,MATCH(TRIM($B6),People!$B$2:$B$199,0)),IFERROR(INDEX(Teams!$A$2:$A$9,MATCH(TRIM($B6),Teams!$B$2:$B$9,0)),"?? CHECK NAME")))
C7: =IF(TRIM($B7)="","",IFERROR(INDEX(People!$A$2:$A$199,MATCH(TRIM($B7),People!$B$2:$B$199,0)),IFERROR(INDEX(Teams!$A$2:$A$9,MATCH(TRIM($B7),Teams!$B$2:$B$9,0)),"?? CHECK NAME")))
C8: =IF(TRIM($B8)="","",IFERROR(INDEX(People!$A$2:$A$199,MATCH(TRIM($B8),People!$B$2:$B$199,0)),IFERROR(INDEX(Teams!$A$2:$A$9,MATCH(TRIM($B8),Teams!$B$2:$B$9,0)),"?? CHECK NAME")))
A9: Senior Advisors | C9: =IF(TRIM($B9)="","",IFERROR(INDEX(People!$A$2:$A$199,MATCH(TRIM($B9),People!$B$2:$B$199,0)),IFERROR(INDEX(Teams!$A$2:$A$9,MATCH(TRIM($B9),Teams!$B$2:$B$9,0)),"?? CHECK NAME")))
C10: =IF(TRIM($B10)="","",IFERROR(INDEX(People!$A$2:$A$199,MATCH(TRIM($B10),People!$B$2:$B$199,0)),IFERROR(INDEX(Teams!$A$2:$A$9,MATCH(TRIM($B10),Teams!$B$2:$B$9,0)),"?? CHECK NAME")))
C11: =IF(TRIM($B11)="","",IFERROR(INDEX(People!$A$2:$A$199,MATCH(TRIM($B11),People!$B$2:$B$199,0)),IFERROR(INDEX(Teams!$A$2:$A$9,MATCH(TRIM($B11),Teams!$B$2:$B$9,0)),"?? CHECK NAME")))
C12: =IF(TRIM($B12)="","",IFERROR(INDEX(People!$A$2:$A$199,MATCH(TRIM($B12),People!$B$2:$B$199,0)),IFERROR(INDEX(Teams!$A$2:$A$9,MATCH(TRIM($B12),Teams!$B$2:$B$9,0)),"?? CHECK NAME")))
C13: =IF(TRIM($B13)="","",IFERROR(INDEX(People!$A$2:$A$199,MATCH(TRIM($B13),People!$B$2:$B$199,0)),IFERROR(INDEX(Teams!$A$2:$A$9,MATCH(TRIM($B13),Teams!$B$2:$B$9,0)),"?? CHECK NAME")))
A14: Logistics | C14: =IF(TRIM($B14)="","",IFERROR(INDEX(People!$A$2:$A$199,MATCH(TRIM($B14),People!$B$2:$B$199,0)),IFERROR(INDEX(Teams!$A$2:$A$9,MATCH(TRIM($B14),Teams!$B$2:$B$9,0)),"?? CHECK NAME")))
C15: =IF(TRIM($B15)="","",IFERROR(INDEX(People!$A$2:$A$199,MATCH(TRIM($B15),People!$B$2:$B$199,0)),IFERROR(INDEX(Teams!$A$2:$A$9,MATCH(TRIM($B15),Teams!$B$2:$B$9,0)),"?? CHECK NAME")))
C16: =IF(TRIM($B16)="","",IFERROR(INDEX(People!$A$2:$A$199,MATCH(TRIM($B16),People!$B$2:$B$199,0)),IFERROR(INDEX(Teams!$A$2:$A$9,MATCH(TRIM($B16),Teams!$B$2:$B$9,0)),"?? CHECK NAME")))
C17: =IF(TRIM($B17)="","",IFERROR(INDEX(People!$A$2:$A$199,MATCH(TRIM($B17),People!$B$2:$B$199,0)),IFERROR(INDEX(Teams!$A$2:$A$9,MATCH(TRIM($B17),Teams!$B$2:$B$9,0)),"?? CHECK NAME")))
C18: =IF(TRIM($B18)="","",IFERROR(INDEX(People!$A$2:$A$199,MATCH(TRIM($B18),People!$B$2:$B$199,0)),IFERROR(INDEX(Teams!$A$2:$A$9,MATCH(TRIM($B18),Teams!$B$2:$B$9,0)),"?? CHECK NAME")))
A19: Hospitality | C19: =IF(TRIM($B19)="","",IFERROR(INDEX(People!$A$2:$A$199,MATCH(TRIM($B19),People!$B$2:$B$199,0)),IFERROR(INDEX(Teams!$A$2:$A$9,MATCH(TRIM($B19),Teams!$B$2:$B$9,0)),"?? CHECK NAME")))
C20: =IF(TRIM($B20)="","",IFERROR(INDEX(People!$A$2:$A$199,MATCH(TRIM($B20),People!$B$2:$B$199,0)),IFERROR(INDEX(Teams!$A$2:$A$9,MATCH(TRIM($B20),Teams!$B$2:$B$9,0)),"?? CHECK NAME")))
C21: =IF(TRIM($B21)="","",IFERROR(INDEX(People!$A$2:$A$199,MATCH(TRIM($B21),People!$B$2:$B$199,0)),IFERROR(INDEX(Teams!$A$2:$A$9,MATCH(TRIM($B21),Teams!$B$2:$B$9,0)),"?? CHECK NAME")))
C22: =IF(TRIM($B22)="","",IFERROR(INDEX(People!$A$2:$A$199,MATCH(TRIM($B22),People!$B$2:$B$199,0)),IFERROR(INDEX(Teams!$A$2:$A$9,MATCH(TRIM($B22),Teams!$B$2:$B$9,0)),"?? CHECK NAME")))
C23: =IF(TRIM($B23)="","",IFERROR(INDEX(People!$A$2:$A$199,MATCH(TRIM($B23),People!$B$2:$B$199,0)),IFERROR(INDEX(Teams!$A$2:$A$9,MATCH(TRIM($B23),Teams!$B$2:$B$9,0)),"?? CHECK NAME")))
A24: Creative | C24: =IF(TRIM($B24)="","",IFERROR(INDEX(People!$A$2:$A$199,MATCH(TRIM($B24),People!$B$2:$B$199,0)),IFERROR(INDEX(Teams!$A$2:$A$9,MATCH(TRIM($B24),Teams!$B$2:$B$9,0)),"?? CHECK NAME")))
C25: =IF(TRIM($B25)="","",IFERROR(INDEX(People!$A$2:$A$199,MATCH(TRIM($B25),People!$B$2:$B$199,0)),IFERROR(INDEX(Teams!$A$2:$A$9,MATCH(TRIM($B25),Teams!$B$2:$B$9,0)),"?? CHECK NAME")))
C26: =IF(TRIM($B26)="","",IFERROR(INDEX(People!$A$2:$A$199,MATCH(TRIM($B26),People!$B$2:$B$199,0)),IFERROR(INDEX(Teams!$A$2:$A$9,MATCH(TRIM($B26),Teams!$B$2:$B$9,0)),"?? CHECK NAME")))
C27: =IF(TRIM($B27)="","",IFERROR(INDEX(People!$A$2:$A$199,MATCH(TRIM($B27),People!$B$2:$B$199,0)),IFERROR(INDEX(Teams!$A$2:$A$9,MATCH(TRIM($B27),Teams!$B$2:$B$9,0)),"?? CHECK NAME")))
C28: =IF(TRIM($B28)="","",IFERROR(INDEX(People!$A$2:$A$199,MATCH(TRIM($B28),People!$B$2:$B$199,0)),IFERROR(INDEX(Teams!$A$2:$A$9,MATCH(TRIM($B28),Teams!$B$2:$B$9,0)),"?? CHECK NAME")))
A29: Registration | C29: =IF(TRIM($B29)="","",IFERROR(INDEX(People!$A$2:$A$199,MATCH(TRIM($B29),People!$B$2:$B$199,0)),IFERROR(INDEX(Teams!$A$2:$A$9,MATCH(TRIM($B29),Teams!$B$2:$B$9,0)),"?? CHECK NAME")))
C30: =IF(TRIM($B30)="","",IFERROR(INDEX(People!$A$2:$A$199,MATCH(TRIM($B30),People!$B$2:$B$199,0)),IFERROR(INDEX(Teams!$A$2:$A$9,MATCH(TRIM($B30),Teams!$B$2:$B$9,0)),"?? CHECK NAME")))
C31: =IF(TRIM($B31)="","",IFERROR(INDEX(People!$A$2:$A$199,MATCH(TRIM($B31),People!$B$2:$B$199,0)),IFERROR(INDEX(Teams!$A$2:$A$9,MATCH(TRIM($B31),Teams!$B$2:$B$9,0)),"?? CHECK NAME")))
C32: =IF(TRIM($B32)="","",IFERROR(INDEX(People!$A$2:$A$199,MATCH(TRIM($B32),People!$B$2:$B$199,0)),IFERROR(INDEX(Teams!$A$2:$A$9,MATCH(TRIM($B32),Teams!$B$2:$B$9,0)),"?? CHECK NAME")))
C33: =IF(TRIM($B33)="","",IFERROR(INDEX(People!$A$2:$A$199,MATCH(TRIM($B33),People!$B$2:$B$199,0)),IFERROR(INDEX(Teams!$A$2:$A$9,MATCH(TRIM($B33),Teams!$B$2:$B$9,0)),"?? CHECK NAME")))
A34: Head Liaisons | C34: =IF(TRIM($B34)="","",IFERROR(INDEX(People!$A$2:$A$199,MATCH(TRIM($B34),People!$B$2:$B$199,0)),IFERROR(INDEX(Teams!$A$2:$A$9,MATCH(TRIM($B34),Teams!$B$2:$B$9,0)),"?? CHECK NAME")))
C35: =IF(TRIM($B35)="","",IFERROR(INDEX(People!$A$2:$A$199,MATCH(TRIM($B35),People!$B$2:$B$199,0)),IFERROR(INDEX(Teams!$A$2:$A$9,MATCH(TRIM($B35),Teams!$B$2:$B$9,0)),"?? CHECK NAME")))
C36: =IF(TRIM($B36)="","",IFERROR(INDEX(People!$A$2:$A$199,MATCH(TRIM($B36),People!$B$2:$B$199,0)),IFERROR(INDEX(Teams!$A$2:$A$9,MATCH(TRIM($B36),Teams!$B$2:$B$9,0)),"?? CHECK NAME")))
C37: =IF(TRIM($B37)="","",IFERROR(INDEX(People!$A$2:$A$199,MATCH(TRIM($B37),People!$B$2:$B$199,0)),IFERROR(INDEX(Teams!$A$2:$A$9,MATCH(TRIM($B37),Teams!$B$2:$B$9,0)),"?? CHECK NAME")))
C38: =IF(TRIM($B38)="","",IFERROR(INDEX(People!$A$2:$A$199,MATCH(TRIM($B38),People!$B$2:$B$199,0)),IFERROR(INDEX(Teams!$A$2:$A$9,MATCH(TRIM($B38),Teams!$B$2:$B$9,0)),"?? CHECK NAME")))
A39: PR | C39: =IF(TRIM($B39)="","",IFERROR(INDEX(People!$A$2:$A$199,MATCH(TRIM($B39),People!$B$2:$B$199,0)),IFERROR(INDEX(Teams!$A$2:$A$9,MATCH(TRIM($B39),Teams!$B$2:$B$9,0)),"?? CHECK NAME")))
C40: =IF(TRIM($B40)="","",IFERROR(INDEX(People!$A$2:$A$199,MATCH(TRIM($B40),People!$B$2:$B$199,0)),IFERROR(INDEX(Teams!$A$2:$A$9,MATCH(TRIM($B40),Teams!$B$2:$B$9,0)),"?? CHECK NAME")))
...

Sheet Friday
A1: Group | B1: Name | C1: ID | D1: =Instructions!$C$14 -> 46241 | CB1: =Instructions!$C$14+1 -> 46242
D2: 0.20833333 | E2: 0.21875 | F2: 0.22916667 | G2: 0.23958333 | H2: 0.25 | I2: 0.26041667 | J2: 0.27083333 | K2: 0.28125 | L2: 0.29166667 | M2: 0.30208333 | N2: 0.3125 | O2: 0.32291667 | P2: 0.33333333 | Q2: 0.34375 | R2: 0.35416667 | S2: 0.36458333 | T2: 0.375 | U2: 0.38541667 | V2: 0.39583333 | W2: 0.40625 | X2: 0.41666667 | Y2: 0.42708333 | Z2: 0.4375 | AA2: 0.44791667 | AB2: 0.45833333 | AC2: 0.46875 | AD2: 0.47916667 | AE2: 0.48958333 | AF2: 0.5 | AG2: 0.51041667 | AH2: 0.52083333 | AI2: 0.53125 | AJ2: 0.54166667 | AK2: 0.55208333 | AL2: 0.5625 | AM2: 0.57291667 | AN2: 0.58333333 | AO2: 0.59375 | AP2: 0.60416667 | AQ2: 0.61458333 | AR2: 0.625 | AS2: 0.63541667 | AT2: 0.64583333 | AU2: 0.65625 | AV2: 0.66666667 | AW2: 0.67708333 | AX2: 0.6875 | AY2: 0.69791667 | AZ2: 0.70833333 | BA2: 0.71875 | BB2: 0.72916667 | BC2: 0.73958333 | BD2: 0.75 | BE2: 0.76041667 | BF2: 0.77083333 | BG2: 0.78125 | BH2: 0.79166667 | BI2: 0.80208333 | BJ2: 0.8125 | BK2: 0.82291667 | BL2: 0.83333333 | BM2: 0.84375 | BN2: 0.85416667 | BO2: 0.86458333 | BP2: 0.875 | BQ2: 0.88541667 | BR2: 0.89583333 | BS2: 0.90625 | BT2: 0.91666667 | BU2: 0.92708333 | BV2: 0.9375 | BW2: 0.94791667 | BX2: 0.95833333 | BY2: 0.96875 | BZ2: 0.97916667 | CA2: 0.98958333 | CB2: 0 | CC2: 0.010416667 | CD2: 0.020833333 | CE2: 0.03125
A3: BOARD MEMBERS
A4: Directors | B4: Example Director | C4: =IF(TRIM($B4)="","",IFERROR(INDEX(People!$A$2:$A$199,MATCH(TRIM($B4),People!$B$2:$B$199,0)),IFERROR(INDEX(Teams!$A$2:$A$9,MATCH(TRIM($B4),Teams!$B$2:$B$9,0)),"?? CHECK NAME"))) -> BRD-01 | H4: 6:00 AM - 5:00 PM HOTEL (REG ROOM) Check in teams, help Head Liaisons with room setup
C5: =IF(TRIM($B5)="","",IFERROR(INDEX(People!$A$2:$A$199,MATCH(TRIM($B5),People!$B$2:$B$199,0)),IFERROR(INDEX(Teams!$A$2:$A$9,MATCH(TRIM($B5),Teams!$B$2:$B$9,0)),"?? CHECK NAME")))
C6: =IF(TRIM($B6)="","",IFERROR(INDEX(People!$A$2:$A$199,MATCH(TRIM($B6),People!$B$2:$B$199,0)),IFERROR(INDEX(Teams!$A$2:$A$9,MATCH(TRIM($B6),Teams!$B$2:$B$9,0)),"?? CHECK NAME")))
C7: =IF(TRIM($B7)="","",IFERROR(INDEX(People!$A$2:$A$199,MATCH(TRIM($B7),People!$B$2:$B$199,0)),IFERROR(INDEX(Teams!$A$2:$A$9,MATCH(TRIM($B7),Teams!$B$2:$B$9,0)),"?? CHECK NAME")))
C8: =IF(TRIM($B8)="","",IFERROR(INDEX(People!$A$2:$A$199,MATCH(TRIM($B8),People!$B$2:$B$199,0)),IFERROR(INDEX(Teams!$A$2:$A$9,MATCH(TRIM($B8),Teams!$B$2:$B$9,0)),"?? CHECK NAME")))
A9: Senior Advisors | C9: =IF(TRIM($B9)="","",IFERROR(INDEX(People!$A$2:$A$199,MATCH(TRIM($B9),People!$B$2:$B$199,0)),IFERROR(INDEX(Teams!$A$2:$A$9,MATCH(TRIM($B9),Teams!$B$2:$B$9,0)),"?? CHECK NAME")))
C10: =IF(TRIM($B10)="","",IFERROR(INDEX(People!$A$2:$A$199,MATCH(TRIM($B10),People!$B$2:$B$199,0)),IFERROR(INDEX(Teams!$A$2:$A$9,MATCH(TRIM($B10),Teams!$B$2:$B$9,0)),"?? CHECK NAME")))
C11: =IF(TRIM($B11)="","",IFERROR(INDEX(People!$A$2:$A$199,MATCH(TRIM($B11),People!$B$2:$B$199,0)),IFERROR(INDEX(Teams!$A$2:$A$9,MATCH(TRIM($B11),Teams!$B$2:$B$9,0)),"?? CHECK NAME")))
C12: =IF(TRIM($B12)="","",IFERROR(INDEX(People!$A$2:$A$199,MATCH(TRIM($B12),People!$B$2:$B$199,0)),IFERROR(INDEX(Teams!$A$2:$A$9,MATCH(TRIM($B12),Teams!$B$2:$B$9,0)),"?? CHECK NAME")))
C13: =IF(TRIM($B13)="","",IFERROR(INDEX(People!$A$2:$A$199,MATCH(TRIM($B13),People!$B$2:$B$199,0)),IFERROR(INDEX(Teams!$A$2:$A$9,MATCH(TRIM($B13),Teams!$B$2:$B$9,0)),"?? CHECK NAME")))
A14: Logistics | C14: =IF(TRIM($B14)="","",IFERROR(INDEX(People!$A$2:$A$199,MATCH(TRIM($B14),People!$B$2:$B$199,0)),IFERROR(INDEX(Teams!$A$2:$A$9,MATCH(TRIM($B14),Teams!$B$2:$B$9,0)),"?? CHECK NAME")))
C15: =IF(TRIM($B15)="","",IFERROR(INDEX(People!$A$2:$A$199,MATCH(TRIM($B15),People!$B$2:$B$199,0)),IFERROR(INDEX(Teams!$A$2:$A$9,MATCH(TRIM($B15),Teams!$B$2:$B$9,0)),"?? CHECK NAME")))
C16: =IF(TRIM($B16)="","",IFERROR(INDEX(People!$A$2:$A$199,MATCH(TRIM($B16),People!$B$2:$B$199,0)),IFERROR(INDEX(Teams!$A$2:$A$9,MATCH(TRIM($B16),Teams!$B$2:$B$9,0)),"?? CHECK NAME")))
C17: =IF(TRIM($B17)="","",IFERROR(INDEX(People!$A$2:$A$199,MATCH(TRIM($B17),People!$B$2:$B$199,0)),IFERROR(INDEX(Teams!$A$2:$A$9,MATCH(TRIM($B17),Teams!$B$2:$B$9,0)),"?? CHECK NAME")))
C18: =IF(TRIM($B18)="","",IFERROR(INDEX(People!$A$2:$A$199,MATCH(TRIM($B18),People!$B$2:$B$199,0)),IFERROR(INDEX(Teams!$A$2:$A$9,MATCH(TRIM($B18),Teams!$B$2:$B$9,0)),"?? CHECK NAME")))
A19: Hospitality | C19: =IF(TRIM($B19)="","",IFERROR(INDEX(People!$A$2:$A$199,MATCH(TRIM($B19),People!$B$2:$B$199,0)),IFERROR(INDEX(Teams!$A$2:$A$9,MATCH(TRIM($B19),Teams!$B$2:$B$9,0)),"?? CHECK NAME")))
C20: =IF(TRIM($B20)="","",IFERROR(INDEX(People!$A$2:$A$199,MATCH(TRIM($B20),People!$B$2:$B$199,0)),IFERROR(INDEX(Teams!$A$2:$A$9,MATCH(TRIM($B20),Teams!$B$2:$B$9,0)),"?? CHECK NAME")))
C21: =IF(TRIM($B21)="","",IFERROR(INDEX(People!$A$2:$A$199,MATCH(TRIM($B21),People!$B$2:$B$199,0)),IFERROR(INDEX(Teams!$A$2:$A$9,MATCH(TRIM($B21),Teams!$B$2:$B$9,0)),"?? CHECK NAME")))
C22: =IF(TRIM($B22)="","",IFERROR(INDEX(People!$A$2:$A$199,MATCH(TRIM($B22),People!$B$2:$B$199,0)),IFERROR(INDEX(Teams!$A$2:$A$9,MATCH(TRIM($B22),Teams!$B$2:$B$9,0)),"?? CHECK NAME")))
C23: =IF(TRIM($B23)="","",IFERROR(INDEX(People!$A$2:$A$199,MATCH(TRIM($B23),People!$B$2:$B$199,0)),IFERROR(INDEX(Teams!$A$2:$A$9,MATCH(TRIM($B23),Teams!$B$2:$B$9,0)),"?? CHECK NAME")))
A24: Creative | C24: =IF(TRIM($B24)="","",IFERROR(INDEX(People!$A$2:$A$199,MATCH(TRIM($B24),People!$B$2:$B$199,0)),IFERROR(INDEX(Teams!$A$2:$A$9,MATCH(TRIM($B24),Teams!$B$2:$B$9,0)),"?? CHECK NAME")))
C25: =IF(TRIM($B25)="","",IFERROR(INDEX(People!$A$2:$A$199,MATCH(TRIM($B25),People!$B$2:$B$199,0)),IFERROR(INDEX(Teams!$A$2:$A$9,MATCH(TRIM($B25),Teams!$B$2:$B$9,0)),"?? CHECK NAME")))
C26: =IF(TRIM($B26)="","",IFERROR(INDEX(People!$A$2:$A$199,MATCH(TRIM($B26),People!$B$2:$B$199,0)),IFERROR(INDEX(Teams!$A$2:$A$9,MATCH(TRIM($B26),Teams!$B$2:$B$9,0)),"?? CHECK NAME")))
C27: =IF(TRIM($B27)="","",IFERROR(INDEX(People!$A$2:$A$199,MATCH(TRIM($B27),People!$B$2:$B$199,0)),IFERROR(INDEX(Teams!$A$2:$A$9,MATCH(TRIM($B27),Teams!$B$2:$B$9,0)),"?? CHECK NAME")))
C28: =IF(TRIM($B28)="","",IFERROR(INDEX(People!$A$2:$A$199,MATCH(TRIM($B28),People!$B$2:$B$199,0)),IFERROR(INDEX(Teams!$A$2:$A$9,MATCH(TRIM($B28),Teams!$B$2:$B$9,0)),"?? CHECK NAME")))
A29: Registration | C29: =IF(TRIM($B29)="","",IFERROR(INDEX(People!$A$2:$A$199,MATCH(TRIM($B29),People!$B$2:$B$199,0)),IFERROR(INDEX(Teams!$A$2:$A$9,MATCH(TRIM($B29),Teams!$B$2:$B$9,0)),"?? CHECK NAME")))
C30: =IF(TRIM($B30)="","",IFERROR(INDEX(People!$A$2:$A$199,MATCH(TRIM($B30),People!$B$2:$B$199,0)),IFERROR(INDEX(Teams!$A$2:$A$9,MATCH(TRIM($B30),Teams!$B$2:$B$9,0)),"?? CHECK NAME")))
C31: =IF(TRIM($B31)="","",IFERROR(INDEX(People!$A$2:$A$199,MATCH(TRIM($B31),People!$B$2:$B$199,0)),IFERROR(INDEX(Teams!$A$2:$A$9,MATCH(TRIM($B31),Teams!$B$2:$B$9,0)),"?? CHECK NAME")))
C32: =IF(TRIM($B32)="","",IFERROR(INDEX(People!$A$2:$A$199,MATCH(TRIM($B32),People!$B$2:$B$199,0)),IFERROR(INDEX(Teams!$A$2:$A$9,MATCH(TRIM($B32),Teams!$B$2:$B$9,0)),"?? CHECK NAME")))
C33: =IF(TRIM($B33)="","",IFERROR(INDEX(People!$A$2:$A$199,MATCH(TRIM($B33),People!$B$2:$B$199,0)),IFERROR(INDEX(Teams!$A$2:$A$9,MATCH(TRIM($B33),Teams!$B$2:$B$9,0)),"?? CHECK NAME")))
A34: Head Liaisons | C34: =IF(TRIM($B34)="","",IFERROR(INDEX(People!$A$2:$A$199,MATCH(TRIM($B34),People!$B$2:$B$199,0)),IFERROR(INDEX(Teams!$A$2:$A$9,MATCH(TRIM($B34),Teams!$B$2:$B$9,0)),"?? CHECK NAME")))
C35: =IF(TRIM($B35)="","",IFERROR(INDEX(People!$A$2:$A$199,MATCH(TRIM($B35),People!$B$2:$B$199,0)),IFERROR(INDEX(Teams!$A$2:$A$9,MATCH(TRIM($B35),Teams!$B$2:$B$9,0)),"?? CHECK NAME")))
C36: =IF(TRIM($B36)="","",IFERROR(INDEX(People!$A$2:$A$199,MATCH(TRIM($B36),People!$B$2:$B$199,0)),IFERROR(INDEX(Teams!$A$2:$A$9,MATCH(TRIM($B36),Teams!$B$2:$B$9,0)),"?? CHECK NAME")))
C37: =IF(TRIM($B37)="","",IFERROR(INDEX(People!$A$2:$A$199,MATCH(TRIM($B37),People!$B$2:$B$199,0)),IFERROR(INDEX(Teams!$A$2:$A$9,MATCH(TRIM($B37),Teams!$B$2:$B$9,0)),"?? CHECK NAME")))
C38: =IF(TRIM($B38)="","",IFERROR(INDEX(People!$A$2:$A$199,MATCH(TRIM($B38),People!$B$2:$B$199,0)),IFERROR(INDEX(Teams!$A$2:$A$9,MATCH(TRIM($B38),Teams!$B$2:$B$9,0)),"?? CHECK NAME")))
A39: PR | C39: =IF(TRIM($B39)="","",IFERROR(INDEX(People!$A$2:$A$199,MATCH(TRIM($B39),People!$B$2:$B$199,0)),IFERROR(INDEX(Teams!$A$2:$A$9,MATCH(TRIM($B39),Teams!$B$2:$B$9,0)),"?? CHECK NAME")))
C40: =IF(TRIM($B40)="","",IFERROR(INDEX(People!$A$2:$A$199,MATCH(TRIM($B40),People!$B$2:$B$199,0)),IFERROR(INDEX(Teams!$A$2:$A$9,MATCH(TRIM($B40),Teams!$B$2:$B$9,0)),"?? CHECK NAME")))
...

Sheet Saturday
A1: Group | B1: Name | C1: ID | D1: =Instructions!$C$14+1 -> 46242 | CH1: =Instructions!$C$14+2 -> 46243
D2: 0.14583333 | E2: 0.15625 | F2: 0.16666667 | G2: 0.17708333 | H2: 0.1875 | I2: 0.19791667 | J2: 0.20833333 | K2: 0.21875 | L2: 0.22916667 | M2: 0.23958333 | N2: 0.25 | O2: 0.26041667 | P2: 0.27083333 | Q2: 0.28125 | R2: 0.29166667 | S2: 0.30208333 | T2: 0.3125 | U2: 0.32291667 | V2: 0.33333333 | W2: 0.34375 | X2: 0.35416667 | Y2: 0.36458333 | Z2: 0.375 | AA2: 0.38541667 | AB2: 0.39583333 | AC2: 0.40625 | AD2: 0.41666667 | AE2: 0.42708333 | AF2: 0.4375 | AG2: 0.44791667 | AH2: 0.45833333 | AI2: 0.46875 | AJ2: 0.47916667 | AK2: 0.48958333 | AL2: 0.5 | AM2: 0.51041667 | AN2: 0.52083333 | AO2: 0.53125 | AP2: 0.54166667 | AQ2: 0.55208333 | AR2: 0.5625 | AS2: 0.57291667 | AT2: 0.58333333 | AU2: 0.59375 | AV2: 0.60416667 | AW2: 0.61458333 | AX2: 0.625 | AY2: 0.63541667 | AZ2: 0.64583333 | BA2: 0.65625 | BB2: 0.66666667 | BC2: 0.67708333 | BD2: 0.6875 | BE2: 0.69791667 | BF2: 0.70833333 | BG2: 0.71875 | BH2: 0.72916667 | BI2: 0.73958333 | BJ2: 0.75 | BK2: 0.76041667 | BL2: 0.77083333 | BM2: 0.78125 | BN2: 0.79166667 | BO2: 0.80208333 | BP2: 0.8125 | BQ2: 0.82291667 | BR2: 0.83333333 | BS2: 0.84375 | BT2: 0.85416667 | BU2: 0.86458333 | BV2: 0.875 | BW2: 0.88541667 | BX2: 0.89583333 | BY2: 0.90625 | BZ2: 0.91666667 | CA2: 0.92708333 | CB2: 0.9375 | CC2: 0.94791667 | CD2: 0.95833333 | CE2: 0.96875 | CF2: 0.97916667 | CG2: 0.98958333 | CH2: 0 | CI2: 0.010416667 | CJ2: 0.020833333 | CK2: 0.03125
A3: BOARD MEMBERS
A4: Directors | C4: =IF(TRIM($B4)="","",IFERROR(INDEX(People!$A$2:$A$199,MATCH(TRIM($B4),People!$B$2:$B$199,0)),IFERROR(INDEX(Teams!$A$2:$A$9,MATCH(TRIM($B4),Teams!$B$2:$B$9,0)),"?? CHECK NAME")))
C5: =IF(TRIM($B5)="","",IFERROR(INDEX(People!$A$2:$A$199,MATCH(TRIM($B5),People!$B$2:$B$199,0)),IFERROR(INDEX(Teams!$A$2:$A$9,MATCH(TRIM($B5),Teams!$B$2:$B$9,0)),"?? CHECK NAME")))
C6: =IF(TRIM($B6)="","",IFERROR(INDEX(People!$A$2:$A$199,MATCH(TRIM($B6),People!$B$2:$B$199,0)),IFERROR(INDEX(Teams!$A$2:$A$9,MATCH(TRIM($B6),Teams!$B$2:$B$9,0)),"?? CHECK NAME")))
C7: =IF(TRIM($B7)="","",IFERROR(INDEX(People!$A$2:$A$199,MATCH(TRIM($B7),People!$B$2:$B$199,0)),IFERROR(INDEX(Teams!$A$2:$A$9,MATCH(TRIM($B7),Teams!$B$2:$B$9,0)),"?? CHECK NAME")))
C8: =IF(TRIM($B8)="","",IFERROR(INDEX(People!$A$2:$A$199,MATCH(TRIM($B8),People!$B$2:$B$199,0)),IFERROR(INDEX(Teams!$A$2:$A$9,MATCH(TRIM($B8),Teams!$B$2:$B$9,0)),"?? CHECK NAME")))
A9: Senior Advisors | C9: =IF(TRIM($B9)="","",IFERROR(INDEX(People!$A$2:$A$199,MATCH(TRIM($B9),People!$B$2:$B$199,0)),IFERROR(INDEX(Teams!$A$2:$A$9,MATCH(TRIM($B9),Teams!$B$2:$B$9,0)),"?? CHECK NAME")))
C10: =IF(TRIM($B10)="","",IFERROR(INDEX(People!$A$2:$A$199,MATCH(TRIM($B10),People!$B$2:$B$199,0)),IFERROR(INDEX(Teams!$A$2:$A$9,MATCH(TRIM($B10),Teams!$B$2:$B$9,0)),"?? CHECK NAME")))
C11: =IF(TRIM($B11)="","",IFERROR(INDEX(People!$A$2:$A$199,MATCH(TRIM($B11),People!$B$2:$B$199,0)),IFERROR(INDEX(Teams!$A$2:$A$9,MATCH(TRIM($B11),Teams!$B$2:$B$9,0)),"?? CHECK NAME")))
C12: =IF(TRIM($B12)="","",IFERROR(INDEX(People!$A$2:$A$199,MATCH(TRIM($B12),People!$B$2:$B$199,0)),IFERROR(INDEX(Teams!$A$2:$A$9,MATCH(TRIM($B12),Teams!$B$2:$B$9,0)),"?? CHECK NAME")))
C13: =IF(TRIM($B13)="","",IFERROR(INDEX(People!$A$2:$A$199,MATCH(TRIM($B13),People!$B$2:$B$199,0)),IFERROR(INDEX(Teams!$A$2:$A$9,MATCH(TRIM($B13),Teams!$B$2:$B$9,0)),"?? CHECK NAME")))
A14: Logistics | C14: =IF(TRIM($B14)="","",IFERROR(INDEX(People!$A$2:$A$199,MATCH(TRIM($B14),People!$B$2:$B$199,0)),IFERROR(INDEX(Teams!$A$2:$A$9,MATCH(TRIM($B14),Teams!$B$2:$B$9,0)),"?? CHECK NAME")))
C15: =IF(TRIM($B15)="","",IFERROR(INDEX(People!$A$2:$A$199,MATCH(TRIM($B15),People!$B$2:$B$199,0)),IFERROR(INDEX(Teams!$A$2:$A$9,MATCH(TRIM($B15),Teams!$B$2:$B$9,0)),"?? CHECK NAME")))
C16: =IF(TRIM($B16)="","",IFERROR(INDEX(People!$A$2:$A$199,MATCH(TRIM($B16),People!$B$2:$B$199,0)),IFERROR(INDEX(Teams!$A$2:$A$9,MATCH(TRIM($B16),Teams!$B$2:$B$9,0)),"?? CHECK NAME")))
C17: =IF(TRIM($B17)="","",IFERROR(INDEX(People!$A$2:$A$199,MATCH(TRIM($B17),People!$B$2:$B$199,0)),IFERROR(INDEX(Teams!$A$2:$A$9,MATCH(TRIM($B17),Teams!$B$2:$B$9,0)),"?? CHECK NAME")))
C18: =IF(TRIM($B18)="","",IFERROR(INDEX(People!$A$2:$A$199,MATCH(TRIM($B18),People!$B$2:$B$199,0)),IFERROR(INDEX(Teams!$A$2:$A$9,MATCH(TRIM($B18),Teams!$B$2:$B$9,0)),"?? CHECK NAME")))
A19: Hospitality | C19: =IF(TRIM($B19)="","",IFERROR(INDEX(People!$A$2:$A$199,MATCH(TRIM($B19),People!$B$2:$B$199,0)),IFERROR(INDEX(Teams!$A$2:$A$9,MATCH(TRIM($B19),Teams!$B$2:$B$9,0)),"?? CHECK NAME")))
C20: =IF(TRIM($B20)="","",IFERROR(INDEX(People!$A$2:$A$199,MATCH(TRIM($B20),People!$B$2:$B$199,0)),IFERROR(INDEX(Teams!$A$2:$A$9,MATCH(TRIM($B20),Teams!$B$2:$B$9,0)),"?? CHECK NAME")))
C21: =IF(TRIM($B21)="","",IFERROR(INDEX(People!$A$2:$A$199,MATCH(TRIM($B21),People!$B$2:$B$199,0)),IFERROR(INDEX(Teams!$A$2:$A$9,MATCH(TRIM($B21),Teams!$B$2:$B$9,0)),"?? CHECK NAME")))
C22: =IF(TRIM($B22)="","",IFERROR(INDEX(People!$A$2:$A$199,MATCH(TRIM($B22),People!$B$2:$B$199,0)),IFERROR(INDEX(Teams!$A$2:$A$9,MATCH(TRIM($B22),Teams!$B$2:$B$9,0)),"?? CHECK NAME")))
C23: =IF(TRIM($B23)="","",IFERROR(INDEX(People!$A$2:$A$199,MATCH(TRIM($B23),People!$B$2:$B$199,0)),IFERROR(INDEX(Teams!$A$2:$A$9,MATCH(TRIM($B23),Teams!$B$2:$B$9,0)),"?? CHECK NAME")))
A24: Creative | C24: =IF(TRIM($B24)="","",IFERROR(INDEX(People!$A$2:$A$199,MATCH(TRIM($B24),People!$B$2:$B$199,0)),IFERROR(INDEX(Teams!$A$2:$A$9,MATCH(TRIM($B24),Teams!$B$2:$B$9,0)),"?? CHECK NAME")))
C25: =IF(TRIM($B25)="","",IFERROR(INDEX(People!$A$2:$A$199,MATCH(TRIM($B25),People!$B$2:$B$199,0)),IFERROR(INDEX(Teams!$A$2:$A$9,MATCH(TRIM($B25),Teams!$B$2:$B$9,0)),"?? CHECK NAME")))
C26: =IF(TRIM($B26)="","",IFERROR(INDEX(People!$A$2:$A$199,MATCH(TRIM($B26),People!$B$2:$B$199,0)),IFERROR(INDEX(Teams!$A$2:$A$9,MATCH(TRIM($B26),Teams!$B$2:$B$9,0)),"?? CHECK NAME")))
C27: =IF(TRIM($B27)="","",IFERROR(INDEX(People!$A$2:$A$199,MATCH(TRIM($B27),People!$B$2:$B$199,0)),IFERROR(INDEX(Teams!$A$2:$A$9,MATCH(TRIM($B27),Teams!$B$2:$B$9,0)),"?? CHECK NAME")))
C28: =IF(TRIM($B28)="","",IFERROR(INDEX(People!$A$2:$A$199,MATCH(TRIM($B28),People!$B$2:$B$199,0)),IFERROR(INDEX(Teams!$A$2:$A$9,MATCH(TRIM($B28),Teams!$B$2:$B$9,0)),"?? CHECK NAME")))
A29: Registration | C29: =IF(TRIM($B29)="","",IFERROR(INDEX(People!$A$2:$A$199,MATCH(TRIM($B29),People!$B$2:$B$199,0)),IFERROR(INDEX(Teams!$A$2:$A$9,MATCH(TRIM($B29),Teams!$B$2:$B$9,0)),"?? CHECK NAME")))
C30: =IF(TRIM($B30)="","",IFERROR(INDEX(People!$A$2:$A$199,MATCH(TRIM($B30),People!$B$2:$B$199,0)),IFERROR(INDEX(Teams!$A$2:$A$9,MATCH(TRIM($B30),Teams!$B$2:$B$9,0)),"?? CHECK NAME")))
C31: =IF(TRIM($B31)="","",IFERROR(INDEX(People!$A$2:$A$199,MATCH(TRIM($B31),People!$B$2:$B$199,0)),IFERROR(INDEX(Teams!$A$2:$A$9,MATCH(TRIM($B31),Teams!$B$2:$B$9,0)),"?? CHECK NAME")))
C32: =IF(TRIM($B32)="","",IFERROR(INDEX(People!$A$2:$A$199,MATCH(TRIM($B32),People!$B$2:$B$199,0)),IFERROR(INDEX(Teams!$A$2:$A$9,MATCH(TRIM($B32),Teams!$B$2:$B$9,0)),"?? CHECK NAME")))
C33: =IF(TRIM($B33)="","",IFERROR(INDEX(People!$A$2:$A$199,MATCH(TRIM($B33),People!$B$2:$B$199,0)),IFERROR(INDEX(Teams!$A$2:$A$9,MATCH(TRIM($B33),Teams!$B$2:$B$9,0)),"?? CHECK NAME")))
A34: Head Liaisons | C34: =IF(TRIM($B34)="","",IFERROR(INDEX(People!$A$2:$A$199,MATCH(TRIM($B34),People!$B$2:$B$199,0)),IFERROR(INDEX(Teams!$A$2:$A$9,MATCH(TRIM($B34),Teams!$B$2:$B$9,0)),"?? CHECK NAME")))
C35: =IF(TRIM($B35)="","",IFERROR(INDEX(People!$A$2:$A$199,MATCH(TRIM($B35),People!$B$2:$B$199,0)),IFERROR(INDEX(Teams!$A$2:$A$9,MATCH(TRIM($B35),Teams!$B$2:$B$9,0)),"?? CHECK NAME")))
C36: =IF(TRIM($B36)="","",IFERROR(INDEX(People!$A$2:$A$199,MATCH(TRIM($B36),People!$B$2:$B$199,0)),IFERROR(INDEX(Teams!$A$2:$A$9,MATCH(TRIM($B36),Teams!$B$2:$B$9,0)),"?? CHECK NAME")))
C37: =IF(TRIM($B37)="","",IFERROR(INDEX(People!$A$2:$A$199,MATCH(TRIM($B37),People!$B$2:$B$199,0)),IFERROR(INDEX(Teams!$A$2:$A$9,MATCH(TRIM($B37),Teams!$B$2:$B$9,0)),"?? CHECK NAME")))
C38: =IF(TRIM($B38)="","",IFERROR(INDEX(People!$A$2:$A$199,MATCH(TRIM($B38),People!$B$2:$B$199,0)),IFERROR(INDEX(Teams!$A$2:$A$9,MATCH(TRIM($B38),Teams!$B$2:$B$9,0)),"?? CHECK NAME")))
A39: PR | C39: =IF(TRIM($B39)="","",IFERROR(INDEX(People!$A$2:$A$199,MATCH(TRIM($B39),People!$B$2:$B$199,0)),IFERROR(INDEX(Teams!$A$2:$A$9,MATCH(TRIM($B39),Teams!$B$2:$B$9,0)),"?? CHECK NAME")))
C40: =IF(TRIM($B40)="","",IFERROR(INDEX(People!$A$2:$A$199,MATCH(TRIM($B40),People!$B$2:$B$199,0)),IFERROR(INDEX(Teams!$A$2:$A$9,MATCH(TRIM($B40),Teams!$B$2:$B$9,0)),"?? CHECK NAME")))
...

Sheet Sunday
A1: Group | B1: Name | C1: ID | D1: =Instructions!$C$14+2 -> 46243
D2: 0.125 | E2: 0.13541667 | F2: 0.14583333 | G2: 0.15625 | H2: 0.16666667 | I2: 0.17708333 | J2: 0.1875 | K2: 0.19791667 | L2: 0.20833333 | M2: 0.21875 | N2: 0.22916667 | O2: 0.23958333 | P2: 0.25 | Q2: 0.26041667 | R2: 0.27083333 | S2: 0.28125 | T2: 0.29166667 | U2: 0.30208333 | V2: 0.3125 | W2: 0.32291667 | X2: 0.33333333 | Y2: 0.34375 | Z2: 0.35416667 | AA2: 0.36458333 | AB2: 0.375 | AC2: 0.38541667 | AD2: 0.39583333 | AE2: 0.40625 | AF2: 0.41666667 | AG2: 0.42708333 | AH2: 0.4375 | AI2: 0.44791667 | AJ2: 0.45833333 | AK2: 0.46875 | AL2: 0.47916667 | AM2: 0.48958333 | AN2: 0.5 | AO2: 0.51041667 | AP2: 0.52083333 | AQ2: 0.53125 | AR2: 0.54166667 | AS2: 0.55208333 | AT2: 0.5625 | AU2: 0.57291667 | AV2: 0.58333333 | AW2: 0.59375 | AX2: 0.60416667 | AY2: 0.61458333 | AZ2: 0.625 | BA2: 0.63541667 | BB2: 0.64583333 | BC2: 0.65625 | BD2: 0.66666667 | BE2: 0.67708333 | BF2: 0.6875 | BG2: 0.69791667 | BH2: 0.70833333 | BI2: 0.71875 | BJ2: 0.72916667 | BK2: 0.73958333 | BL2: 0.75 | BM2: 0.76041667 | BN2: 0.77083333 | BO2: 0.78125 | BP2: 0.79166667 | BQ2: 0.80208333 | BR2: 0.8125 | BS2: 0.82291667 | BT2: 0.83333333 | BU2: 0.84375 | BV2: 0.85416667 | BW2: 0.86458333
A3: BOARD MEMBERS
A4: Directors | C4: =IF(TRIM($B4)="","",IFERROR(INDEX(People!$A$2:$A$199,MATCH(TRIM($B4),People!$B$2:$B$199,0)),IFERROR(INDEX(Teams!$A$2:$A$9,MATCH(TRIM($B4),Teams!$B$2:$B$9,0)),"?? CHECK NAME")))
C5: =IF(TRIM($B5)="","",IFERROR(INDEX(People!$A$2:$A$199,MATCH(TRIM($B5),People!$B$2:$B$199,0)),IFERROR(INDEX(Teams!$A$2:$A$9,MATCH(TRIM($B5),Teams!$B$2:$B$9,0)),"?? CHECK NAME")))
C6: =IF(TRIM($B6)="","",IFERROR(INDEX(People!$A$2:$A$199,MATCH(TRIM($B6),People!$B$2:$B$199,0)),IFERROR(INDEX(Teams!$A$2:$A$9,MATCH(TRIM($B6),Teams!$B$2:$B$9,0)),"?? CHECK NAME")))
C7: =IF(TRIM($B7)="","",IFERROR(INDEX(People!$A$2:$A$199,MATCH(TRIM($B7),People!$B$2:$B$199,0)),IFERROR(INDEX(Teams!$A$2:$A$9,MATCH(TRIM($B7),Teams!$B$2:$B$9,0)),"?? CHECK NAME")))
C8: =IF(TRIM($B8)="","",IFERROR(INDEX(People!$A$2:$A$199,MATCH(TRIM($B8),People!$B$2:$B$199,0)),IFERROR(INDEX(Teams!$A$2:$A$9,MATCH(TRIM($B8),Teams!$B$2:$B$9,0)),"?? CHECK NAME")))
A9: Senior Advisors | C9: =IF(TRIM($B9)="","",IFERROR(INDEX(People!$A$2:$A$199,MATCH(TRIM($B9),People!$B$2:$B$199,0)),IFERROR(INDEX(Teams!$A$2:$A$9,MATCH(TRIM($B9),Teams!$B$2:$B$9,0)),"?? CHECK NAME")))
C10: =IF(TRIM($B10)="","",IFERROR(INDEX(People!$A$2:$A$199,MATCH(TRIM($B10),People!$B$2:$B$199,0)),IFERROR(INDEX(Teams!$A$2:$A$9,MATCH(TRIM($B10),Teams!$B$2:$B$9,0)),"?? CHECK NAME")))
C11: =IF(TRIM($B11)="","",IFERROR(INDEX(People!$A$2:$A$199,MATCH(TRIM($B11),People!$B$2:$B$199,0)),IFERROR(INDEX(Teams!$A$2:$A$9,MATCH(TRIM($B11),Teams!$B$2:$B$9,0)),"?? CHECK NAME")))
C12: =IF(TRIM($B12)="","",IFERROR(INDEX(People!$A$2:$A$199,MATCH(TRIM($B12),People!$B$2:$B$199,0)),IFERROR(INDEX(Teams!$A$2:$A$9,MATCH(TRIM($B12),Teams!$B$2:$B$9,0)),"?? CHECK NAME")))
C13: =IF(TRIM($B13)="","",IFERROR(INDEX(People!$A$2:$A$199,MATCH(TRIM($B13),People!$B$2:$B$199,0)),IFERROR(INDEX(Teams!$A$2:$A$9,MATCH(TRIM($B13),Teams!$B$2:$B$9,0)),"?? CHECK NAME")))
A14: Logistics | C14: =IF(TRIM($B14)="","",IFERROR(INDEX(People!$A$2:$A$199,MATCH(TRIM($B14),People!$B$2:$B$199,0)),IFERROR(INDEX(Teams!$A$2:$A$9,MATCH(TRIM($B14),Teams!$B$2:$B$9,0)),"?? CHECK NAME")))
C15: =IF(TRIM($B15)="","",IFERROR(INDEX(People!$A$2:$A$199,MATCH(TRIM($B15),People!$B$2:$B$199,0)),IFERROR(INDEX(Teams!$A$2:$A$9,MATCH(TRIM($B15),Teams!$B$2:$B$9,0)),"?? CHECK NAME")))
C16: =IF(TRIM($B16)="","",IFERROR(INDEX(People!$A$2:$A$199,MATCH(TRIM($B16),People!$B$2:$B$199,0)),IFERROR(INDEX(Teams!$A$2:$A$9,MATCH(TRIM($B16),Teams!$B$2:$B$9,0)),"?? CHECK NAME")))
C17: =IF(TRIM($B17)="","",IFERROR(INDEX(People!$A$2:$A$199,MATCH(TRIM($B17),People!$B$2:$B$199,0)),IFERROR(INDEX(Teams!$A$2:$A$9,MATCH(TRIM($B17),Teams!$B$2:$B$9,0)),"?? CHECK NAME")))
C18: =IF(TRIM($B18)="","",IFERROR(INDEX(People!$A$2:$A$199,MATCH(TRIM($B18),People!$B$2:$B$199,0)),IFERROR(INDEX(Teams!$A$2:$A$9,MATCH(TRIM($B18),Teams!$B$2:$B$9,0)),"?? CHECK NAME")))
A19: Hospitality | C19: =IF(TRIM($B19)="","",IFERROR(INDEX(People!$A$2:$A$199,MATCH(TRIM($B19),People!$B$2:$B$199,0)),IFERROR(INDEX(Teams!$A$2:$A$9,MATCH(TRIM($B19),Teams!$B$2:$B$9,0)),"?? CHECK NAME")))
C20: =IF(TRIM($B20)="","",IFERROR(INDEX(People!$A$2:$A$199,MATCH(TRIM($B20),People!$B$2:$B$199,0)),IFERROR(INDEX(Teams!$A$2:$A$9,MATCH(TRIM($B20),Teams!$B$2:$B$9,0)),"?? CHECK NAME")))
C21: =IF(TRIM($B21)="","",IFERROR(INDEX(People!$A$2:$A$199,MATCH(TRIM($B21),People!$B$2:$B$199,0)),IFERROR(INDEX(Teams!$A$2:$A$9,MATCH(TRIM($B21),Teams!$B$2:$B$9,0)),"?? CHECK NAME")))
C22: =IF(TRIM($B22)="","",IFERROR(INDEX(People!$A$2:$A$199,MATCH(TRIM($B22),People!$B$2:$B$199,0)),IFERROR(INDEX(Teams!$A$2:$A$9,MATCH(TRIM($B22),Teams!$B$2:$B$9,0)),"?? CHECK NAME")))
C23: =IF(TRIM($B23)="","",IFERROR(INDEX(People!$A$2:$A$199,MATCH(TRIM($B23),People!$B$2:$B$199,0)),IFERROR(INDEX(Teams!$A$2:$A$9,MATCH(TRIM($B23),Teams!$B$2:$B$9,0)),"?? CHECK NAME")))
A24: Creative | C24: =IF(TRIM($B24)="","",IFERROR(INDEX(People!$A$2:$A$199,MATCH(TRIM($B24),People!$B$2:$B$199,0)),IFERROR(INDEX(Teams!$A$2:$A$9,MATCH(TRIM($B24),Teams!$B$2:$B$9,0)),"?? CHECK NAME")))
C25: =IF(TRIM($B25)="","",IFERROR(INDEX(People!$A$2:$A$199,MATCH(TRIM($B25),People!$B$2:$B$199,0)),IFERROR(INDEX(Teams!$A$2:$A$9,MATCH(TRIM($B25),Teams!$B$2:$B$9,0)),"?? CHECK NAME")))
C26: =IF(TRIM($B26)="","",IFERROR(INDEX(People!$A$2:$A$199,MATCH(TRIM($B26),People!$B$2:$B$199,0)),IFERROR(INDEX(Teams!$A$2:$A$9,MATCH(TRIM($B26),Teams!$B$2:$B$9,0)),"?? CHECK NAME")))
C27: =IF(TRIM($B27)="","",IFERROR(INDEX(People!$A$2:$A$199,MATCH(TRIM($B27),People!$B$2:$B$199,0)),IFERROR(INDEX(Teams!$A$2:$A$9,MATCH(TRIM($B27),Teams!$B$2:$B$9,0)),"?? CHECK NAME")))
C28: =IF(TRIM($B28)="","",IFERROR(INDEX(People!$A$2:$A$199,MATCH(TRIM($B28),People!$B$2:$B$199,0)),IFERROR(INDEX(Teams!$A$2:$A$9,MATCH(TRIM($B28),Teams!$B$2:$B$9,0)),"?? CHECK NAME")))
A29: Registration | C29: =IF(TRIM($B29)="","",IFERROR(INDEX(People!$A$2:$A$199,MATCH(TRIM($B29),People!$B$2:$B$199,0)),IFERROR(INDEX(Teams!$A$2:$A$9,MATCH(TRIM($B29),Teams!$B$2:$B$9,0)),"?? CHECK NAME")))
C30: =IF(TRIM($B30)="","",IFERROR(INDEX(People!$A$2:$A$199,MATCH(TRIM($B30),People!$B$2:$B$199,0)),IFERROR(INDEX(Teams!$A$2:$A$9,MATCH(TRIM($B30),Teams!$B$2:$B$9,0)),"?? CHECK NAME")))
C31: =IF(TRIM($B31)="","",IFERROR(INDEX(People!$A$2:$A$199,MATCH(TRIM($B31),People!$B$2:$B$199,0)),IFERROR(INDEX(Teams!$A$2:$A$9,MATCH(TRIM($B31),Teams!$B$2:$B$9,0)),"?? CHECK NAME")))
C32: =IF(TRIM($B32)="","",IFERROR(INDEX(People!$A$2:$A$199,MATCH(TRIM($B32),People!$B$2:$B$199,0)),IFERROR(INDEX(Teams!$A$2:$A$9,MATCH(TRIM($B32),Teams!$B$2:$B$9,0)),"?? CHECK NAME")))
C33: =IF(TRIM($B33)="","",IFERROR(INDEX(People!$A$2:$A$199,MATCH(TRIM($B33),People!$B$2:$B$199,0)),IFERROR(INDEX(Teams!$A$2:$A$9,MATCH(TRIM($B33),Teams!$B$2:$B$9,0)),"?? CHECK NAME")))
A34: Head Liaisons | C34: =IF(TRIM($B34)="","",IFERROR(INDEX(People!$A$2:$A$199,MATCH(TRIM($B34),People!$B$2:$B$199,0)),IFERROR(INDEX(Teams!$A$2:$A$9,MATCH(TRIM($B34),Teams!$B$2:$B$9,0)),"?? CHECK NAME")))
C35: =IF(TRIM($B35)="","",IFERROR(INDEX(People!$A$2:$A$199,MATCH(TRIM($B35),People!$B$2:$B$199,0)),IFERROR(INDEX(Teams!$A$2:$A$9,MATCH(TRIM($B35),Teams!$B$2:$B$9,0)),"?? CHECK NAME")))
C36: =IF(TRIM($B36)="","",IFERROR(INDEX(People!$A$2:$A$199,MATCH(TRIM($B36),People!$B$2:$B$199,0)),IFERROR(INDEX(Teams!$A$2:$A$9,MATCH(TRIM($B36),Teams!$B$2:$B$9,0)),"?? CHECK NAME")))
C37: =IF(TRIM($B37)="","",IFERROR(INDEX(People!$A$2:$A$199,MATCH(TRIM($B37),People!$B$2:$B$199,0)),IFERROR(INDEX(Teams!$A$2:$A$9,MATCH(TRIM($B37),Teams!$B$2:$B$9,0)),"?? CHECK NAME")))
C38: =IF(TRIM($B38)="","",IFERROR(INDEX(People!$A$2:$A$199,MATCH(TRIM($B38),People!$B$2:$B$199,0)),IFERROR(INDEX(Teams!$A$2:$A$9,MATCH(TRIM($B38),Teams!$B$2:$B$9,0)),"?? CHECK NAME")))
A39: PR | C39: =IF(TRIM($B39)="","",IFERROR(INDEX(People!$A$2:$A$199,MATCH(TRIM($B39),People!$B$2:$B$199,0)),IFERROR(INDEX(Teams!$A$2:$A$9,MATCH(TRIM($B39),Teams!$B$2:$B$9,0)),"?? CHECK NAME")))
C40: =IF(TRIM($B40)="","",IFERROR(INDEX(People!$A$2:$A$199,MATCH(TRIM($B40),People!$B$2:$B$199,0)),IFERROR(INDEX(Teams!$A$2:$A$9,MATCH(TRIM($B40),Teams!$B$2:$B$9,0)),"?? CHECK NAME")))
...

Sheet Sequences
A1: Sequence | B1: Step | C1: Offset (min) | D1: Length (min) | E1: Location | F1: Day | G1: Offsets are measured from…
A2: Saturday Practice | B2: Report to Lobby | C2: 0 | D2: 5 | E2: Courtyard Marriott — Lobby | F2: Saturday | G2: when that team reports to the hotel lobby
B3: Load Vans | C3: 5 | D3: 10 | E3: Courtyard Marriott — Garage
B4: Leave Hotel | C4: 15 | D4: 20 | E4: In transit
B5: On-Stage Rehearsal | C5: 35 | D5: 20 | E5: IU Auditorium — Stage
B6: Walk to Viewing | C6: 55 | D6: 10 | E6: IU Auditorium
B7: Viewing Room | C7: 65 | D7: 20 | E7: IU Auditorium — Viewing Room
B8: Walk to Off-Stage | C8: 85 | D8: 15 | E8: Intramural Fieldhouse
B9: Off-Stage Rehearsal | C9: 100 | D9: 20 | E9: Intramural Fieldhouse
B10: Load Vans (return) | C10: 120 | D10: 10 | E10: Intramural Fieldhouse
B11: Leave Fieldhouse | C11: 130 | D11: 15 | E11: In transit
A16: Saturday Photos | B16: Staircase (Team Boomerang) | C16: 0 | D16: 5 | E16: IU Auditorium — Staircase | F16: Saturday | G16: that team's staircase photo time
B17: Balcony (Team Photo) | C17: 5 | D17: 5 | E17: IU Auditorium — Balcony
A30: Show Backstage | B30: Leave Audience Seats | C30: -25 | D30: 5 | E30: IU Auditorium — House | F30: Saturday | G30: that team's ON STAGE time (offsets are negative before it)
B31: Dressing Room | C31: -20 | D31: 10 | E31: IU Auditorium — Dressing Room
B32: Pre-Prop | C32: -10 | D32: 10 | E32: IU Auditorium — Pre-Prop
B33: ON STAGE | C33: 0 | D33: 10 | E33: IU Auditorium — Stage
B34: Post-Prop to Audience | C34: 10 | D34: 10 | E34: IU Auditorium — Post-Prop
A45: This is the recipe. It barely changes year to year — only the times on Slot Times do.
A46: Offset is minutes from the reference time in the last column. It can be negative, which means before it.
A47: Blank yellow rows are spare capacity. Leave them empty.

Sheet Slot Times
A1: Sequence | B1: Slot | C1: Anchor | D1: Gap before (min) | E1: Adjust (min) | F1: Reference time | G1: Team (from the draw)
A2: Saturday Practice | B2: 1 | C2: 0.30208333 | F2: =IF($C2="","",$C2+$E2/1440) -> 0.30208333 | G2: =IFERROR(INDEX(Teams!$B$2:$B$9,MATCH($B2,Teams!$D$2:$D$9,0)),"(not drawn)") -> (not drawn)
B3: 2 | D3: 25 | F3: =IF(OR($F2="",$D3=""),"",$F2+($D3+$E3)/1440) -> 0.31944444 | G3: =IFERROR(INDEX(Teams!$B$2:$B$9,MATCH($B3,Teams!$D$2:$D$9,0)),"(not drawn)") -> (not drawn)
B4: 3 | D4: 25 | F4: =IF(OR($F3="",$D4=""),"",$F3+($D4+$E4)/1440) -> 0.33680556 | G4: =IFERROR(INDEX(Teams!$B$2:$B$9,MATCH($B4,Teams!$D$2:$D$9,0)),"(not drawn)") -> (not drawn)
B5: 4 | D5: 25 | F5: =IF(OR($F4="",$D5=""),"",$F4+($D5+$E5)/1440) -> 0.35416667 | G5: =IFERROR(INDEX(Teams!$B$2:$B$9,MATCH($B5,Teams!$D$2:$D$9,0)),"(not drawn)") -> (not drawn)
B6: 5 | D6: 60 | F6: =IF(OR($F5="",$D6=""),"",$F5+($D6+$E6)/1440) -> 0.39583333 | G6: =IFERROR(INDEX(Teams!$B$2:$B$9,MATCH($B6,Teams!$D$2:$D$9,0)),"(not drawn)") -> (not drawn)
B7: 6 | D7: 25 | F7: =IF(OR($F6="",$D7=""),"",$F6+($D7+$E7)/1440) -> 0.41319444 | G7: =IFERROR(INDEX(Teams!$B$2:$B$9,MATCH($B7,Teams!$D$2:$D$9,0)),"(not drawn)") -> (not drawn)
B8: 7 | D8: 25 | F8: =IF(OR($F7="",$D8=""),"",$F7+($D8+$E8)/1440) -> 0.43055556 | G8: =IFERROR(INDEX(Teams!$B$2:$B$9,MATCH($B8,Teams!$D$2:$D$9,0)),"(not drawn)") -> (not drawn)
B9: 8 | D9: 25 | F9: =IF(OR($F8="",$D9=""),"",$F8+($D9+$E9)/1440) -> 0.44791667 | G9: =IFERROR(INDEX(Teams!$B$2:$B$9,MATCH($B9,Teams!$D$2:$D$9,0)),"(not drawn)") -> (not drawn)
A10: Saturday Photos | B10: 1 | C10: 0.625 | F10: =IF($C10="","",$C10+$E10/1440) -> 0.625 | G10: =IFERROR(INDEX(Teams!$B$2:$B$9,MATCH($B10,Teams!$D$2:$D$9,0)),"(not drawn)") -> (not drawn)
B11: 2 | D11: 5 | F11: =IF(OR($F10="",$D11=""),"",$F10+($D11+$E11)/1440) -> 0.62847222 | G11: =IFERROR(INDEX(Teams!$B$2:$B$9,MATCH($B11,Teams!$D$2:$D$9,0)),"(not drawn)") -> (not drawn)
B12: 3 | D12: 5 | F12: =IF(OR($F11="",$D12=""),"",$F11+($D12+$E12)/1440) -> 0.63194444 | G12: =IFERROR(INDEX(Teams!$B$2:$B$9,MATCH($B12,Teams!$D$2:$D$9,0)),"(not drawn)") -> (not drawn)
B13: 4 | D13: 5 | F13: =IF(OR($F12="",$D13=""),"",$F12+($D13+$E13)/1440) -> 0.63541667 | G13: =IFERROR(INDEX(Teams!$B$2:$B$9,MATCH($B13,Teams!$D$2:$D$9,0)),"(not drawn)") -> (not drawn)
B14: 5 | D14: 10 | F14: =IF(OR($F13="",$D14=""),"",$F13+($D14+$E14)/1440) -> 0.64236111 | G14: =IFERROR(INDEX(Teams!$B$2:$B$9,MATCH($B14,Teams!$D$2:$D$9,0)),"(not drawn)") -> (not drawn)
B15: 6 | D15: 5 | F15: =IF(OR($F14="",$D15=""),"",$F14+($D15+$E15)/1440) -> 0.64583333 | G15: =IFERROR(INDEX(Teams!$B$2:$B$9,MATCH($B15,Teams!$D$2:$D$9,0)),"(not drawn)") -> (not drawn)
B16: 7 | D16: 5 | F16: =IF(OR($F15="",$D16=""),"",$F15+($D16+$E16)/1440) -> 0.64930556 | G16: =IFERROR(INDEX(Teams!$B$2:$B$9,MATCH($B16,Teams!$D$2:$D$9,0)),"(not drawn)") -> (not drawn)
B17: 8 | D17: 5 | F17: =IF(OR($F16="",$D17=""),"",$F16+($D17+$E17)/1440) -> 0.65277778 | G17: =IFERROR(INDEX(Teams!$B$2:$B$9,MATCH($B17,Teams!$D$2:$D$9,0)),"(not drawn)") -> (not drawn)
A18: Show Backstage | B18: 1 | C18: 0.72569444 | F18: =IF($C18="","",$C18+$E18/1440) -> 0.72569444 | G18: =IFERROR(INDEX(Teams!$B$2:$B$9,MATCH($B18,Teams!$D$2:$D$9,0)),"(not drawn)") -> (not drawn)
B19: 2 | D19: 10 | F19: =IF(OR($F18="",$D19=""),"",$F18+($D19+$E19)/1440) -> 0.73263889 | G19: =IFERROR(INDEX(Teams!$B$2:$B$9,MATCH($B19,Teams!$D$2:$D$9,0)),"(not drawn)") -> (not drawn)
B20: 3 | D20: 10 | F20: =IF(OR($F19="",$D20=""),"",$F19+($D20+$E20)/1440) -> 0.73958333 | G20: =IFERROR(INDEX(Teams!$B$2:$B$9,MATCH($B20,Teams!$D$2:$D$9,0)),"(not drawn)") -> (not drawn)
B21: 4 | D21: 10 | F21: =IF(OR($F20="",$D21=""),"",$F20+($D21+$E21)/1440) -> 0.74652778 | G21: =IFERROR(INDEX(Teams!$B$2:$B$9,MATCH($B21,Teams!$D$2:$D$9,0)),"(not drawn)") -> (not drawn)
B22: 5 | D22: 30 | F22: =IF(OR($F21="",$D22=""),"",$F21+($D22+$E22)/1440) -> 0.76736111 | G22: =IFERROR(INDEX(Teams!$B$2:$B$9,MATCH($B22,Teams!$D$2:$D$9,0)),"(not drawn)") -> (not drawn)
B23: 6 | D23: 10 | F23: =IF(OR($F22="",$D23=""),"",$F22+($D23+$E23)/1440) -> 0.77430556 | G23: =IFERROR(INDEX(Teams!$B$2:$B$9,MATCH($B23,Teams!$D$2:$D$9,0)),"(not drawn)") -> (not drawn)
B24: 7 | D24: 10 | F24: =IF(OR($F23="",$D24=""),"",$F23+($D24+$E24)/1440) -> 0.78125 | G24: =IFERROR(INDEX(Teams!$B$2:$B$9,MATCH($B24,Teams!$D$2:$D$9,0)),"(not drawn)") -> (not drawn)
B25: 8 | D25: 10 | F25: =IF(OR($F24="",$D25=""),"",$F24+($D25+$E25)/1440) -> 0.78819444 | G25: =IFERROR(INDEX(Teams!$B$2:$B$9,MATCH($B25,Teams!$D$2:$D$9,0)),"(not drawn)") -> (not drawn)
A27: Anchor is when slot 1 starts. Every slot after it is the one before plus its Gap.
A28: RUNNING LATE? Whole pipeline late — change the Anchor. One team ran long — raise the Gap on the NEXT slot. Everything after moves; everything already finished does not.
A29: Adjust shifts one slot on its own without moving anyone else. Use it sparingly.
A30: Check the Timeline tab after any change.

Sheet Team Blocks
A1: Day | B1: Sequence | C1: Slot | D1: Team | E1: Step | F1: Start | G1: End | H1: Location
A2: =IF(Sequences!$B$2="","",Sequences!$F$2) -> Saturday | B2: =IF(Sequences!$B$2="","",Sequences!$A$2) -> Saturday Practice | C2: =IF(Sequences!$B$2="","",'Slot Times'!$B$2) -> 1 | D2: =IF(Sequences!$B$2="","",'Slot Times'!$G$2) -> (not drawn) | E2: =IF(Sequences!$B$2="","",Sequences!$B$2) -> Report to Lobby | F2: =IF(OR(Sequences!$B$2="",'Slot Times'!$F$2=""),"",'Slot Times'!$F$2+Sequences!$C$2/1440) -> 0.30208333 | G2: =IF($F2="","",$F2+Sequences!$D$2/1440) -> 0.30555556 | H2: =IF(Sequences!$B$2="","",Sequences!$E$2) -> Courtyard Marriott — Lobby
A3: =IF(Sequences!$B$3="","",Sequences!$F$2) -> Saturday | B3: =IF(Sequences!$B$3="","",Sequences!$A$2) -> Saturday Practice | C3: =IF(Sequences!$B$3="","",'Slot Times'!$B$2) -> 1 | D3: =IF(Sequences!$B$3="","",'Slot Times'!$G$2) -> (not drawn) | E3: =IF(Sequences!$B$3="","",Sequences!$B$3) -> Load Vans | F3: =IF(OR(Sequences!$B$3="",'Slot Times'!$F$2=""),"",'Slot Times'!$F$2+Sequences!$C$3/1440) -> 0.30555556 | G3: =IF($F3="","",$F3+Sequences!$D$3/1440) -> 0.3125 | H3: =IF(Sequences!$B$3="","",Sequences!$E$3) -> Courtyard Marriott — Garage
A4: =IF(Sequences!$B$4="","",Sequences!$F$2) -> Saturday | B4: =IF(Sequences!$B$4="","",Sequences!$A$2) -> Saturday Practice | C4: =IF(Sequences!$B$4="","",'Slot Times'!$B$2) -> 1 | D4: =IF(Sequences!$B$4="","",'Slot Times'!$G$2) -> (not drawn) | E4: =IF(Sequences!$B$4="","",Sequences!$B$4) -> Leave Hotel | F4: =IF(OR(Sequences!$B$4="",'Slot Times'!$F$2=""),"",'Slot Times'!$F$2+Sequences!$C$4/1440) -> 0.3125 | G4: =IF($F4="","",$F4+Sequences!$D$4/1440) -> 0.32638889 | H4: =IF(Sequences!$B$4="","",Sequences!$E$4) -> In transit
A5: =IF(Sequences!$B$5="","",Sequences!$F$2) -> Saturday | B5: =IF(Sequences!$B$5="","",Sequences!$A$2) -> Saturday Practice | C5: =IF(Sequences!$B$5="","",'Slot Times'!$B$2) -> 1 | D5: =IF(Sequences!$B$5="","",'Slot Times'!$G$2) -> (not drawn) | E5: =IF(Sequences!$B$5="","",Sequences!$B$5) -> On-Stage Rehearsal | F5: =IF(OR(Sequences!$B$5="",'Slot Times'!$F$2=""),"",'Slot Times'!$F$2+Sequences!$C$5/1440) -> 0.32638889 | G5: =IF($F5="","",$F5+Sequences!$D$5/1440) -> 0.34027778 | H5: =IF(Sequences!$B$5="","",Sequences!$E$5) -> IU Auditorium — Stage
A6: =IF(Sequences!$B$6="","",Sequences!$F$2) -> Saturday | B6: =IF(Sequences!$B$6="","",Sequences!$A$2) -> Saturday Practice | C6: =IF(Sequences!$B$6="","",'Slot Times'!$B$2) -> 1 | D6: =IF(Sequences!$B$6="","",'Slot Times'!$G$2) -> (not drawn) | E6: =IF(Sequences!$B$6="","",Sequences!$B$6) -> Walk to Viewing | F6: =IF(OR(Sequences!$B$6="",'Slot Times'!$F$2=""),"",'Slot Times'!$F$2+Sequences!$C$6/1440) -> 0.34027778 | G6: =IF($F6="","",$F6+Sequences!$D$6/1440) -> 0.34722222 | H6: =IF(Sequences!$B$6="","",Sequences!$E$6) -> IU Auditorium
A7: =IF(Sequences!$B$7="","",Sequences!$F$2) -> Saturday | B7: =IF(Sequences!$B$7="","",Sequences!$A$2) -> Saturday Practice | C7: =IF(Sequences!$B$7="","",'Slot Times'!$B$2) -> 1 | D7: =IF(Sequences!$B$7="","",'Slot Times'!$G$2) -> (not drawn) | E7: =IF(Sequences!$B$7="","",Sequences!$B$7) -> Viewing Room | F7: =IF(OR(Sequences!$B$7="",'Slot Times'!$F$2=""),"",'Slot Times'!$F$2+Sequences!$C$7/1440) -> 0.34722222 | G7: =IF($F7="","",$F7+Sequences!$D$7/1440) -> 0.36111111 | H7: =IF(Sequences!$B$7="","",Sequences!$E$7) -> IU Auditorium — Viewing Room
A8: =IF(Sequences!$B$8="","",Sequences!$F$2) -> Saturday | B8: =IF(Sequences!$B$8="","",Sequences!$A$2) -> Saturday Practice | C8: =IF(Sequences!$B$8="","",'Slot Times'!$B$2) -> 1 | D8: =IF(Sequences!$B$8="","",'Slot Times'!$G$2) -> (not drawn) | E8: =IF(Sequences!$B$8="","",Sequences!$B$8) -> Walk to Off-Stage | F8: =IF(OR(Sequences!$B$8="",'Slot Times'!$F$2=""),"",'Slot Times'!$F$2+Sequences!$C$8/1440) -> 0.36111111 | G8: =IF($F8="","",$F8+Sequences!$D$8/1440) -> 0.37152778 | H8: =IF(Sequences!$B$8="","",Sequences!$E$8) -> Intramural Fieldhouse
A9: =IF(Sequences!$B$9="","",Sequences!$F$2) -> Saturday | B9: =IF(Sequences!$B$9="","",Sequences!$A$2) -> Saturday Practice | C9: =IF(Sequences!$B$9="","",'Slot Times'!$B$2) -> 1 | D9: =IF(Sequences!$B$9="","",'Slot Times'!$G$2) -> (not drawn) | E9: =IF(Sequences!$B$9="","",Sequences!$B$9) -> Off-Stage Rehearsal | F9: =IF(OR(Sequences!$B$9="",'Slot Times'!$F$2=""),"",'Slot Times'!$F$2+Sequences!$C$9/1440) -> 0.37152778 | G9: =IF($F9="","",$F9+Sequences!$D$9/1440) -> 0.38541667 | H9: =IF(Sequences!$B$9="","",Sequences!$E$9) -> Intramural Fieldhouse
A10: =IF(Sequences!$B$10="","",Sequences!$F$2) -> Saturday | B10: =IF(Sequences!$B$10="","",Sequences!$A$2) -> Saturday Practice | C10: =IF(Sequences!$B$10="","",'Slot Times'!$B$2) -> 1 | D10: =IF(Sequences!$B$10="","",'Slot Times'!$G$2) -> (not drawn) | E10: =IF(Sequences!$B$10="","",Sequences!$B$10) -> Load Vans (return) | F10: =IF(OR(Sequences!$B$10="",'Slot Times'!$F$2=""),"",'Slot Times'!$F$2+Sequences!$C$10/1440) -> 0.38541667 | G10: =IF($F10="","",$F10+Sequences!$D$10/1440) -> 0.39236111 | H10: =IF(Sequences!$B$10="","",Sequences!$E$10) -> Intramural Fieldhouse
A11: =IF(Sequences!$B$11="","",Sequences!$F$2) -> Saturday | B11: =IF(Sequences!$B$11="","",Sequences!$A$2) -> Saturday Practice | C11: =IF(Sequences!$B$11="","",'Slot Times'!$B$2) -> 1 | D11: =IF(Sequences!$B$11="","",'Slot Times'!$G$2) -> (not drawn) | E11: =IF(Sequences!$B$11="","",Sequences!$B$11) -> Leave Fieldhouse | F11: =IF(OR(Sequences!$B$11="",'Slot Times'!$F$2=""),"",'Slot Times'!$F$2+Sequences!$C$11/1440) -> 0.39236111 | G11: =IF($F11="","",$F11+Sequences!$D$11/1440) -> 0.40277778 | H11: =IF(Sequences!$B$11="","",Sequences!$E$11) -> In transit
A12: =IF(Sequences!$B$12="","",Sequences!$F$2) | B12: =IF(Sequences!$B$12="","",Sequences!$A$2) | C12: =IF(Sequences!$B$12="","",'Slot Times'!$B$2) | D12: =IF(Sequences!$B$12="","",'Slot Times'!$G$2) | E12: =IF(Sequences!$B$12="","",Sequences!$B$12) | F12: =IF(OR(Sequences!$B$12="",'Slot Times'!$F$2=""),"",'Slot Times'!$F$2+Sequences!$C$12/1440) | G12: =IF($F12="","",$F12+Sequences!$D$12/1440) | H12: =IF(Sequences!$B$12="","",Sequences!$E$12)
A13: =IF(Sequences!$B$13="","",Sequences!$F$2) | B13: =IF(Sequences!$B$13="","",Sequences!$A$2) | C13: =IF(Sequences!$B$13="","",'Slot Times'!$B$2) | D13: =IF(Sequences!$B$13="","",'Slot Times'!$G$2) | E13: =IF(Sequences!$B$13="","",Sequences!$B$13) | F13: =IF(OR(Sequences!$B$13="",'Slot Times'!$F$2=""),"",'Slot Times'!$F$2+Sequences!$C$13/1440) | G13: =IF($F13="","",$F13+Sequences!$D$13/1440) | H13: =IF(Sequences!$B$13="","",Sequences!$E$13)
A14: =IF(Sequences!$B$14="","",Sequences!$F$2) | B14: =IF(Sequences!$B$14="","",Sequences!$A$2) | C14: =IF(Sequences!$B$14="","",'Slot Times'!$B$2) | D14: =IF(Sequences!$B$14="","",'Slot Times'!$G$2) | E14: =IF(Sequences!$B$14="","",Sequences!$B$14) | F14: =IF(OR(Sequences!$B$14="",'Slot Times'!$F$2=""),"",'Slot Times'!$F$2+Sequences!$C$14/1440) | G14: =IF($F14="","",$F14+Sequences!$D$14/1440) | H14: =IF(Sequences!$B$14="","",Sequences!$E$14)
A15: =IF(Sequences!$B$15="","",Sequences!$F$2) | B15: =IF(Sequences!$B$15="","",Sequences!$A$2) | C15: =IF(Sequences!$B$15="","",'Slot Times'!$B$2) | D15: =IF(Sequences!$B$15="","",'Slot Times'!$G$2) | E15: =IF(Sequences!$B$15="","",Sequences!$B$15) | F15: =IF(OR(Sequences!$B$15="",'Slot Times'!$F$2=""),"",'Slot Times'!$F$2+Sequences!$C$15/1440) | G15: =IF($F15="","",$F15+Sequences!$D$15/1440) | H15: =IF(Sequences!$B$15="","",Sequences!$E$15)
A16: =IF(Sequences!$B$2="","",Sequences!$F$2) -> Saturday | B16: =IF(Sequences!$B$2="","",Sequences!$A$2) -> Saturday Practice | C16: =IF(Sequences!$B$2="","",'Slot Times'!$B$3) -> 2 | D16: =IF(Sequences!$B$2="","",'Slot Times'!$G$3) -> (not drawn) | E16: =IF(Sequences!$B$2="","",Sequences!$B$2) -> Report to Lobby | F16: =IF(OR(Sequences!$B$2="",'Slot Times'!$F$3=""),"",'Slot Times'!$F$3+Sequences!$C$2/1440) -> 0.31944444 | G16: =IF($F16="","",$F16+Sequences!$D$2/1440) -> 0.32291667 | H16: =IF(Sequences!$B$2="","",Sequences!$E$2) -> Courtyard Marriott — Lobby
A17: =IF(Sequences!$B$3="","",Sequences!$F$2) -> Saturday | B17: =IF(Sequences!$B$3="","",Sequences!$A$2) -> Saturday Practice | C17: =IF(Sequences!$B$3="","",'Slot Times'!$B$3) -> 2 | D17: =IF(Sequences!$B$3="","",'Slot Times'!$G$3) -> (not drawn) | E17: =IF(Sequences!$B$3="","",Sequences!$B$3) -> Load Vans | F17: =IF(OR(Sequences!$B$3="",'Slot Times'!$F$3=""),"",'Slot Times'!$F$3+Sequences!$C$3/1440) -> 0.32291667 | G17: =IF($F17="","",$F17+Sequences!$D$3/1440) -> 0.32986111 | H17: =IF(Sequences!$B$3="","",Sequences!$E$3) -> Courtyard Marriott — Garage
A18: =IF(Sequences!$B$4="","",Sequences!$F$2) -> Saturday | B18: =IF(Sequences!$B$4="","",Sequences!$A$2) -> Saturday Practice | C18: =IF(Sequences!$B$4="","",'Slot Times'!$B$3) -> 2 | D18: =IF(Sequences!$B$4="","",'Slot Times'!$G$3) -> (not drawn) | E18: =IF(Sequences!$B$4="","",Sequences!$B$4) -> Leave Hotel | F18: =IF(OR(Sequences!$B$4="",'Slot Times'!$F$3=""),"",'Slot Times'!$F$3+Sequences!$C$4/1440) -> 0.32986111 | G18: =IF($F18="","",$F18+Sequences!$D$4/1440) -> 0.34375 | H18: =IF(Sequences!$B$4="","",Sequences!$E$4) -> In transit
A19: =IF(Sequences!$B$5="","",Sequences!$F$2) -> Saturday | B19: =IF(Sequences!$B$5="","",Sequences!$A$2) -> Saturday Practice | C19: =IF(Sequences!$B$5="","",'Slot Times'!$B$3) -> 2 | D19: =IF(Sequences!$B$5="","",'Slot Times'!$G$3) -> (not drawn) | E19: =IF(Sequences!$B$5="","",Sequences!$B$5) -> On-Stage Rehearsal | F19: =IF(OR(Sequences!$B$5="",'Slot Times'!$F$3=""),"",'Slot Times'!$F$3+Sequences!$C$5/1440) -> 0.34375 | G19: =IF($F19="","",$F19+Sequences!$D$5/1440) -> 0.35763889 | H19: =IF(Sequences!$B$5="","",Sequences!$E$5) -> IU Auditorium — Stage
A20: =IF(Sequences!$B$6="","",Sequences!$F$2) -> Saturday | B20: =IF(Sequences!$B$6="","",Sequences!$A$2) -> Saturday Practice | C20: =IF(Sequences!$B$6="","",'Slot Times'!$B$3) -> 2 | D20: =IF(Sequences!$B$6="","",'Slot Times'!$G$3) -> (not drawn) | E20: =IF(Sequences!$B$6="","",Sequences!$B$6) -> Walk to Viewing | F20: =IF(OR(Sequences!$B$6="",'Slot Times'!$F$3=""),"",'Slot Times'!$F$3+Sequences!$C$6/1440) -> 0.35763889 | G20: =IF($F20="","",$F20+Sequences!$D$6/1440) -> 0.36458333 | H20: =IF(Sequences!$B$6="","",Sequences!$E$6) -> IU Auditorium
A21: =IF(Sequences!$B$7="","",Sequences!$F$2) -> Saturday | B21: =IF(Sequences!$B$7="","",Sequences!$A$2) -> Saturday Practice | C21: =IF(Sequences!$B$7="","",'Slot Times'!$B$3) -> 2 | D21: =IF(Sequences!$B$7="","",'Slot Times'!$G$3) -> (not drawn) | E21: =IF(Sequences!$B$7="","",Sequences!$B$7) -> Viewing Room | F21: =IF(OR(Sequences!$B$7="",'Slot Times'!$F$3=""),"",'Slot Times'!$F$3+Sequences!$C$7/1440) -> 0.36458333 | G21: =IF($F21="","",$F21+Sequences!$D$7/1440) -> 0.37847222 | H21: =IF(Sequences!$B$7="","",Sequences!$E$7) -> IU Auditorium — Viewing Room
A22: =IF(Sequences!$B$8="","",Sequences!$F$2) -> Saturday | B22: =IF(Sequences!$B$8="","",Sequences!$A$2) -> Saturday Practice | C22: =IF(Sequences!$B$8="","",'Slot Times'!$B$3) -> 2 | D22: =IF(Sequences!$B$8="","",'Slot Times'!$G$3) -> (not drawn) | E22: =IF(Sequences!$B$8="","",Sequences!$B$8) -> Walk to Off-Stage | F22: =IF(OR(Sequences!$B$8="",'Slot Times'!$F$3=""),"",'Slot Times'!$F$3+Sequences!$C$8/1440) -> 0.37847222 | G22: =IF($F22="","",$F22+Sequences!$D$8/1440) -> 0.38888889 | H22: =IF(Sequences!$B$8="","",Sequences!$E$8) -> Intramural Fieldhouse
A23: =IF(Sequences!$B$9="","",Sequences!$F$2) -> Saturday | B23: =IF(Sequences!$B$9="","",Sequences!$A$2) -> Saturday Practice | C23: =IF(Sequences!$B$9="","",'Slot Times'!$B$3) -> 2 | D23: =IF(Sequences!$B$9="","",'Slot Times'!$G$3) -> (not drawn) | E23: =IF(Sequences!$B$9="","",Sequences!$B$9) -> Off-Stage Rehearsal | F23: =IF(OR(Sequences!$B$9="",'Slot Times'!$F$3=""),"",'Slot Times'!$F$3+Sequences!$C$9/1440) -> 0.38888889 | G23: =IF($F23="","",$F23+Sequences!$D$9/1440) -> 0.40277778 | H23: =IF(Sequences!$B$9="","",Sequences!$E$9) -> Intramural Fieldhouse
