Workbook

Sheet Instructions
B2: How to use this schedule file
B3: Read this page once before you type anything. It takes about five minutes.
B5: WHAT THIS FILE IS
B6: This file holds the schedule for the whole weekend.
B7: The app reads this file. Then it shows each person only their own schedule on their phone.
B9: If you follow the rules on this page, the app reads the file correctly.
B10: If you break the rules, the app may show someone the wrong time, or show them nothing at all.
B12: STEP 1 — SET THE DATE
B13: Type the date of the Friday of your event in the yellow box.
B14: Event Friday date | C14: 46241
B15: You only do this once. Every day tab works out its own date from this one box.
B16: It even handles the hours after midnight, so nothing lands on the wrong day.
B18: STEP 2 — LEARN THE TABS
B19: The tabs are at the bottom of the window. Here is what each one holds.
B21: Instructions | C21: This page.
B22: Teams | C22: The eight teams. Also the show order, which you fill in later.
B23: People | C23: Every board member, liaison, judge, videographer and RAS rep.
B24: Roster | C24: Every dancer.
B25: Thursday, Friday, | C25: The schedule for each day. One row per person or group.
B26: Saturday, Sunday
B27: Airport | C27: Who is flying, when, and who is driving them.
B29: STEP 3 — FILL IN THE TABS, IN THIS ORDER
B30: Do not skip ahead. Each tab uses what you typed in the ones before it.
B32: 1. Teams | C32: Type each team name and short name. Leave Show Order empty for now.
B33: 2. People | C33: Add one row for each board member, liaison, judge, videographer and RAS rep. Do not put dancers here.
C34: Fill in ID, Full Name, Group, Phone, Email and Type.
C35: If the person is a liaison, you must also pick their Team from the dropdown. If you skip this, they will not show up on any day tab.
C36: Never type in the Key column. It fills itself in.
B37: 3. Roster | C37: Add one row for each dancer. Pick their team from the dropdown. Put Yes in the Captain? column for captains.
B38: 4. Day tabs | C38: Fill in Thursday, Friday, Saturday and Sunday. See the next two sections.
B39: 5. Show order | C39: After the draw, go back to Teams and type each team's number, 1 to 8. Saturday then fills itself in.
B40: 6. Check it | C40: Use the checklist at the bottom of this page before you upload.
B42: Spell each name on the People tab the way you want it to appear on that person's phone. The day tabs copy it exactly.
B44: STEP 4 — HOW TO ADD SOMETHING TO A DAY
B45: A day tab is a big grid. Times run across the top. Names run down the left side.
B47: 1. Find the person's row.
B48: 2. Find the column for the time they start.
B49: 3. Click that box and type what they are doing. The next section shows you how.
B50: 4. Select that box and all the boxes to its right, up to the time they finish.
B51: Then click Merge. Now it is one wide box, and you can see how long it lasts.
...

Sheet People
A1: ID | B1: Full Name | C1: Group | D1: Team | E1: Phone | F1: Email | G1: Type | H1: Key (auto)
A2: BRD-01 | B2: Example Director | C2: Directors | E2: 555-0100 | F2: director@example.edu | G2: board | H2: =IF(OR($G2<>"liaison",$D2=""),"",$D2&"#"&COUNTIFS($D$2:$D2,$D2,$G$2:$G2,"liaison"))
A3: LIA-01 | B3: Example Liaison One | C3: Liaisons | D3: UNC Taar Heel Raas | E3: 555-0101 | F3: lia1@example.edu | G3: liaison | H3: =IF(OR($G3<>"liaison",$D3=""),"",$D3&"#"&COUNTIFS($D$2:$D3,$D3,$G$2:$G3,"liaison")) -> UNC Taar Heel Raas#1
A4: LIA-02 | B4: Example Liaison Two | C4: Liaisons | D4: UNC Taar Heel Raas | E4: 555-0102 | F4: lia2@example.edu | G4: liaison | H4: =IF(OR($G4<>"liaison",$D4=""),"",$D4&"#"&COUNTIFS($D$2:$D4,$D4,$G$2:$G4,"liaison")) -> UNC Taar Heel Raas#2
A5: LIA-03 | B5: Example Liaison Three | C5: Liaisons | D5: UNC Taar Heel Raas | E5: 555-0103 | F5: lia3@example.edu | G5: liaison | H5: =IF(OR($G5<>"liaison",$D5=""),"",$D5&"#"&COUNTIFS($D$2:$D5,$D5,$G$2:$G5,"liaison")) -> UNC Taar Heel Raas#3
A6: JDG-01 | B6: Example Judge | C6: Judging | E6: 555-0104 | F6: judge@example.com | G6: judge | H6: =IF(OR($G6<>"liaison",$D6=""),"",$D6&"#"&COUNTIFS($D$2:$D6,$D6,$G$2:$G6,"liaison"))
A7: VID-01 | B7: Example Videographer | C7: External | E7: 555-0105 | F7: video@example.com | G7: videographer | H7: =IF(OR($G7<>"liaison",$D7=""),"",$D7&"#"&COUNTIFS($D$2:$D7,$D7,$G$2:$G7,"liaison"))
H8: =IF(OR($G8<>"liaison",$D8=""),"",$D8&"#"&COUNTIFS($D$2:$D8,$D8,$G$2:$G8,"liaison"))
H9: =IF(OR($G9<>"liaison",$D9=""),"",$D9&"#"&COUNTIFS($D$2:$D9,$D9,$G$2:$G9,"liaison"))
H10: =IF(OR($G10<>"liaison",$D10=""),"",$D10&"#"&COUNTIFS($D$2:$D10,$D10,$G$2:$G10,"liaison"))
H11: =IF(OR($G11<>"liaison",$D11=""),"",$D11&"#"&COUNTIFS($D$2:$D11,$D11,$G$2:$G11,"liaison"))
H12: =IF(OR($G12<>"liaison",$D12=""),"",$D12&"#"&COUNTIFS($D$2:$D12,$D12,$G$2:$G12,"liaison"))
H13: =IF(OR($G13<>"liaison",$D13=""),"",$D13&"#"&COUNTIFS($D$2:$D13,$D13,$G$2:$G13,"liaison"))
H14: =IF(OR($G14<>"liaison",$D14=""),"",$D14&"#"&COUNTIFS($D$2:$D14,$D14,$G$2:$G14,"liaison"))
H15: =IF(OR($G15<>"liaison",$D15=""),"",$D15&"#"&COUNTIFS($D$2:$D15,$D15,$G$2:$G15,"liaison"))
H16: =IF(OR($G16<>"liaison",$D16=""),"",$D16&"#"&COUNTIFS($D$2:$D16,$D16,$G$2:$G16,"liaison"))
H17: =IF(OR($G17<>"liaison",$D17=""),"",$D17&"#"&COUNTIFS($D$2:$D17,$D17,$G$2:$G17,"liaison"))
H18: =IF(OR($G18<>"liaison",$D18=""),"",$D18&"#"&COUNTIFS($D$2:$D18,$D18,$G$2:$G18,"liaison"))
H19: =IF(OR($G19<>"liaison",$D19=""),"",$D19&"#"&COUNTIFS($D$2:$D19,$D19,$G$2:$G19,"liaison"))
... H199: =IF(OR($G199<>"liaison",$D199=""),"",$D199&"#"&COUNTIFS($D$2:$D199,$D199,$G$2:$G199,"liaison"))
A201: Set Type to "liaison" and pick a Team, and that person appears on every day tab automatically — the first five rows for a team become its liaisons 1 to 5.
A202: Key is computed. Do not type in it.

Sheet Teams
A1: ID | B1: Team Name | C1: Abbrev | D1: Show Order | E1: Check | F1: Captain(s) | G1: Liaison Contact
A2: TM-UNC | B2: UNC Taar Heel Raas | C2: UNC | E2: =IF($D2="","",IF(COUNTIF($D$2:$D$9,$D2)>1,"DUPLICATE","OK"))
A3: TM-ILL | B3: Illini Raas | C3: Illini | E3: =IF($D3="","",IF(COUNTIF($D$2:$D$9,$D3)>1,"DUPLICATE","OK"))
A4: TM-UTD | B4: UTD Taraas | C4: UTD | E4: =IF($D4="","",IF(COUNTIF($D$2:$D$9,$D4)>1,"DUPLICATE","OK"))
A5: TM-UVA | B5: UVA Hooraas | C5: UVA | E5: =IF($D5="","",IF(COUNTIF($D$2:$D$9,$D5)>1,"DUPLICATE","OK"))
A6: TM-UMD | B6: UMD Entouraas | C6: UMD | E6: =IF($D6="","",IF(COUNTIF($D$2:$D$9,$D6)>1,"DUPLICATE","OK"))
A7: TM-UMI | B7: Michigan Wolveraas | C7: UMich | E7: =IF($D7="","",IF(COUNTIF($D$2:$D$9,$D7)>1,"DUPLICATE","OK"))
A8: TM-MSU | B8: MSU Raasparty | C8: MSU | E8: =IF($D8="","",IF(COUNTIF($D$2:$D$9,$D8)>1,"DUPLICATE","OK"))
A9: TM-GT | B9: GT Ramblin Raas | C9: GT | E9: =IF($D9="","",IF(COUNTIF($D$2:$D$9,$D9)>1,"DUPLICATE","OK"))
A11: Show Order is the running order, 1-8. Leave it blank until the draw — Saturday's grid is built against slots, not teams, so it can be filled in before you know who is where.
A12: Fill this column in and Saturday resolves itself: every "Show Order N" row picks up the team sitting in slot N, and the app imports it as that team's schedule.
A13: Check flags a slot given to two teams. Every row must read OK before you upload.

Sheet Roster
A1: First Name | B1: Last Name | C1: Team | D1: Phone | E1: Email | F1: Captain? | G1: Dietary Restrictions | H1: T-Shirt Size
A2: Example | B2: Dancer | C2: UNC Taar Heel Raas | D2: 555-0110 | E2: dancer@example.edu | F2: No | G2: Vegetarian | H2: M
A261: One row per dancer, Team as a column — replaces last year's eight per-team tabs. Captain? replaces the asterisk on the first name.

Sheet Thursday
A1: Group | B1: Name | C1: ID | D1: =Instructions!$C$14-1 -> 46240 | AZ1: =Instructions!$C$14 -> 46241
D2: 0.5 | E2: 0.51041667 | F2: 0.52083333 | G2: 0.53125 | H2: 0.54166667 | I2: 0.55208333 | J2: 0.5625 | K2: 0.57291667 | L2: 0.58333333 | M2: 0.59375 | N2: 0.60416667 | O2: 0.61458333 | P2: 0.625 | Q2: 0.63541667 | R2: 0.64583333 | S2: 0.65625 | T2: 0.66666667 | U2: 0.67708333 | V2: 0.6875 | W2: 0.69791667 | X2: 0.70833333 | Y2: 0.71875 | Z2: 0.72916667 | AA2: 0.73958333 | AB2: 0.75 | AC2: 0.76041667 | AD2: 0.77083333 | AE2: 0.78125 | AF2: 0.79166667 | AG2: 0.80208333 | AH2: 0.8125 | AI2: 0.82291667 | AJ2: 0.83333333 | AK2: 0.84375 | AL2: 0.85416667 | AM2: 0.86458333 | AN2: 0.875 | AO2: 0.88541667 | AP2: 0.89583333 | AQ2: 0.90625 | AR2: 0.91666667 | AS2: 0.92708333 | AT2: 0.9375 | AU2: 0.94791667 | AV2: 0.95833333 | AW2: 0.96875 | AX2: 0.97916667 | AY2: 0.98958333 | AZ2: 0 | BA2: 0.010416667 | BB2: 0.020833333 | BC2: 0.03125 | BD2: 0.041666667 | BE2: 0.052083333 | BF2: 0.0625 | BG2: 0.072916667 | BH2: 0.083333333 | BI2: 0.09375 | BJ2: 0.10416667 | BK2: 0.11458333
A3: BOARD MEMBERS
A4: Directors | C4: =IF(TRIM($B4)="","",IFERROR(INDEX(People!$A$2:$A$199,MATCH(TRIM($B4),People!$B$2:$B$199,0)),IFERROR(INDEX(Teams!$A$2:$A$9,MATCH(TRIM($B4),Teams!$B$2:$B$9,0)),"?? CHECK NAME")))
C5: =IF(TRIM($B5)="","",IFERROR(INDEX(People!$A$2:$A$199,MATCH(TRIM($B5),People!$B$2:$B$199,0)),IFERROR(INDEX(Teams!$A$2:$A$9,MATCH(TRIM($B5),Teams!$B$2:$B$9,0)),"?? CHECK NAME")))
C6: =IF(TRIM($B6)="","",IFERROR(INDEX(People!$A$2:$A$199,MATCH(TRIM($B6),People!$B$2:$B$199,0)),IFERROR(INDEX(Teams!$A$2:$A$9,MATCH(TRIM($B6),Teams!$B$2:$B$9,0)),"?? CHECK NAME")))
C7: =IF(TRIM($B7)="","",IFERROR(INDEX(People!$A$2:$A$199,MATCH(TRIM($B7),People!$B$2:$B$199,0)),IFERROR(INDEX(Teams!$A$2:$A$9,MATCH(TRIM($B7),Teams!$B$2:$B$9,0)),"?? CHECK NAME")))
C8: =IF(TRIM($B8)="","",IFERROR(INDEX(People!$A$2:$A$199,MATCH(TRIM($B8),People!$B$2:$B$199,0)),IFERROR(INDEX(Teams!$A$2:$A$9,MATCH(TRIM($B8),Teams!$B$2:$B$9,0)),"?? CHECK NAME")))
A9: Senior Advisors | C9: =IF(TRIM($B9)="","",IFERROR(INDEX(People!$A$2:$A$199,MATCH(TRIM($B9),People!$B$2:$B$199,0)),IFERROR(INDEX(Teams!$A$2:$A$9,MATCH(TRIM($B9),Teams!$B$2:$B$9,0)),"?? CHECK NAME")))
C10: =IF(TRIM($B10)="","",IFERROR(INDEX(People!$A$2:$A$199,MATCH(TRIM($B10),People!$B$2:$B$199,0)),IFERROR(INDEX(Teams!$A$2:$A$9,MATCH(TRIM($B10),Teams!$B$2:$B$9,0)),"?? CHECK NAME")))
C11: =IF(TRIM($B11)="","",IFERROR(INDEX(People!$A$2:$A$199,MATCH(TRIM($B11),People!$B$2:$B$199,0)),IFERROR(INDEX(Teams!$A$2:$A$9,MATCH(TRIM($B11),Teams!$B$2:$B$9,0)),"?? CHECK NAME")))
C12: =IF(TRIM($B12)="","",IFERROR(INDEX(People!$A$2:$A$199,MATCH(TRIM($B12),People!$B$2:$B$199,0)),IFERROR(INDEX(Teams!$A$2:$A$9,MATCH(TRIM($B12),Teams!$B$2:$B$9,0)),"?? CHECK NAME")))
C13: =IF(TRIM($B13)="","",IFERROR(INDEX(People!$A$2:$A$199,MATCH(TRIM($B13),People!$B$2:$B$199,0)),IFERROR(INDEX(Teams!$A$2:$A$9,MATCH(TRIM($B13),Teams!$B$2:$B$9,0)),"?? CHECK NAME")))
A14: Logistics | C14: =IF(TRIM($B14)="","",IFERROR(INDEX(People!$A$2:$A$199,MATCH(TRIM($B14),People!$B$2:$B$199,0)),IFERROR(INDEX(Teams!$A$2:$A$9,MATCH(TRIM($B14),Teams!$B$2:$B$9,0)),"?? CHECK NAME")))
C15: =IF(TRIM($B15)="","",IFERROR(INDEX(People!$A$2:$A$199,MATCH(TRIM($B15),People!$B$2:$B$199,0)),IFERROR(INDEX(Teams!$A$2:$A$9,MATCH(TRIM($B15),Teams!$B$2:$B$9,0)),"?? CHECK NAME")))
C16: =IF(TRIM($B16)="","",IFERROR(INDEX(People!$A$2:$A$199,MATCH(TRIM($B16),People!$B$2:$B$199,0)),IFERROR(INDEX(Teams!$A$2:$A$9,MATCH(TRIM($B16),Teams!$B$2:$B$9,0)),"?? CHECK NAME")))
C17: =IF(TRIM($B17)="","",IFERROR(INDEX(People!$A$2:$A$199,MATCH(TRIM($B17),People!$B$2:$B$199,0)),IFERROR(INDEX(Teams!$A$2:$A$9,MATCH(TRIM($B17),Teams!$B$2:$B$9,0)),"?? CHECK NAME")))
C18: =IF(TRIM($B18)="","",IFERROR(INDEX(People!$A$2:$A$199,MATCH(TRIM($B18),People!$B$2:$B$199,0)),IFERROR(INDEX(Teams!$A$2:$A$9,MATCH(TRIM($B18),Teams!$B$2:$B$9,0)),"?? CHECK NAME")))
A19: Hospitality | C19: =IF(TRIM($B19)="","",IFERROR(INDEX(People!$A$2:$A$199,MATCH(TRIM($B19),People!$B$2:$B$199,0)),IFERROR(INDEX(Teams!$A$2:$A$9,MATCH(TRIM($B19),Teams!$B$2:$B$9,0)),"?? CHECK NAME")))
C20: =IF(TRIM($B20)="","",IFERROR(INDEX(People!$A$2:$A$199,MATCH(TRIM($B20),People!$B$2:$B$199,0)),IFERROR(INDEX(Teams!$A$2:$A$9,MATCH(TRIM($B20),Teams!$B$2:$B$9,0)),"?? CHECK NAME")))
C21: =IF(TRIM($B21)="","",IFERROR(INDEX(People!$A$2:$A$199,MATCH(TRIM($B21),People!$B$2:$B$199,0)),IFERROR(INDEX(Teams!$A$2:$A$9,MATCH(TRIM($B21),Teams!$B$2:$B$9,0)),"?? CHECK NAME")))
C22: =IF(TRIM($B22)="","",IFERROR(INDEX(People!$A$2:$A$199,MATCH(TRIM($B22),People!$B$2:$B$199,0)),IFERROR(INDEX(Teams!$A$2:$A$9,MATCH(TRIM($B22),Teams!$B$2:$B$9,0)),"?? CHECK NAME")))
C23: =IF(TRIM($B23)="","",IFERROR(INDEX(People!$A$2:$A$199,MATCH(TRIM($B23),People!$B$2:$B$199,0)),IFERROR(INDEX(Teams!$A$2:$A$9,MATCH(TRIM($B23),Teams!$B$2:$B$9,0)),"?? CHECK NAME")))
A24: Creative | C24: =IF(TRIM($B24)="","",IFERROR(INDEX(People!$A$2:$A$199,MATCH(TRIM($B24),People!$B$2:$B$199,0)),IFERROR(INDEX(Teams!$A$2:$A$9,MATCH(TRIM($B24),Teams!$B$2:$B$9,0)),"?? CHECK NAME")))
C25: =IF(TRIM($B25)="","",IFERROR(INDEX(People!$A$2:$A$199,MATCH(TRIM($B25),People!$B$2:$B$199,0)),IFERROR(INDEX(Teams!$A$2:$A$9,MATCH(TRIM($B25),Teams!$B$2:$B$9,0)),"?? CHECK NAME")))
C26: =IF(TRIM($B26)="","",IFERROR(INDEX(People!$A$2:$A$199,MATCH(TRIM($B26),People!$B$2:$B$199,0)),IFERROR(INDEX(Teams!$A$2:$A$9,MATCH(TRIM($B26),Teams!$B$2:$B$9,0)),"?? CHECK NAME")))
C27: =IF(TRIM($B27)="","",IFERROR(INDEX(People!$A$2:$A$199,MATCH(TRIM($B27),People!$B$2:$B$199,0)),IFERROR(INDEX(Teams!$A$2:$A$9,MATCH(TRIM($B27),Teams!$B$2:$B$9,0)),"?? CHECK NAME")))
C28: =IF(TRIM($B28)="","",IFERROR(INDEX(People!$A$2:$A$199,MATCH(TRIM($B28),People!$B$2:$B$199,0)),IFERROR(INDEX(Teams!$A$2:$A$9,MATCH(TRIM($B28),Teams!$B$2:$B$9,0)),"?? CHECK NAME")))
A29: Registration | C29: =IF(TRIM($B29)="","",IFERROR(INDEX(People!$A$2:$A$199,MATCH(TRIM($B29),People!$B$2:$B$199,0)),IFERROR(INDEX(Teams!$A$2:$A$9,MATCH(TRIM($B29),Teams!$B$2:$B$9,0)),"?? CHECK NAME")))
C30: =IF(TRIM($B30)="","",IFERROR(INDEX(People!$A$2:$A$199,MATCH(TRIM($B30),People!$B$2:$B$199,0)),IFERROR(INDEX(Teams!$A$2:$A$9,MATCH(TRIM($B30),Teams!$B$2:$B$9,0)),"?? CHECK NAME")))
C31: =IF(TRIM($B31)="","",IFERROR(INDEX(People!$A$2:$A$199,MATCH(TRIM($B31),People!$B$2:$B$199,0)),IFERROR(INDEX(Teams!$A$2:$A$9,MATCH(TRIM($B31),Teams!$B$2:$B$9,0)),"?? CHECK NAME")))
C32: =IF(TRIM($B32)="","",IFERROR(INDEX(People!$A$2:$A$199,MATCH(TRIM($B32),People!$B$2:$B$199,0)),IFERROR(INDEX(Teams!$A$2:$A$9,MATCH(TRIM($B32),Teams!$B$2:$B$9,0)),"?? CHECK NAME")))
C33: =IF(TRIM($B33)="","",IFERROR(INDEX(People!$A$2:$A$199,MATCH(TRIM($B33),People!$B$2:$B$199,0)),IFERROR(INDEX(Teams!$A$2:$A$9,MATCH(TRIM($B33),Teams!$B$2:$B$9,0)),"?? CHECK NAME")))
A34: Head Liaisons | C34: =IF(TRIM($B34)="","",IFERROR(INDEX(People!$A$2:$A$199,MATCH(TRIM($B34),People!$B$2:$B$199,0)),IFERROR(INDEX(Teams!$A$2:$A$9,MATCH(TRIM($B34),Teams!$B$2:$B$9,0)),"?? CHECK NAME")))
C35: =IF(TRIM($B35)="","",IFERROR(INDEX(People!$A$2:$A$199,MATCH(TRIM($B35),People!$B$2:$B$199,0)),IFERROR(INDEX(Teams!$A$2:$A$9,MATCH(TRIM($B35),Teams!$B$2:$B$9,0)),"?? CHECK NAME")))
C36: =IF(TRIM($B36)="","",IFERROR(INDEX(People!$A$2:$A$199,MATCH(TRIM($B36),People!$B$2:$B$199,0)),IFERROR(INDEX(Teams!$A$2:$A$9,MATCH(TRIM($B36),Teams!$B$2:$B$9,0)),"?? CHECK NAME")))
C37: =IF(TRIM($B37)="","",IFERROR(INDEX(People!$A$2:$A$199,MATCH(TRIM($B37),People!$B$2:$B$199,0)),IFERROR(INDEX(Teams!$A$2:$A$9,MATCH(TRIM($B37),Teams!$B$2:$B$9,0)),"?? CHECK NAME")))
C38: =IF(TRIM($B38)="","",IFERROR(INDEX(People!$A$2:$A$199,MATCH(TRIM($B38),People!$B$2:$B$199,0)),IFERROR(INDEX(Teams!$A$2:$A$9,MATCH(TRIM($B38),Teams!$B$2:$B$9,0)),"?? CHECK NAME")))
A39: PR | C39: =IF(TRIM($B39)="","",IFERROR(INDEX(People!$A$2:$A$199,MATCH(TRIM($B39),People!$B$2:$B$199,0)),IFERROR(INDEX(Teams!$A$2:$A$9,MATCH(TRIM($B39),Teams!$B$2:$B$9,0)),"?? CHECK NAME")))
C40: =IF(TRIM($B40)="","",IFERROR(INDEX(People!$A$2:$A$199,MATCH(TRIM($B40),People!$B$2:$B$199,0)),IFERROR(INDEX(Teams!$A$2:$A$9,MATCH(TRIM($B40),Teams!$B$2:$B$9,0)),"?? CHECK NAME")))
...

Sheet Friday
A1: Group | B1: Name | C1: ID | D1: =Instructions!$C$14 -> 46241 | CB1: =Instructions!$C$14+1 -> 46242
D2: 0.20833333 | E2: 0.21875 | F2: 0.22916667 | G2: 0.23958333 | H2: 0.25 | I2: 0.26041667 | J2: 0.27083333 | K2: 0.28125 | L2: 0.29166667 | M2: 0.30208333 | N2: 0.3125 | O2: 0.32291667 | P2: 0.33333333 | Q2: 0.34375 | R2: 0.35416667 | S2: 0.36458333 | T2: 0.375 | U2: 0.38541667 | V2: 0.39583333 | W2: 0.40625 | X2: 0.41666667 | Y2: 0.42708333 | Z2: 0.4375 | AA2: 0.44791667 | AB2: 0.45833333 | AC2: 0.46875 | AD2: 0.47916667 | AE2: 0.48958333 | AF2: 0.5 | AG2: 0.51041667 | AH2: 0.52083333 | AI2: 0.53125 | AJ2: 0.54166667 | AK2: 0.55208333 | AL2: 0.5625 | AM2: 0.57291667 | AN2: 0.58333333 | AO2: 0.59375 | AP2: 0.60416667 | AQ2: 0.61458333 | AR2: 0.625 | AS2: 0.63541667 | AT2: 0.64583333 | AU2: 0.65625 | AV2: 0.66666667 | AW2: 0.67708333 | AX2: 0.6875 | AY2: 0.69791667 | AZ2: 0.70833333 | BA2: 0.71875 | BB2: 0.72916667 | BC2: 0.73958333 | BD2: 0.75 | BE2: 0.76041667 | BF2: 0.77083333 | BG2: 0.78125 | BH2: 0.79166667 | BI2: 0.80208333 | BJ2: 0.8125 | BK2: 0.82291667 | BL2: 0.83333333 | BM2: 0.84375 | BN2: 0.85416667 | BO2: 0.86458333 | BP2: 0.875 | BQ2: 0.88541667 | BR2: 0.89583333 | BS2: 0.90625 | BT2: 0.91666667 | BU2: 0.92708333 | BV2: 0.9375 | BW2: 0.94791667 | BX2: 0.95833333 | BY2: 0.96875 | BZ2: 0.97916667 | CA2: 0.98958333 | CB2: 0 | CC2: 0.010416667 | CD2: 0.020833333 | CE2: 0.03125
A3: BOARD MEMBERS
A4: Directors | B4: Example Director | C4: =IF(TRIM($B4)="","",IFERROR(INDEX(People!$A$2:$A$199,MATCH(TRIM($B4),People!$B$2:$B$199,0)),IFERROR(INDEX(Teams!$A$2:$A$9,MATCH(TRIM($B4),Teams!$B$2:$B$9,0)),"?? CHECK NAME"))) -> BRD-01 | H4: 6:00 AM - 5:00 PM HOTEL (REG ROOM) Check in teams, help Head Liaisons with room setup
C5: =IF(TRIM($B5)="","",IFERROR(INDEX(People!$A$2:$A$199,MATCH(TRIM($B5),People!$B$2:$B$199,0)),IFERROR(INDEX(Teams!$A$2:$A$9,MATCH(TRIM($B5),Teams!$B$2:$B$9,0)),"?? CHECK NAME")))
C6: =IF(TRIM($B6)="","",IFERROR(INDEX(People!$A$2:$A$199,MATCH(TRIM($B6),People!$B$2:$B$199,0)),IFERROR(INDEX(Teams!$A$2:$A$9,MATCH(TRIM($B6),Teams!$B$2:$B$9,0)),"?? CHECK NAME")))
C7: =IF(TRIM($B7)="","",IFERROR(INDEX(People!$A$2:$A$199,MATCH(TRIM($B7),People!$B$2:$B$199,0)),IFERROR(INDEX(Teams!$A$2:$A$9,MATCH(TRIM($B7),Teams!$B$2:$B$9,0)),"?? CHECK NAME")))
C8: =IF(TRIM($B8)="","",IFERROR(INDEX(People!$A$2:$A$199,MATCH(TRIM($B8),People!$B$2:$B$199,0)),IFERROR(INDEX(Teams!$A$2:$A$9,MATCH(TRIM($B8),Teams!$B$2:$B$9,0)),"?? CHECK NAME")))
A9: Senior Advisors | C9: =IF(TRIM($B9)="","",IFERROR(INDEX(People!$A$2:$A$199,MATCH(TRIM($B9),People!$B$2:$B$199,0)),IFERROR(INDEX(Teams!$A$2:$A$9,MATCH(TRIM($B9),Teams!$B$2:$B$9,0)),"?? CHECK NAME")))
C10: =IF(TRIM($B10)="","",IFERROR(INDEX(People!$A$2:$A$199,MATCH(TRIM($B10),People!$B$2:$B$199,0)),IFERROR(INDEX(Teams!$A$2:$A$9,MATCH(TRIM($B10),Teams!$B$2:$B$9,0)),"?? CHECK NAME")))
C11: =IF(TRIM($B11)="","",IFERROR(INDEX(People!$A$2:$A$199,MATCH(TRIM($B11),People!$B$2:$B$199,0)),IFERROR(INDEX(Teams!$A$2:$A$9,MATCH(TRIM($B11),Teams!$B$2:$B$9,0)),"?? CHECK NAME")))
C12: =IF(TRIM($B12)="","",IFERROR(INDEX(People!$A$2:$A$199,MATCH(TRIM($B12),People!$B$2:$B$199,0)),IFERROR(INDEX(Teams!$A$2:$A$9,MATCH(TRIM($B12),Teams!$B$2:$B$9,0)),"?? CHECK NAME")))
C13: =IF(TRIM($B13)="","",IFERROR(INDEX(People!$A$2:$A$199,MATCH(TRIM($B13),People!$B$2:$B$199,0)),IFERROR(INDEX(Teams!$A$2:$A$9,MATCH(TRIM($B13),Teams!$B$2:$B$9,0)),"?? CHECK NAME")))
A14: Logistics | C14: =IF(TRIM($B14)="","",IFERROR(INDEX(People!$A$2:$A$199,MATCH(TRIM($B14),People!$B$2:$B$199,0)),IFERROR(INDEX(Teams!$A$2:$A$9,MATCH(TRIM($B14),Teams!$B$2:$B$9,0)),"?? CHECK NAME")))
C15: =IF(TRIM($B15)="","",IFERROR(INDEX(People!$A$2:$A$199,MATCH(TRIM($B15),People!$B$2:$B$199,0)),IFERROR(INDEX(Teams!$A$2:$A$9,MATCH(TRIM($B15),Teams!$B$2:$B$9,0)),"?? CHECK NAME")))
C16: =IF(TRIM($B16)="","",IFERROR(INDEX(People!$A$2:$A$199,MATCH(TRIM($B16),People!$B$2:$B$199,0)),IFERROR(INDEX(Teams!$A$2:$A$9,MATCH(TRIM($B16),Teams!$B$2:$B$9,0)),"?? CHECK NAME")))
C17: =IF(TRIM($B17)="","",IFERROR(INDEX(People!$A$2:$A$199,MATCH(TRIM($B17),People!$B$2:$B$199,0)),IFERROR(INDEX(Teams!$A$2:$A$9,MATCH(TRIM($B17),Teams!$B$2:$B$9,0)),"?? CHECK NAME")))
C18: =IF(TRIM($B18)="","",IFERROR(INDEX(People!$A$2:$A$199,MATCH(TRIM($B18),People!$B$2:$B$199,0)),IFERROR(INDEX(Teams!$A$2:$A$9,MATCH(TRIM($B18),Teams!$B$2:$B$9,0)),"?? CHECK NAME")))
A19: Hospitality | C19: =IF(TRIM($B19)="","",IFERROR(INDEX(People!$A$2:$A$199,MATCH(TRIM($B19),People!$B$2:$B$199,0)),IFERROR(INDEX(Teams!$A$2:$A$9,MATCH(TRIM($B19),Teams!$B$2:$B$9,0)),"?? CHECK NAME")))
C20: =IF(TRIM($B20)="","",IFERROR(INDEX(People!$A$2:$A$199,MATCH(TRIM($B20),People!$B$2:$B$199,0)),IFERROR(INDEX(Teams!$A$2:$A$9,MATCH(TRIM($B20),Teams!$B$2:$B$9,0)),"?? CHECK NAME")))
C21: =IF(TRIM($B21)="","",IFERROR(INDEX(People!$A$2:$A$199,MATCH(TRIM($B21),People!$B$2:$B$199,0)),IFERROR(INDEX(Teams!$A$2:$A$9,MATCH(TRIM($B21),Teams!$B$2:$B$9,0)),"?? CHECK NAME")))
C22: =IF(TRIM($B22)="","",IFERROR(INDEX(People!$A$2:$A$199,MATCH(TRIM($B22),People!$B$2:$B$199,0)),IFERROR(INDEX(Teams!$A$2:$A$9,MATCH(TRIM($B22),Teams!$B$2:$B$9,0)),"?? CHECK NAME")))
C23: =IF(TRIM($B23)="","",IFERROR(INDEX(People!$A$2:$A$199,MATCH(TRIM($B23),People!$B$2:$B$199,0)),IFERROR(INDEX(Teams!$A$2:$A$9,MATCH(TRIM($B23),Teams!$B$2:$B$9,0)),"?? CHECK NAME")))
A24: Creative | C24: =IF(TRIM($B24)="","",IFERROR(INDEX(People!$A$2:$A$199,MATCH(TRIM($B24),People!$B$2:$B$199,0)),IFERROR(INDEX(Teams!$A$2:$A$9,MATCH(TRIM($B24),Teams!$B$2:$B$9,0)),"?? CHECK NAME")))
C25: =IF(TRIM($B25)="","",IFERROR(INDEX(People!$A$2:$A$199,MATCH(TRIM($B25),People!$B$2:$B$199,0)),IFERROR(INDEX(Teams!$A$2:$A$9,MATCH(TRIM($B25),Teams!$B$2:$B$9,0)),"?? CHECK NAME")))
C26: =IF(TRIM($B26)="","",IFERROR(INDEX(People!$A$2:$A$199,MATCH(TRIM($B26),People!$B$2:$B$199,0)),IFERROR(INDEX(Teams!$A$2:$A$9,MATCH(TRIM($B26),Teams!$B$2:$B$9,0)),"?? CHECK NAME")))
C27: =IF(TRIM($B27)="","",IFERROR(INDEX(People!$A$2:$A$199,MATCH(TRIM($B27),People!$B$2:$B$199,0)),IFERROR(INDEX(Teams!$A$2:$A$9,MATCH(TRIM($B27),Teams!$B$2:$B$9,0)),"?? CHECK NAME")))
C28: =IF(TRIM($B28)="","",IFERROR(INDEX(People!$A$2:$A$199,MATCH(TRIM($B28),People!$B$2:$B$199,0)),IFERROR(INDEX(Teams!$A$2:$A$9,MATCH(TRIM($B28),Teams!$B$2:$B$9,0)),"?? CHECK NAME")))
A29: Registration | C29: =IF(TRIM($B29)="","",IFERROR(INDEX(People!$A$2:$A$199,MATCH(TRIM($B29),People!$B$2:$B$199,0)),IFERROR(INDEX(Teams!$A$2:$A$9,MATCH(TRIM($B29),Teams!$B$2:$B$9,0)),"?? CHECK NAME")))
C30: =IF(TRIM($B30)="","",IFERROR(INDEX(People!$A$2:$A$199,MATCH(TRIM($B30),People!$B$2:$B$199,0)),IFERROR(INDEX(Teams!$A$2:$A$9,MATCH(TRIM($B30),Teams!$B$2:$B$9,0)),"?? CHECK NAME")))
C31: =IF(TRIM($B31)="","",IFERROR(INDEX(People!$A$2:$A$199,MATCH(TRIM($B31),People!$B$2:$B$199,0)),IFERROR(INDEX(Teams!$A$2:$A$9,MATCH(TRIM($B31),Teams!$B$2:$B$9,0)),"?? CHECK NAME")))
C32: =IF(TRIM($B32)="","",IFERROR(INDEX(People!$A$2:$A$199,MATCH(TRIM($B32),People!$B$2:$B$199,0)),IFERROR(INDEX(Teams!$A$2:$A$9,MATCH(TRIM($B32),Teams!$B$2:$B$9,0)),"?? CHECK NAME")))
C33: =IF(TRIM($B33)="","",IFERROR(INDEX(People!$A$2:$A$199,MATCH(TRIM($B33),People!$B$2:$B$199,0)),IFERROR(INDEX(Teams!$A$2:$A$9,MATCH(TRIM($B33),Teams!$B$2:$B$9,0)),"?? CHECK NAME")))
A34: Head Liaisons | C34: =IF(TRIM($B34)="","",IFERROR(INDEX(People!$A$2:$A$199,MATCH(TRIM($B34),People!$B$2:$B$199,0)),IFERROR(INDEX(Teams!$A$2:$A$9,MATCH(TRIM($B34),Teams!$B$2:$B$9,0)),"?? CHECK NAME")))
C35: =IF(TRIM($B35)="","",IFERROR(INDEX(People!$A$2:$A$199,MATCH(TRIM($B35),People!$B$2:$B$199,0)),IFERROR(INDEX(Teams!$A$2:$A$9,MATCH(TRIM($B35),Teams!$B$2:$B$9,0)),"?? CHECK NAME")))
C36: =IF(TRIM($B36)="","",IFERROR(INDEX(People!$A$2:$A$199,MATCH(TRIM($B36),People!$B$2:$B$199,0)),IFERROR(INDEX(Teams!$A$2:$A$9,MATCH(TRIM($B36),Teams!$B$2:$B$9,0)),"?? CHECK NAME")))
C37: =IF(TRIM($B37)="","",IFERROR(INDEX(People!$A$2:$A$199,MATCH(TRIM($B37),People!$B$2:$B$199,0)),IFERROR(INDEX(Teams!$A$2:$A$9,MATCH(TRIM($B37),Teams!$B$2:$B$9,0)),"?? CHECK NAME")))
C38: =IF(TRIM($B38)="","",IFERROR(INDEX(People!$A$2:$A$199,MATCH(TRIM($B38),People!$B$2:$B$199,0)),IFERROR(INDEX(Teams!$A$2:$A$9,MATCH(TRIM($B38),Teams!$B$2:$B$9,0)),"?? CHECK NAME")))
A39: PR | C39: =IF(TRIM($B39)="","",IFERROR(INDEX(People!$A$2:$A$199,MATCH(TRIM($B39),People!$B$2:$B$199,0)),IFERROR(INDEX(Teams!$A$2:$A$9,MATCH(TRIM($B39),Teams!$B$2:$B$9,0)),"?? CHECK NAME")))
C40: =IF(TRIM($B40)="","",IFERROR(INDEX(People!$A$2:$A$199,MATCH(TRIM($B40),People!$B$2:$B$199,0)),IFERROR(INDEX(Teams!$A$2:$A$9,MATCH(TRIM($B40),Teams!$B$2:$B$9,0)),"?? CHECK NAME")))
...

Sheet Saturday
A1: Group | B1: Name | C1: ID | D1: =Instructions!$C$14+1 -> 46242 | CH1: =Instructions!$C$14+2 -> 46243
D2: 0.14583333 | E2: 0.15625 | F2: 0.16666667 | G2: 0.17708333 | H2: 0.1875 | I2: 0.19791667 | J2: 0.20833333 | K2: 0.21875 | L2: 0.22916667 | M2: 0.23958333 | N2: 0.25 | O2: 0.26041667 | P2: 0.27083333 | Q2: 0.28125 | R2: 0.29166667 | S2: 0.30208333 | T2: 0.3125 | U2: 0.32291667 | V2: 0.33333333 | W2: 0.34375 | X2: 0.35416667 | Y2: 0.36458333 | Z2: 0.375 | AA2: 0.38541667 | AB2: 0.39583333 | AC2: 0.40625 | AD2: 0.41666667 | AE2: 0.42708333 | AF2: 0.4375 | AG2: 0.44791667 | AH2: 0.45833333 | AI2: 0.46875 | AJ2: 0.47916667 | AK2: 0.48958333 | AL2: 0.5 | AM2: 0.51041667 | AN2: 0.52083333 | AO2: 0.53125 | AP2: 0.54166667 | AQ2: 0.55208333 | AR2: 0.5625 | AS2: 0.57291667 | AT2: 0.58333333 | AU2: 0.59375 | AV2: 0.60416667 | AW2: 0.61458333 | AX2: 0.625 | AY2: 0.63541667 | AZ2: 0.64583333 | BA2: 0.65625 | BB2: 0.66666667 | BC2: 0.67708333 | BD2: 0.6875 | BE2: 0.69791667 | BF2: 0.70833333 | BG2: 0.71875 | BH2: 0.72916667 | BI2: 0.73958333 | BJ2: 0.75 | BK2: 0.76041667 | BL2: 0.77083333 | BM2: 0.78125 | BN2: 0.79166667 | BO2: 0.80208333 | BP2: 0.8125 | BQ2: 0.82291667 | BR2: 0.83333333 | BS2: 0.84375 | BT2: 0.85416667 | BU2: 0.86458333 | BV2: 0.875 | BW2: 0.88541667 | BX2: 0.89583333 | BY2: 0.90625 | BZ2: 0.91666667 | CA2: 0.92708333 | CB2: 0.9375 | CC2: 0.94791667 | CD2: 0.95833333 | CE2: 0.96875 | CF2: 0.97916667 | CG2: 0.98958333 | CH2: 0 | CI2: 0.010416667 | CJ2: 0.020833333 | CK2: 0.03125
A3: BOARD MEMBERS
A4: Directors | C4: =IF(TRIM($B4)="","",IFERROR(INDEX(People!$A$2:$A$199,MATCH(TRIM($B4),People!$B$2:$B$199,0)),IFERROR(INDEX(Teams!$A$2:$A$9,MATCH(TRIM($B4),Teams!$B$2:$B$9,0)),"?? CHECK NAME")))
C5: =IF(TRIM($B5)="","",IFERROR(INDEX(People!$A$2:$A$199,MATCH(TRIM($B5),People!$B$2:$B$199,0)),IFERROR(INDEX(Teams!$A$2:$A$9,MATCH(TRIM($B5),Teams!$B$2:$B$9,0)),"?? CHECK NAME")))
C6: =IF(TRIM($B6)="","",IFERROR(INDEX(People!$A$2:$A$199,MATCH(TRIM($B6),People!$B$2:$B$199,0)),IFERROR(INDEX(Teams!$A$2:$A$9,MATCH(TRIM($B6),Teams!$B$2:$B$9,0)),"?? CHECK NAME")))
C7: =IF(TRIM($B7)="","",IFERROR(INDEX(People!$A$2:$A$199,MATCH(TRIM($B7),People!$B$2:$B$199,0)),IFERROR(INDEX(Teams!$A$2:$A$9,MATCH(TRIM($B7),Teams!$B$2:$B$9,0)),"?? CHECK NAME")))
C8: =IF(TRIM($B8)="","",IFERROR(INDEX(People!$A$2:$A$199,MATCH(TRIM($B8),People!$B$2:$B$199,0)),IFERROR(INDEX(Teams!$A$2:$A$9,MATCH(TRIM($B8),Teams!$B$2:$B$9,0)),"?? CHECK NAME")))
A9: Senior Advisors | C9: =IF(TRIM($B9)="","",IFERROR(INDEX(People!$A$2:$A$199,MATCH(TRIM($B9),People!$B$2:$B$199,0)),IFERROR(INDEX(Teams!$A$2:$A$9,MATCH(TRIM($B9),Teams!$B$2:$B$9,0)),"?? CHECK NAME")))
C10: =IF(TRIM($B10)="","",IFERROR(INDEX(People!$A$2:$A$199,MATCH(TRIM($B10),People!$B$2:$B$199,0)),IFERROR(INDEX(Teams!$A$2:$A$9,MATCH(TRIM($B10),Teams!$B$2:$B$9,0)),"?? CHECK NAME")))
C11: =IF(TRIM($B11)="","",IFERROR(INDEX(People!$A$2:$A$199,MATCH(TRIM($B11),People!$B$2:$B$199,0)),IFERROR(INDEX(Teams!$A$2:$A$9,MATCH(TRIM($B11),Teams!$B$2:$B$9,0)),"?? CHECK NAME")))
C12: =IF(TRIM($B12)="","",IFERROR(INDEX(People!$A$2:$A$199,MATCH(TRIM($B12),People!$B$2:$B$199,0)),IFERROR(INDEX(Teams!$A$2:$A$9,MATCH(TRIM($B12),Teams!$B$2:$B$9,0)),"?? CHECK NAME")))
C13: =IF(TRIM($B13)="","",IFERROR(INDEX(People!$A$2:$A$199,MATCH(TRIM($B13),People!$B$2:$B$199,0)),IFERROR(INDEX(Teams!$A$2:$A$9,MATCH(TRIM($B13),Teams!$B$2:$B$9,0)),"?? CHECK NAME")))
A14: Logistics | C14: =IF(TRIM($B14)="","",IFERROR(INDEX(People!$A$2:$A$199,MATCH(TRIM($B14),People!$B$2:$B$199,0)),IFERROR(INDEX(Teams!$A$2:$A$9,MATCH(TRIM($B14),Teams!$B$2:$B$9,0)),"?? CHECK NAME")))
C15: =IF(TRIM($B15)="","",IFERROR(INDEX(People!$A$2:$A$199,MATCH(TRIM($B15),People!$B$2:$B$199,0)),IFERROR(INDEX(Teams!$A$2:$A$9,MATCH(TRIM($B15),Teams!$B$2:$B$9,0)),"?? CHECK NAME")))
C16: =IF(TRIM($B16)="","",IFERROR(INDEX(People!$A$2:$A$199,MATCH(TRIM($B16),People!$B$2:$B$199,0)),IFERROR(INDEX(Teams!$A$2:$A$9,MATCH(TRIM($B16),Teams!$B$2:$B$9,0)),"?? CHECK NAME")))
C17: =IF(TRIM($B17)="","",IFERROR(INDEX(People!$A$2:$A$199,MATCH(TRIM($B17),People!$B$2:$B$199,0)),IFERROR(INDEX(Teams!$A$2:$A$9,MATCH(TRIM($B17),Teams!$B$2:$B$9,0)),"?? CHECK NAME")))
C18: =IF(TRIM($B18)="","",IFERROR(INDEX(People!$A$2:$A$199,MATCH(TRIM($B18),People!$B$2:$B$199,0)),IFERROR(INDEX(Teams!$A$2:$A$9,MATCH(TRIM($B18),Teams!$B$2:$B$9,0)),"?? CHECK NAME")))
A19: Hospitality | C19: =IF(TRIM($B19)="","",IFERROR(INDEX(People!$A$2:$A$199,MATCH(TRIM($B19),People!$B$2:$B$199,0)),IFERROR(INDEX(Teams!$A$2:$A$9,MATCH(TRIM($B19),Teams!$B$2:$B$9,0)),"?? CHECK NAME")))
C20: =IF(TRIM($B20)="","",IFERROR(INDEX(People!$A$2:$A$199,MATCH(TRIM($B20),People!$B$2:$B$199,0)),IFERROR(INDEX(Teams!$A$2:$A$9,MATCH(TRIM($B20),Teams!$B$2:$B$9,0)),"?? CHECK NAME")))
C21: =IF(TRIM($B21)="","",IFERROR(INDEX(People!$A$2:$A$199,MATCH(TRIM($B21),People!$B$2:$B$199,0)),IFERROR(INDEX(Teams!$A$2:$A$9,MATCH(TRIM($B21),Teams!$B$2:$B$9,0)),"?? CHECK NAME")))
C22: =IF(TRIM($B22)="","",IFERROR(INDEX(People!$A$2:$A$199,MATCH(TRIM($B22),People!$B$2:$B$199,0)),IFERROR(INDEX(Teams!$A$2:$A$9,MATCH(TRIM($B22),Teams!$B$2:$B$9,0)),"?? CHECK NAME")))
C23: =IF(TRIM($B23)="","",IFERROR(INDEX(People!$A$2:$A$199,MATCH(TRIM($B23),People!$B$2:$B$199,0)),IFERROR(INDEX(Teams!$A$2:$A$9,MATCH(TRIM($B23),Teams!$B$2:$B$9,0)),"?? CHECK NAME")))
A24: Creative | C24: =IF(TRIM($B24)="","",IFERROR(INDEX(People!$A$2:$A$199,MATCH(TRIM($B24),People!$B$2:$B$199,0)),IFERROR(INDEX(Teams!$A$2:$A$9,MATCH(TRIM($B24),Teams!$B$2:$B$9,0)),"?? CHECK NAME")))
C25: =IF(TRIM($B25)="","",IFERROR(INDEX(People!$A$2:$A$199,MATCH(TRIM($B25),People!$B$2:$B$199,0)),IFERROR(INDEX(Teams!$A$2:$A$9,MATCH(TRIM($B25),Teams!$B$2:$B$9,0)),"?? CHECK NAME")))
C26: =IF(TRIM($B26)="","",IFERROR(INDEX(People!$A$2:$A$199,MATCH(TRIM($B26),People!$B$2:$B$199,0)),IFERROR(INDEX(Teams!$A$2:$A$9,MATCH(TRIM($B26),Teams!$B$2:$B$9,0)),"?? CHECK NAME")))
C27: =IF(TRIM($B27)="","",IFERROR(INDEX(People!$A$2:$A$199,MATCH(TRIM($B27),People!$B$2:$B$199,0)),IFERROR(INDEX(Teams!$A$2:$A$9,MATCH(TRIM($B27),Teams!$B$2:$B$9,0)),"?? CHECK NAME")))
C28: =IF(TRIM($B28)="","",IFERROR(INDEX(People!$A$2:$A$199,MATCH(TRIM($B28),People!$B$2:$B$199,0)),IFERROR(INDEX(Teams!$A$2:$A$9,MATCH(TRIM($B28),Teams!$B$2:$B$9,0)),"?? CHECK NAME")))
A29: Registration | C29: =IF(TRIM($B29)="","",IFERROR(INDEX(People!$A$2:$A$199,MATCH(TRIM($B29),People!$B$2:$B$199,0)),IFERROR(INDEX(Teams!$A$2:$A$9,MATCH(TRIM($B29),Teams!$B$2:$B$9,0)),"?? CHECK NAME")))
C30: =IF(TRIM($B30)="","",IFERROR(INDEX(People!$A$2:$A$199,MATCH(TRIM($B30),People!$B$2:$B$199,0)),IFERROR(INDEX(Teams!$A$2:$A$9,MATCH(TRIM($B30),Teams!$B$2:$B$9,0)),"?? CHECK NAME")))
C31: =IF(TRIM($B31)="","",IFERROR(INDEX(People!$A$2:$A$199,MATCH(TRIM($B31),People!$B$2:$B$199,0)),IFERROR(INDEX(Teams!$A$2:$A$9,MATCH(TRIM($B31),Teams!$B$2:$B$9,0)),"?? CHECK NAME")))
C32: =IF(TRIM($B32)="","",IFERROR(INDEX(People!$A$2:$A$199,MATCH(TRIM($B32),People!$B$2:$B$199,0)),IFERROR(INDEX(Teams!$A$2:$A$9,MATCH(TRIM($B32),Teams!$B$2:$B$9,0)),"?? CHECK NAME")))
C33: =IF(TRIM($B33)="","",IFERROR(INDEX(People!$A$2:$A$199,MATCH(TRIM($B33),People!$B$2:$B$199,0)),IFERROR(INDEX(Teams!$A$2:$A$9,MATCH(TRIM($B33),Teams!$B$2:$B$9,0)),"?? CHECK NAME")))
A34: Head Liaisons | C34: =IF(TRIM($B34)="","",IFERROR(INDEX(People!$A$2:$A$199,MATCH(TRIM($B34),People!$B$2:$B$199,0)),IFERROR(INDEX(Teams!$A$2:$A$9,MATCH(TRIM($B34),Teams!$B$2:$B$9,0)),"?? CHECK NAME")))
C35: =IF(TRIM($B35)="","",IFERROR(INDEX(People!$A$2:$A$199,MATCH(TRIM($B35),People!$B$2:$B$199,0)),IFERROR(INDEX(Teams!$A$2:$A$9,MATCH(TRIM($B35),Teams!$B$2:$B$9,0)),"?? CHECK NAME")))
C36: =IF(TRIM($B36)="","",IFERROR(INDEX(People!$A$2:$A$199,MATCH(TRIM($B36),People!$B$2:$B$199,0)),IFERROR(INDEX(Teams!$A$2:$A$9,MATCH(TRIM($B36),Teams!$B$2:$B$9,0)),"?? CHECK NAME")))
C37: =IF(TRIM($B37)="","",IFERROR(INDEX(People!$A$2:$A$199,MATCH(TRIM($B37),People!$B$2:$B$199,0)),IFERROR(INDEX(Teams!$A$2:$A$9,MATCH(TRIM($B37),Teams!$B$2:$B$9,0)),"?? CHECK NAME")))
C38: =IF(TRIM($B38)="","",IFERROR(INDEX(People!$A$2:$A$199,MATCH(TRIM($B38),People!$B$2:$B$199,0)),IFERROR(INDEX(Teams!$A$2:$A$9,MATCH(TRIM($B38),Teams!$B$2:$B$9,0)),"?? CHECK NAME")))
A39: PR | C39: =IF(TRIM($B39)="","",IFERROR(INDEX(People!$A$2:$A$199,MATCH(TRIM($B39),People!$B$2:$B$199,0)),IFERROR(INDEX(Teams!$A$2:$A$9,MATCH(TRIM($B39),Teams!$B$2:$B$9,0)),"?? CHECK NAME")))
C40: =IF(TRIM($B40)="","",IFERROR(INDEX(People!$A$2:$A$199,MATCH(TRIM($B40),People!$B$2:$B$199,0)),IFERROR(INDEX(Teams!$A$2:$A$9,MATCH(TRIM($B40),Teams!$B$2:$B$9,0)),"?? CHECK NAME")))
...

Sheet Sunday
A1: Group | B1: Name | C1: ID | D1: =Instructions!$C$14+2 -> 46243
D2: 0.125 | E2: 0.13541667 | F2: 0.14583333 | G2: 0.15625 | H2: 0.16666667 | I2: 0.17708333 | J2: 0.1875 | K2: 0.19791667 | L2: 0.20833333 | M2: 0.21875 | N2: 0.22916667 | O2: 0.23958333 | P2: 0.25 | Q2: 0.26041667 | R2: 0.27083333 | S2: 0.28125 | T2: 0.29166667 | U2: 0.30208333 | V2: 0.3125 | W2: 0.32291667 | X2: 0.33333333 | Y2: 0.34375 | Z2: 0.35416667 | AA2: 0.36458333 | AB2: 0.375 | AC2: 0.38541667 | AD2: 0.39583333 | AE2: 0.40625 | AF2: 0.41666667 | AG2: 0.42708333 | AH2: 0.4375 | AI2: 0.44791667 | AJ2: 0.45833333 | AK2: 0.46875 | AL2: 0.47916667 | AM2: 0.48958333 | AN2: 0.5 | AO2: 0.51041667 | AP2: 0.52083333 | AQ2: 0.53125 | AR2: 0.54166667 | AS2: 0.55208333 | AT2: 0.5625 | AU2: 0.57291667 | AV2: 0.58333333 | AW2: 0.59375 | AX2: 0.60416667 | AY2: 0.61458333 | AZ2: 0.625 | BA2: 0.63541667 | BB2: 0.64583333 | BC2: 0.65625 | BD2: 0.66666667 | BE2: 0.67708333 | BF2: 0.6875 | BG2: 0.69791667 | BH2: 0.70833333 | BI2: 0.71875 | BJ2: 0.72916667 | BK2: 0.73958333 | BL2: 0.75 | BM2: 0.76041667 | BN2: 0.77083333 | BO2: 0.78125 | BP2: 0.79166667 | BQ2: 0.80208333 | BR2: 0.8125 | BS2: 0.82291667 | BT2: 0.83333333 | BU2: 0.84375 | BV2: 0.85416667 | BW2: 0.86458333
A3: BOARD MEMBERS
A4: Directors | C4: =IF(TRIM($B4)="","",IFERROR(INDEX(People!$A$2:$A$199,MATCH(TRIM($B4),People!$B$2:$B$199,0)),IFERROR(INDEX(Teams!$A$2:$A$9,MATCH(TRIM($B4),Teams!$B$2:$B$9,0)),"?? CHECK NAME")))
C5: =IF(TRIM($B5)="","",IFERROR(INDEX(People!$A$2:$A$199,MATCH(TRIM($B5),People!$B$2:$B$199,0)),IFERROR(INDEX(Teams!$A$2:$A$9,MATCH(TRIM($B5),Teams!$B$2:$B$9,0)),"?? CHECK NAME")))
C6: =IF(TRIM($B6)="","",IFERROR(INDEX(People!$A$2:$A$199,MATCH(TRIM($B6),People!$B$2:$B$199,0)),IFERROR(INDEX(Teams!$A$2:$A$9,MATCH(TRIM($B6),Teams!$B$2:$B$9,0)),"?? CHECK NAME")))
C7: =IF(TRIM($B7)="","",IFERROR(INDEX(People!$A$2:$A$199,MATCH(TRIM($B7),People!$B$2:$B$199,0)),IFERROR(INDEX(Teams!$A$2:$A$9,MATCH(TRIM($B7),Teams!$B$2:$B$9,0)),"?? CHECK NAME")))
C8: =IF(TRIM($B8)="","",IFERROR(INDEX(People!$A$2:$A$199,MATCH(TRIM($B8),People!$B$2:$B$199,0)),IFERROR(INDEX(Teams!$A$2:$A$9,MATCH(TRIM($B8),Teams!$B$2:$B$9,0)),"?? CHECK NAME")))
A9: Senior Advisors | C9: =IF(TRIM($B9)="","",IFERROR(INDEX(People!$A$2:$A$199,MATCH(TRIM($B9),People!$B$2:$B$199,0)),IFERROR(INDEX(Teams!$A$2:$A$9,MATCH(TRIM($B9),Teams!$B$2:$B$9,0)),"?? CHECK NAME")))
C10: =IF(TRIM($B10)="","",IFERROR(INDEX(People!$A$2:$A$199,MATCH(TRIM($B10),People!$B$2:$B$199,0)),IFERROR(INDEX(Teams!$A$2:$A$9,MATCH(TRIM($B10),Teams!$B$2:$B$9,0)),"?? CHECK NAME")))
C11: =IF(TRIM($B11)="","",IFERROR(INDEX(People!$A$2:$A$199,MATCH(TRIM($B11),People!$B$2:$B$199,0)),IFERROR(INDEX(Teams!$A$2:$A$9,MATCH(TRIM($B11),Teams!$B$2:$B$9,0)),"?? CHECK NAME")))
C12: =IF(TRIM($B12)="","",IFERROR(INDEX(People!$A$2:$A$199,MATCH(TRIM($B12),People!$B$2:$B$199,0)),IFERROR(INDEX(Teams!$A$2:$A$9,MATCH(TRIM($B12),Teams!$B$2:$B$9,0)),"?? CHECK NAME")))
C13: =IF(TRIM($B13)="","",IFERROR(INDEX(People!$A$2:$A$199,MATCH(TRIM($B13),People!$B$2:$B$199,0)),IFERROR(INDEX(Teams!$A$2:$A$9,MATCH(TRIM($B13),Teams!$B$2:$B$9,0)),"?? CHECK NAME")))
A14: Logistics | C14: =IF(TRIM($B14)="","",IFERROR(INDEX(People!$A$2:$A$199,MATCH(TRIM($B14),People!$B$2:$B$199,0)),IFERROR(INDEX(Teams!$A$2:$A$9,MATCH(TRIM($B14),Teams!$B$2:$B$9,0)),"?? CHECK NAME")))
C15: =IF(TRIM($B15)="","",IFERROR(INDEX(People!$A$2:$A$199,MATCH(TRIM($B15),People!$B$2:$B$199,0)),IFERROR(INDEX(Teams!$A$2:$A$9,MATCH(TRIM($B15),Teams!$B$2:$B$9,0)),"?? CHECK NAME")))
C16: =IF(TRIM($B16)="","",IFERROR(INDEX(People!$A$2:$A$199,MATCH(TRIM($B16),People!$B$2:$B$199,0)),IFERROR(INDEX(Teams!$A$2:$A$9,MATCH(TRIM($B16),Teams!$B$2:$B$9,0)),"?? CHECK NAME")))
C17: =IF(TRIM($B17)="","",IFERROR(INDEX(People!$A$2:$A$199,MATCH(TRIM($B17),People!$B$2:$B$199,0)),IFERROR(INDEX(Teams!$A$2:$A$9,MATCH(TRIM($B17),Teams!$B$2:$B$9,0)),"?? CHECK NAME")))
C18: =IF(TRIM($B18)="","",IFERROR(INDEX(People!$A$2:$A$199,MATCH(TRIM($B18),People!$B$2:$B$199,0)),IFERROR(INDEX(Teams!$A$2:$A$9,MATCH(TRIM($B18),Teams!$B$2:$B$9,0)),"?? CHECK NAME")))
A19: Hospitality | C19: =IF(TRIM($B19)="","",IFERROR(INDEX(People!$A$2:$A$199,MATCH(TRIM($B19),People!$B$2:$B$199,0)),IFERROR(INDEX(Teams!$A$2:$A$9,MATCH(TRIM($B19),Teams!$B$2:$B$9,0)),"?? CHECK NAME")))
C20: =IF(TRIM($B20)="","",IFERROR(INDEX(People!$A$2:$A$199,MATCH(TRIM($B20),People!$B$2:$B$199,0)),IFERROR(INDEX(Teams!$A$2:$A$9,MATCH(TRIM($B20),Teams!$B$2:$B$9,0)),"?? CHECK NAME")))
C21: =IF(TRIM($B21)="","",IFERROR(INDEX(People!$A$2:$A$199,MATCH(TRIM($B21),People!$B$2:$B$199,0)),IFERROR(INDEX(Teams!$A$2:$A$9,MATCH(TRIM($B21),Teams!$B$2:$B$9,0)),"?? CHECK NAME")))
C22: =IF(TRIM($B22)="","",IFERROR(INDEX(People!$A$2:$A$199,MATCH(TRIM($B22),People!$B$2:$B$199,0)),IFERROR(INDEX(Teams!$A$2:$A$9,MATCH(TRIM($B22),Teams!$B$2:$B$9,0)),"?? CHECK NAME")))
C23: =IF(TRIM($B23)="","",IFERROR(INDEX(People!$A$2:$A$199,MATCH(TRIM($B23),People!$B$2:$B$199,0)),IFERROR(INDEX(Teams!$A$2:$A$9,MATCH(TRIM($B23),Teams!$B$2:$B$9,0)),"?? CHECK NAME")))
A24: Creative | C24: =IF(TRIM($B24)="","",IFERROR(INDEX(People!$A$2:$A$199,MATCH(TRIM($B24),People!$B$2:$B$199,0)),IFERROR(INDEX(Teams!$A$2:$A$9,MATCH(TRIM($B24),Teams!$B$2:$B$9,0)),"?? CHECK NAME")))
C25: =IF(TRIM($B25)="","",IFERROR(INDEX(People!$A$2:$A$199,MATCH(TRIM($B25),People!$B$2:$B$199,0)),IFERROR(INDEX(Teams!$A$2:$A$9,MATCH(TRIM($B25),Teams!$B$2:$B$9,0)),"?? CHECK NAME")))
C26: =IF(TRIM($B26)="","",IFERROR(INDEX(People!$A$2:$A$199,MATCH(TRIM($B26),People!$B$2:$B$199,0)),IFERROR(INDEX(Teams!$A$2:$A$9,MATCH(TRIM($B26),Teams!$B$2:$B$9,0)),"?? CHECK NAME")))
C27: =IF(TRIM($B27)="","",IFERROR(INDEX(People!$A$2:$A$199,MATCH(TRIM($B27),People!$B$2:$B$199,0)),IFERROR(INDEX(Teams!$A$2:$A$9,MATCH(TRIM($B27),Teams!$B$2:$B$9,0)),"?? CHECK NAME")))
C28: =IF(TRIM($B28)="","",IFERROR(INDEX(People!$A$2:$A$199,MATCH(TRIM($B28),People!$B$2:$B$199,0)),IFERROR(INDEX(Teams!$A$2:$A$9,MATCH(TRIM($B28),Teams!$B$2:$B$9,0)),"?? CHECK NAME")))
A29: Registration | C29: =IF(TRIM($B29)="","",IFERROR(INDEX(People!$A$2:$A$199,MATCH(TRIM($B29),People!$B$2:$B$199,0)),IFERROR(INDEX(Teams!$A$2:$A$9,MATCH(TRIM($B29),Teams!$B$2:$B$9,0)),"?? CHECK NAME")))
C30: =IF(TRIM($B30)="","",IFERROR(INDEX(People!$A$2:$A$199,MATCH(TRIM($B30),People!$B$2:$B$199,0)),IFERROR(INDEX(Teams!$A$2:$A$9,MATCH(TRIM($B30),Teams!$B$2:$B$9,0)),"?? CHECK NAME")))
C31: =IF(TRIM($B31)="","",IFERROR(INDEX(People!$A$2:$A$199,MATCH(TRIM($B31),People!$B$2:$B$199,0)),IFERROR(INDEX(Teams!$A$2:$A$9,MATCH(TRIM($B31),Teams!$B$2:$B$9,0)),"?? CHECK NAME")))
C32: =IF(TRIM($B32)="","",IFERROR(INDEX(People!$A$2:$A$199,MATCH(TRIM($B32),People!$B$2:$B$199,0)),IFERROR(INDEX(Teams!$A$2:$A$9,MATCH(TRIM($B32),Teams!$B$2:$B$9,0)),"?? CHECK NAME")))
C33: =IF(TRIM($B33)="","",IFERROR(INDEX(People!$A$2:$A$199,MATCH(TRIM($B33),People!$B$2:$B$199,0)),IFERROR(INDEX(Teams!$A$2:$A$9,MATCH(TRIM($B33),Teams!$B$2:$B$9,0)),"?? CHECK NAME")))
A34: Head Liaisons | C34: =IF(TRIM($B34)="","",IFERROR(INDEX(People!$A$2:$A$199,MATCH(TRIM($B34),People!$B$2:$B$199,0)),IFERROR(INDEX(Teams!$A$2:$A$9,MATCH(TRIM($B34),Teams!$B$2:$B$9,0)),"?? CHECK NAME")))
C35: =IF(TRIM($B35)="","",IFERROR(INDEX(People!$A$2:$A$199,MATCH(TRIM($B35),People!$B$2:$B$199,0)),IFERROR(INDEX(Teams!$A$2:$A$9,MATCH(TRIM($B35),Teams!$B$2:$B$9,0)),"?? CHECK NAME")))
C36: =IF(TRIM($B36)="","",IFERROR(INDEX(People!$A$2:$A$199,MATCH(TRIM($B36),People!$B$2:$B$199,0)),IFERROR(INDEX(Teams!$A$2:$A$9,MATCH(TRIM($B36),Teams!$B$2:$B$9,0)),"?? CHECK NAME")))
C37: =IF(TRIM($B37)="","",IFERROR(INDEX(People!$A$2:$A$199,MATCH(TRIM($B37),People!$B$2:$B$199,0)),IFERROR(INDEX(Teams!$A$2:$A$9,MATCH(TRIM($B37),Teams!$B$2:$B$9,0)),"?? CHECK NAME")))
C38: =IF(TRIM($B38)="","",IFERROR(INDEX(People!$A$2:$A$199,MATCH(TRIM($B38),People!$B$2:$B$199,0)),IFERROR(INDEX(Teams!$A$2:$A$9,MATCH(TRIM($B38),Teams!$B$2:$B$9,0)),"?? CHECK NAME")))
A39: PR | C39: =IF(TRIM($B39)="","",IFERROR(INDEX(People!$A$2:$A$199,MATCH(TRIM($B39),People!$B$2:$B$199,0)),IFERROR(INDEX(Teams!$A$2:$A$9,MATCH(TRIM($B39),Teams!$B$2:$B$9,0)),"?? CHECK NAME")))
C40: =IF(TRIM($B40)="","",IFERROR(INDEX(People!$A$2:$A$199,MATCH(TRIM($B40),People!$B$2:$B$199,0)),IFERROR(INDEX(Teams!$A$2:$A$9,MATCH(TRIM($B40),Teams!$B$2:$B$9,0)),"?? CHECK NAME")))
...

Sheet Airport
A1: Direction | B1: Date | C1: Applies To | D1: # People | E1: Flight # | F1: Flight Time | G1: Pickup / Leave Time | H1: Arrive | I1: Driver(s) | J1: Vehicle(s) | K1: Driver Phone
A2: Arrival | B2: 46241 | C2: Team: UMD Entouraas | D2: 13 | E2: AA4352 | F2: 0.36180556 | G2: 0.38194444 | H2: 0.42361111 | I2: Example Liaison | J2: Minibus | K2: 555-0101
A3: Arrival | B3: 46241 | C3: Person: Example Dancer | D3: 1 | E3: UA2646 | F3: 0.39513889 | G3: 0.40972222 | H3: 0.45138889 | I3: Example Director | J3: Personal car | K3: 555-0100
A82: Applies To uses the app's assignment grammar: "Team: <name>", "Person: <name>", or "Role: <name>". Flights group people across teams, which is why this stays its own tab — one row per travel party, not per team.
