Workbook

Sheet Instructions
B2: How to use this schedule file
B3: Read this page once before you type anything. It takes about five minutes.
B5: WHAT THIS FILE IS
B6: This file holds the schedule for the whole weekend.
B7: The app reads this file. Then it shows each person only their own schedule on their phone.
B9: If you follow the rules on this page, the app reads the file correctly.
B10: If you break the rules, the app may show someone the wrong time, or show them nothing at all.
B12: STEP 1 — SET THE DATE
B13: Type the date of the Friday of your event in the yellow box.
B14: Event Friday date | C14: 46241
B15: You only do this once. Every day tab works out its own date from this one box.
B16: It even handles the hours after midnight, so nothing lands on the wrong day.
B18: STEP 2 — LEARN THE TABS
B19: The tabs are at the bottom of the window. Here is what each one holds.
B21: Instructions | C21: This page.
B22: Teams | C22: The eight teams. Also the show order, which you fill in later.
B23: People | C23: Every board member, liaison, judge, videographer and RAS rep.
B24: Roster | C24: Every dancer.
B25: Thursday, Friday, | C25: The schedule for each day. One row per person or group.
B26: Saturday, Sunday
B27: Sequences | C27: The recipe for anything that repeats team by team.
B28: Slot Times | C28: When each team starts its turn. Fix a running-late day here.
B29: Vehicles | C29: Which van takes which team, and whether it can get back in time.
B30: Windows | C30: Meals. A range you may use, not an appointment.
B31: Manual Blocks | C31: One-off things that are not a pipeline. Board duties, airport runs.
B32: Export | C32: Calculated. THE ONLY TAB THE APP READS. Never type on it.
B33: Checks | C33: Does the day fit, do rooms clash, is the day humane. Read it before you publish.
B34: Airport | C34: Who is flying, when, and who is driving them.
B36: STEP 3 — FILL IN THE TABS, IN THIS ORDER
B37: Do not skip ahead. Each tab uses what you typed in the ones before it.
B39: 1. Teams | C39: Type each team name and short name. Leave Show Order empty for now.
B40: 2. People | C40: Add one row for each board member, liaison, judge, videographer and RAS rep. Do not put dancers here.
C41: Fill in ID, Full Name, Group, Phone, Email and Type.
C42: If the person is a liaison, you must also pick their Team from the dropdown. If you skip this, they will not show up on any day tab.
C43: Never type in the Key column. It fills itself in.
B44: 3. Roster | C44: Add one row for each dancer. Pick their team from the dropdown. Put Yes in the Captain? column for captains.
B45: 4. Day tabs | C45: Fill in Thursday, Friday, Saturday and Sunday. See the next two sections.
B46: 5. Show order | C46: After the draw, go back to Teams and type each team's number, 1 to 8. Saturday then fills itself in.
B47: 6. Check it | C47: Use the checklist at the bottom of this page before you upload.
B49: Spell each name on the People tab the way you want it to appear on that person's phone. The day tabs copy it exactly.
...

Sheet People
A1: ID | B1: Full Name | C1: Group | D1: Team | E1: Phone | F1: Email | G1: Type | H1: Key (auto)
A2: BRD-01 | B2: Example Director | C2: Directors | E2: 555-0100 | F2: director@example.edu | G2: board | H2: =IF(OR($G2<>"liaison",$D2=""),"",$D2&"#"&COUNTIFS($D$2:$D2,$D2,$G$2:$G2,"liaison"))
A3: LIA-01 | B3: Example Liaison One | C3: Liaisons | D3: UNC Taar Heel Raas | E3: 555-0101 | F3: lia1@example.edu | G3: liaison | H3: =IF(OR($G3<>"liaison",$D3=""),"",$D3&"#"&COUNTIFS($D$2:$D3,$D3,$G$2:$G3,"liaison"))
A4: LIA-02 | B4: Example Liaison Two | C4: Liaisons | D4: UNC Taar Heel Raas | E4: 555-0102 | F4: lia2@example.edu | G4: liaison | H4: =IF(OR($G4<>"liaison",$D4=""),"",$D4&"#"&COUNTIFS($D$2:$D4,$D4,$G$2:$G4,"liaison"))
A5: LIA-03 | B5: Example Liaison Three | C5: Liaisons | D5: UNC Taar Heel Raas | E5: 555-0103 | F5: lia3@example.edu | G5: liaison | H5: =IF(OR($G5<>"liaison",$D5=""),"",$D5&"#"&COUNTIFS($D$2:$D5,$D5,$G$2:$G5,"liaison"))
A6: JDG-01 | B6: Example Judge | C6: Judging | E6: 555-0104 | F6: judge@example.com | G6: judge | H6: =IF(OR($G6<>"liaison",$D6=""),"",$D6&"#"&COUNTIFS($D$2:$D6,$D6,$G$2:$G6,"liaison"))
A7: VID-01 | B7: Example Videographer | C7: External | E7: 555-0105 | F7: video@example.com | G7: videographer | H7: =IF(OR($G7<>"liaison",$D7=""),"",$D7&"#"&COUNTIFS($D$2:$D7,$D7,$G$2:$G7,"liaison"))
H8: =IF(OR($G8<>"liaison",$D8=""),"",$D8&"#"&COUNTIFS($D$2:$D8,$D8,$G$2:$G8,"liaison"))
H9: =IF(OR($G9<>"liaison",$D9=""),"",$D9&"#"&COUNTIFS($D$2:$D9,$D9,$G$2:$G9,"liaison"))
H10: =IF(OR($G10<>"liaison",$D10=""),"",$D10&"#"&COUNTIFS($D$2:$D10,$D10,$G$2:$G10,"liaison"))
H11: =IF(OR($G11<>"liaison",$D11=""),"",$D11&"#"&COUNTIFS($D$2:$D11,$D11,$G$2:$G11,"liaison"))
H12: =IF(OR($G12<>"liaison",$D12=""),"",$D12&"#"&COUNTIFS($D$2:$D12,$D12,$G$2:$G12,"liaison"))
H13: =IF(OR($G13<>"liaison",$D13=""),"",$D13&"#"&COUNTIFS($D$2:$D13,$D13,$G$2:$G13,"liaison"))
H14: =IF(OR($G14<>"liaison",$D14=""),"",$D14&"#"&COUNTIFS($D$2:$D14,$D14,$G$2:$G14,"liaison"))
H15: =IF(OR($G15<>"liaison",$D15=""),"",$D15&"#"&COUNTIFS($D$2:$D15,$D15,$G$2:$G15,"liaison"))
H16: =IF(OR($G16<>"liaison",$D16=""),"",$D16&"#"&COUNTIFS($D$2:$D16,$D16,$G$2:$G16,"liaison"))
H17: =IF(OR($G17<>"liaison",$D17=""),"",$D17&"#"&COUNTIFS($D$2:$D17,$D17,$G$2:$G17,"liaison"))
H18: =IF(OR($G18<>"liaison",$D18=""),"",$D18&"#"&COUNTIFS($D$2:$D18,$D18,$G$2:$G18,"liaison"))
H19: =IF(OR($G19<>"liaison",$D19=""),"",$D19&"#"&COUNTIFS($D$2:$D19,$D19,$G$2:$G19,"liaison"))
... H199: =IF(OR($G199<>"liaison",$D199=""),"",$D199&"#"&COUNTIFS($D$2:$D199,$D199,$G$2:$G199,"liaison"))
A201: Set Type to "liaison" and pick a Team, and that person appears on every day tab automatically — the first five rows for a team become its liaisons 1 to 5.
A202: Key is computed. Do not type in it.

Sheet Teams
A1: ID | B1: Team Name | C1: Abbrev | D1: Show Order | E1: Check | F1: Captain(s) | G1: Liaison Contact
A2: TM-UNC | B2: UNC Taar Heel Raas | C2: UNC | E2: =IF($D2="","",IF(COUNTIF($D$2:$D$9,$D2)>1,"DUPLICATE","OK"))
A3: TM-ILL | B3: Illini Raas | C3: Illini | E3: =IF($D3="","",IF(COUNTIF($D$2:$D$9,$D3)>1,"DUPLICATE","OK"))
A4: TM-UTD | B4: UTD Taraas | C4: UTD | E4: =IF($D4="","",IF(COUNTIF($D$2:$D$9,$D4)>1,"DUPLICATE","OK"))
A5: TM-UVA | B5: UVA Hooraas | C5: UVA | E5: =IF($D5="","",IF(COUNTIF($D$2:$D$9,$D5)>1,"DUPLICATE","OK"))
A6: TM-UMD | B6: UMD Entouraas | C6: UMD | E6: =IF($D6="","",IF(COUNTIF($D$2:$D$9,$D6)>1,"DUPLICATE","OK"))
A7: TM-UMI | B7: Michigan Wolveraas | C7: UMich | E7: =IF($D7="","",IF(COUNTIF($D$2:$D$9,$D7)>1,"DUPLICATE","OK"))
A8: TM-MSU | B8: MSU Raasparty | C8: MSU | E8: =IF($D8="","",IF(COUNTIF($D$2:$D$9,$D8)>1,"DUPLICATE","OK"))
A9: TM-GT | B9: GT Ramblin Raas | C9: GT | E9: =IF($D9="","",IF(COUNTIF($D$2:$D$9,$D9)>1,"DUPLICATE","OK"))
A11: Show Order is the running order, 1-8. Leave it blank until the draw — Saturday's grid is built against slots, not teams, so it can be filled in before you know who is where.
A12: Fill this column in and Saturday resolves itself: every "Show Order N" row picks up the team sitting in slot N, and the app imports it as that team's schedule.
A13: Check flags a slot given to two teams. Every row must read OK before you upload.

Sheet Roster
A1: First Name | B1: Last Name | C1: Team | D1: Phone | E1: Email | F1: Captain? | G1: Dietary Restrictions | H1: T-Shirt Size
A2: Example | B2: Dancer | C2: UNC Taar Heel Raas | D2: 555-0110 | E2: dancer@example.edu | F2: No | G2: Vegetarian | H2: M
A261: One row per dancer, Team as a column — replaces last year's eight per-team tabs. Captain? replaces the asterisk on the first name.

Sheet Thursday
A1: Group | B1: Name | C1: ID | D1: =Instructions!$C$14-1 | AZ1: =Instructions!$C$14
D2: 0.5 | E2: 0.51041667 | F2: 0.52083333 | G2: 0.53125 | H2: 0.54166667 | I2: 0.55208333 | J2: 0.5625 | K2: 0.57291667 | L2: 0.58333333 | M2: 0.59375 | N2: 0.60416667 | O2: 0.61458333 | P2: 0.625 | Q2: 0.63541667 | R2: 0.64583333 | S2: 0.65625 | T2: 0.66666667 | U2: 0.67708333 | V2: 0.6875 | W2: 0.69791667 | X2: 0.70833333 | Y2: 0.71875 | Z2: 0.72916667 | AA2: 0.73958333 | AB2: 0.75 | AC2: 0.76041667 | AD2: 0.77083333 | AE2: 0.78125 | AF2: 0.79166667 | AG2: 0.80208333 | AH2: 0.8125 | AI2: 0.82291667 | AJ2: 0.83333333 | AK2: 0.84375 | AL2: 0.85416667 | AM2: 0.86458333 | AN2: 0.875 | AO2: 0.88541667 | AP2: 0.89583333 | AQ2: 0.90625 | AR2: 0.91666667 | AS2: 0.92708333 | AT2: 0.9375 | AU2: 0.94791667 | AV2: 0.95833333 | AW2: 0.96875 | AX2: 0.97916667 | AY2: 0.98958333 | AZ2: 0 | BA2: 0.010416667 | BB2: 0.020833333 | BC2: 0.03125 | BD2: 0.041666667 | BE2: 0.052083333 | BF2: 0.0625 | BG2: 0.072916667 | BH2: 0.083333333 | BI2: 0.09375 | BJ2: 0.10416667 | BK2: 0.11458333
A3: BOARD MEMBERS
A4: Directors | C4: =IF(TRIM($B4)="","",IFERROR(INDEX(People!$A$2:$A$199,MATCH(TRIM($B4),People!$B$2:$B$199,0)),IFERROR(INDEX(Teams!$A$2:$A$9,MATCH(TRIM($B4),Teams!$B$2:$B$9,0)),"?? CHECK NAME")))
C5: =IF(TRIM($B5)="","",IFERROR(INDEX(People!$A$2:$A$199,MATCH(TRIM($B5),People!$B$2:$B$199,0)),IFERROR(INDEX(Teams!$A$2:$A$9,MATCH(TRIM($B5),Teams!$B$2:$B$9,0)),"?? CHECK NAME")))
C6: =IF(TRIM($B6)="","",IFERROR(INDEX(People!$A$2:$A$199,MATCH(TRIM($B6),People!$B$2:$B$199,0)),IFERROR(INDEX(Teams!$A$2:$A$9,MATCH(TRIM($B6),Teams!$B$2:$B$9,0)),"?? CHECK NAME")))
C7: =IF(TRIM($B7)="","",IFERROR(INDEX(People!$A$2:$A$199,MATCH(TRIM($B7),People!$B$2:$B$199,0)),IFERROR(INDEX(Teams!$A$2:$A$9,MATCH(TRIM($B7),Teams!$B$2:$B$9,0)),"?? CHECK NAME")))
C8: =IF(TRIM($B8)="","",IFERROR(INDEX(People!$A$2:$A$199,MATCH(TRIM($B8),People!$B$2:$B$199,0)),IFERROR(INDEX(Teams!$A$2:$A$9,MATCH(TRIM($B8),Teams!$B$2:$B$9,0)),"?? CHECK NAME")))
A9: Senior Advisors | C9: =IF(TRIM($B9)="","",IFERROR(INDEX(People!$A$2:$A$199,MATCH(TRIM($B9),People!$B$2:$B$199,0)),IFERROR(INDEX(Teams!$A$2:$A$9,MATCH(TRIM($B9),Teams!$B$2:$B$9,0)),"?? CHECK NAME")))
C10: =IF(TRIM($B10)="","",IFERROR(INDEX(People!$A$2:$A$199,MATCH(TRIM($B10),People!$B$2:$B$199,0)),IFERROR(INDEX(Teams!$A$2:$A$9,MATCH(TRIM($B10),Teams!$B$2:$B$9,0)),"?? CHECK NAME")))
C11: =IF(TRIM($B11)="","",IFERROR(INDEX(People!$A$2:$A$199,MATCH(TRIM($B11),People!$B$2:$B$199,0)),IFERROR(INDEX(Teams!$A$2:$A$9,MATCH(TRIM($B11),Teams!$B$2:$B$9,0)),"?? CHECK NAME")))
C12: =IF(TRIM($B12)="","",IFERROR(INDEX(People!$A$2:$A$199,MATCH(TRIM($B12),People!$B$2:$B$199,0)),IFERROR(INDEX(Teams!$A$2:$A$9,MATCH(TRIM($B12),Teams!$B$2:$B$9,0)),"?? CHECK NAME")))
C13: =IF(TRIM($B13)="","",IFERROR(INDEX(People!$A$2:$A$199,MATCH(TRIM($B13),People!$B$2:$B$199,0)),IFERROR(INDEX(Teams!$A$2:$A$9,MATCH(TRIM($B13),Teams!$B$2:$B$9,0)),"?? CHECK NAME")))
A14: Logistics | C14: =IF(TRIM($B14)="","",IFERROR(INDEX(People!$A$2:$A$199,MATCH(TRIM($B14),People!$B$2:$B$199,0)),IFERROR(INDEX(Teams!$A$2:$A$9,MATCH(TRIM($B14),Teams!$B$2:$B$9,0)),"?? CHECK NAME")))
C15: =IF(TRIM($B15)="","",IFERROR(INDEX(People!$A$2:$A$199,MATCH(TRIM($B15),People!$B$2:$B$199,0)),IFERROR(INDEX(Teams!$A$2:$A$9,MATCH(TRIM($B15),Teams!$B$2:$B$9,0)),"?? CHECK NAME")))
C16: =IF(TRIM($B16)="","",IFERROR(INDEX(People!$A$2:$A$199,MATCH(TRIM($B16),People!$B$2:$B$199,0)),IFERROR(INDEX(Teams!$A$2:$A$9,MATCH(TRIM($B16),Teams!$B$2:$B$9,0)),"?? CHECK NAME")))
C17: =IF(TRIM($B17)="","",IFERROR(INDEX(People!$A$2:$A$199,MATCH(TRIM($B17),People!$B$2:$B$199,0)),IFERROR(INDEX(Teams!$A$2:$A$9,MATCH(TRIM($B17),Teams!$B$2:$B$9,0)),"?? CHECK NAME")))
C18: =IF(TRIM($B18)="","",IFERROR(INDEX(People!$A$2:$A$199,MATCH(TRIM($B18),People!$B$2:$B$199,0)),IFERROR(INDEX(Teams!$A$2:$A$9,MATCH(TRIM($B18),Teams!$B$2:$B$9,0)),"?? CHECK NAME")))
A19: Hospitality | C19: =IF(TRIM($B19)="","",IFERROR(INDEX(People!$A$2:$A$199,MATCH(TRIM($B19),People!$B$2:$B$199,0)),IFERROR(INDEX(Teams!$A$2:$A$9,MATCH(TRIM($B19),Teams!$B$2:$B$9,0)),"?? CHECK NAME")))
C20: =IF(TRIM($B20)="","",IFERROR(INDEX(People!$A$2:$A$199,MATCH(TRIM($B20),People!$B$2:$B$199,0)),IFERROR(INDEX(Teams!$A$2:$A$9,MATCH(TRIM($B20),Teams!$B$2:$B$9,0)),"?? CHECK NAME")))
C21: =IF(TRIM($B21)="","",IFERROR(INDEX(People!$A$2:$A$199,MATCH(TRIM($B21),People!$B$2:$B$199,0)),IFERROR(INDEX(Teams!$A$2:$A$9,MATCH(TRIM($B21),Teams!$B$2:$B$9,0)),"?? CHECK NAME")))
C22: =IF(TRIM($B22)="","",IFERROR(INDEX(People!$A$2:$A$199,MATCH(TRIM($B22),People!$B$2:$B$199,0)),IFERROR(INDEX(Teams!$A$2:$A$9,MATCH(TRIM($B22),Teams!$B$2:$B$9,0)),"?? CHECK NAME")))
C23: =IF(TRIM($B23)="","",IFERROR(INDEX(People!$A$2:$A$199,MATCH(TRIM($B23),People!$B$2:$B$199,0)),IFERROR(INDEX(Teams!$A$2:$A$9,MATCH(TRIM($B23),Teams!$B$2:$B$9,0)),"?? CHECK NAME")))
A24: Creative | C24: =IF(TRIM($B24)="","",IFERROR(INDEX(People!$A$2:$A$199,MATCH(TRIM($B24),People!$B$2:$B$199,0)),IFERROR(INDEX(Teams!$A$2:$A$9,MATCH(TRIM($B24),Teams!$B$2:$B$9,0)),"?? CHECK NAME")))
C25: =IF(TRIM($B25)="","",IFERROR(INDEX(People!$A$2:$A$199,MATCH(TRIM($B25),People!$B$2:$B$199,0)),IFERROR(INDEX(Teams!$A$2:$A$9,MATCH(TRIM($B25),Teams!$B$2:$B$9,0)),"?? CHECK NAME")))
C26: =IF(TRIM($B26)="","",IFERROR(INDEX(People!$A$2:$A$199,MATCH(TRIM($B26),People!$B$2:$B$199,0)),IFERROR(INDEX(Teams!$A$2:$A$9,MATCH(TRIM($B26),Teams!$B$2:$B$9,0)),"?? CHECK NAME")))
C27: =IF(TRIM($B27)="","",IFERROR(INDEX(People!$A$2:$A$199,MATCH(TRIM($B27),People!$B$2:$B$199,0)),IFERROR(INDEX(Teams!$A$2:$A$9,MATCH(TRIM($B27),Teams!$B$2:$B$9,0)),"?? CHECK NAME")))
C28: =IF(TRIM($B28)="","",IFERROR(INDEX(People!$A$2:$A$199,MATCH(TRIM($B28),People!$B$2:$B$199,0)),IFERROR(INDEX(Teams!$A$2:$A$9,MATCH(TRIM($B28),Teams!$B$2:$B$9,0)),"?? CHECK NAME")))
A29: Registration | C29: =IF(TRIM($B29)="","",IFERROR(INDEX(People!$A$2:$A$199,MATCH(TRIM($B29),People!$B$2:$B$199,0)),IFERROR(INDEX(Teams!$A$2:$A$9,MATCH(TRIM($B29),Teams!$B$2:$B$9,0)),"?? CHECK NAME")))
C30: =IF(TRIM($B30)="","",IFERROR(INDEX(People!$A$2:$A$199,MATCH(TRIM($B30),People!$B$2:$B$199,0)),IFERROR(INDEX(Teams!$A$2:$A$9,MATCH(TRIM($B30),Teams!$B$2:$B$9,0)),"?? CHECK NAME")))
C31: =IF(TRIM($B31)="","",IFERROR(INDEX(People!$A$2:$A$199,MATCH(TRIM($B31),People!$B$2:$B$199,0)),IFERROR(INDEX(Teams!$A$2:$A$9,MATCH(TRIM($B31),Teams!$B$2:$B$9,0)),"?? CHECK NAME")))
C32: =IF(TRIM($B32)="","",IFERROR(INDEX(People!$A$2:$A$199,MATCH(TRIM($B32),People!$B$2:$B$199,0)),IFERROR(INDEX(Teams!$A$2:$A$9,MATCH(TRIM($B32),Teams!$B$2:$B$9,0)),"?? CHECK NAME")))
C33: =IF(TRIM($B33)="","",IFERROR(INDEX(People!$A$2:$A$199,MATCH(TRIM($B33),People!$B$2:$B$199,0)),IFERROR(INDEX(Teams!$A$2:$A$9,MATCH(TRIM($B33),Teams!$B$2:$B$9,0)),"?? CHECK NAME")))
A34: Head Liaisons | C34: =IF(TRIM($B34)="","",IFERROR(INDEX(People!$A$2:$A$199,MATCH(TRIM($B34),People!$B$2:$B$199,0)),IFERROR(INDEX(Teams!$A$2:$A$9,MATCH(TRIM($B34),Teams!$B$2:$B$9,0)),"?? CHECK NAME")))
C35: =IF(TRIM($B35)="","",IFERROR(INDEX(People!$A$2:$A$199,MATCH(TRIM($B35),People!$B$2:$B$199,0)),IFERROR(INDEX(Teams!$A$2:$A$9,MATCH(TRIM($B35),Teams!$B$2:$B$9,0)),"?? CHECK NAME")))
C36: =IF(TRIM($B36)="","",IFERROR(INDEX(People!$A$2:$A$199,MATCH(TRIM($B36),People!$B$2:$B$199,0)),IFERROR(INDEX(Teams!$A$2:$A$9,MATCH(TRIM($B36),Teams!$B$2:$B$9,0)),"?? CHECK NAME")))
C37: =IF(TRIM($B37)="","",IFERROR(INDEX(People!$A$2:$A$199,MATCH(TRIM($B37),People!$B$2:$B$199,0)),IFERROR(INDEX(Teams!$A$2:$A$9,MATCH(TRIM($B37),Teams!$B$2:$B$9,0)),"?? CHECK NAME")))
C38: =IF(TRIM($B38)="","",IFERROR(INDEX(People!$A$2:$A$199,MATCH(TRIM($B38),People!$B$2:$B$199,0)),IFERROR(INDEX(Teams!$A$2:$A$9,MATCH(TRIM($B38),Teams!$B$2:$B$9,0)),"?? CHECK NAME")))
A39: PR | C39: =IF(TRIM($B39)="","",IFERROR(INDEX(People!$A$2:$A$199,MATCH(TRIM($B39),People!$B$2:$B$199,0)),IFERROR(INDEX(Teams!$A$2:$A$9,MATCH(TRIM($B39),Teams!$B$2:$B$9,0)),"?? CHECK NAME")))
C40: =IF(TRIM($B40)="","",IFERROR(INDEX(People!$A$2:$A$199,MATCH(TRIM($B40),People!$B$2:$B$199,0)),IFERROR(INDEX(Teams!$A$2:$A$9,MATCH(TRIM($B40),Teams!$B$2:$B$9,0)),"?? CHECK NAME")))
...

Sheet Friday
A1: Group | B1: Name | C1: ID | D1: =Instructions!$C$14 | CB1: =Instructions!$C$14+1
D2: 0.20833333 | E2: 0.21875 | F2: 0.22916667 | G2: 0.23958333 | H2: 0.25 | I2: 0.26041667 | J2: 0.27083333 | K2: 0.28125 | L2: 0.29166667 | M2: 0.30208333 | N2: 0.3125 | O2: 0.32291667 | P2: 0.33333333 | Q2: 0.34375 | R2: 0.35416667 | S2: 0.36458333 | T2: 0.375 | U2: 0.38541667 | V2: 0.39583333 | W2: 0.40625 | X2: 0.41666667 | Y2: 0.42708333 | Z2: 0.4375 | AA2: 0.44791667 | AB2: 0.45833333 | AC2: 0.46875 | AD2: 0.47916667 | AE2: 0.48958333 | AF2: 0.5 | AG2: 0.51041667 | AH2: 0.52083333 | AI2: 0.53125 | AJ2: 0.54166667 | AK2: 0.55208333 | AL2: 0.5625 | AM2: 0.57291667 | AN2: 0.58333333 | AO2: 0.59375 | AP2: 0.60416667 | AQ2: 0.61458333 | AR2: 0.625 | AS2: 0.63541667 | AT2: 0.64583333 | AU2: 0.65625 | AV2: 0.66666667 | AW2: 0.67708333 | AX2: 0.6875 | AY2: 0.69791667 | AZ2: 0.70833333 | BA2: 0.71875 | BB2: 0.72916667 | BC2: 0.73958333 | BD2: 0.75 | BE2: 0.76041667 | BF2: 0.77083333 | BG2: 0.78125 | BH2: 0.79166667 | BI2: 0.80208333 | BJ2: 0.8125 | BK2: 0.82291667 | BL2: 0.83333333 | BM2: 0.84375 | BN2: 0.85416667 | BO2: 0.86458333 | BP2: 0.875 | BQ2: 0.88541667 | BR2: 0.89583333 | BS2: 0.90625 | BT2: 0.91666667 | BU2: 0.92708333 | BV2: 0.9375 | BW2: 0.94791667 | BX2: 0.95833333 | BY2: 0.96875 | BZ2: 0.97916667 | CA2: 0.98958333 | CB2: 0 | CC2: 0.010416667 | CD2: 0.020833333 | CE2: 0.03125
A3: BOARD MEMBERS
A4: Directors | B4: Example Director | C4: =IF(TRIM($B4)="","",IFERROR(INDEX(People!$A$2:$A$199,MATCH(TRIM($B4),People!$B$2:$B$199,0)),IFERROR(INDEX(Teams!$A$2:$A$9,MATCH(TRIM($B4),Teams!$B$2:$B$9,0)),"?? CHECK NAME"))) | H4: 6:00 AM - 5:00 PM HOTEL (REG ROOM) Check in teams, help Head Liaisons with room setup
C5: =IF(TRIM($B5)="","",IFERROR(INDEX(People!$A$2:$A$199,MATCH(TRIM($B5),People!$B$2:$B$199,0)),IFERROR(INDEX(Teams!$A$2:$A$9,MATCH(TRIM($B5),Teams!$B$2:$B$9,0)),"?? CHECK NAME")))
C6: =IF(TRIM($B6)="","",IFERROR(INDEX(People!$A$2:$A$199,MATCH(TRIM($B6),People!$B$2:$B$199,0)),IFERROR(INDEX(Teams!$A$2:$A$9,MATCH(TRIM($B6),Teams!$B$2:$B$9,0)),"?? CHECK NAME")))
C7: =IF(TRIM($B7)="","",IFERROR(INDEX(People!$A$2:$A$199,MATCH(TRIM($B7),People!$B$2:$B$199,0)),IFERROR(INDEX(Teams!$A$2:$A$9,MATCH(TRIM($B7),Teams!$B$2:$B$9,0)),"?? CHECK NAME")))
C8: =IF(TRIM($B8)="","",IFERROR(INDEX(People!$A$2:$A$199,MATCH(TRIM($B8),People!$B$2:$B$199,0)),IFERROR(INDEX(Teams!$A$2:$A$9,MATCH(TRIM($B8),Teams!$B$2:$B$9,0)),"?? CHECK NAME")))
A9: Senior Advisors | C9: =IF(TRIM($B9)="","",IFERROR(INDEX(People!$A$2:$A$199,MATCH(TRIM($B9),People!$B$2:$B$199,0)),IFERROR(INDEX(Teams!$A$2:$A$9,MATCH(TRIM($B9),Teams!$B$2:$B$9,0)),"?? CHECK NAME")))
C10: =IF(TRIM($B10)="","",IFERROR(INDEX(People!$A$2:$A$199,MATCH(TRIM($B10),People!$B$2:$B$199,0)),IFERROR(INDEX(Teams!$A$2:$A$9,MATCH(TRIM($B10),Teams!$B$2:$B$9,0)),"?? CHECK NAME")))
C11: =IF(TRIM($B11)="","",IFERROR(INDEX(People!$A$2:$A$199,MATCH(TRIM($B11),People!$B$2:$B$199,0)),IFERROR(INDEX(Teams!$A$2:$A$9,MATCH(TRIM($B11),Teams!$B$2:$B$9,0)),"?? CHECK NAME")))
C12: =IF(TRIM($B12)="","",IFERROR(INDEX(People!$A$2:$A$199,MATCH(TRIM($B12),People!$B$2:$B$199,0)),IFERROR(INDEX(Teams!$A$2:$A$9,MATCH(TRIM($B12),Teams!$B$2:$B$9,0)),"?? CHECK NAME")))
C13: =IF(TRIM($B13)="","",IFERROR(INDEX(People!$A$2:$A$199,MATCH(TRIM($B13),People!$B$2:$B$199,0)),IFERROR(INDEX(Teams!$A$2:$A$9,MATCH(TRIM($B13),Teams!$B$2:$B$9,0)),"?? CHECK NAME")))
A14: Logistics | C14: =IF(TRIM($B14)="","",IFERROR(INDEX(People!$A$2:$A$199,MATCH(TRIM($B14),People!$B$2:$B$199,0)),IFERROR(INDEX(Teams!$A$2:$A$9,MATCH(TRIM($B14),Teams!$B$2:$B$9,0)),"?? CHECK NAME")))
C15: =IF(TRIM($B15)="","",IFERROR(INDEX(People!$A$2:$A$199,MATCH(TRIM($B15),People!$B$2:$B$199,0)),IFERROR(INDEX(Teams!$A$2:$A$9,MATCH(TRIM($B15),Teams!$B$2:$B$9,0)),"?? CHECK NAME")))
C16: =IF(TRIM($B16)="","",IFERROR(INDEX(People!$A$2:$A$199,MATCH(TRIM($B16),People!$B$2:$B$199,0)),IFERROR(INDEX(Teams!$A$2:$A$9,MATCH(TRIM($B16),Teams!$B$2:$B$9,0)),"?? CHECK NAME")))
C17: =IF(TRIM($B17)="","",IFERROR(INDEX(People!$A$2:$A$199,MATCH(TRIM($B17),People!$B$2:$B$199,0)),IFERROR(INDEX(Teams!$A$2:$A$9,MATCH(TRIM($B17),Teams!$B$2:$B$9,0)),"?? CHECK NAME")))
C18: =IF(TRIM($B18)="","",IFERROR(INDEX(People!$A$2:$A$199,MATCH(TRIM($B18),People!$B$2:$B$199,0)),IFERROR(INDEX(Teams!$A$2:$A$9,MATCH(TRIM($B18),Teams!$B$2:$B$9,0)),"?? CHECK NAME")))
A19: Hospitality | C19: =IF(TRIM($B19)="","",IFERROR(INDEX(People!$A$2:$A$199,MATCH(TRIM($B19),People!$B$2:$B$199,0)),IFERROR(INDEX(Teams!$A$2:$A$9,MATCH(TRIM($B19),Teams!$B$2:$B$9,0)),"?? CHECK NAME")))
C20: =IF(TRIM($B20)="","",IFERROR(INDEX(People!$A$2:$A$199,MATCH(TRIM($B20),People!$B$2:$B$199,0)),IFERROR(INDEX(Teams!$A$2:$A$9,MATCH(TRIM($B20),Teams!$B$2:$B$9,0)),"?? CHECK NAME")))
C21: =IF(TRIM($B21)="","",IFERROR(INDEX(People!$A$2:$A$199,MATCH(TRIM($B21),People!$B$2:$B$199,0)),IFERROR(INDEX(Teams!$A$2:$A$9,MATCH(TRIM($B21),Teams!$B$2:$B$9,0)),"?? CHECK NAME")))
C22: =IF(TRIM($B22)="","",IFERROR(INDEX(People!$A$2:$A$199,MATCH(TRIM($B22),People!$B$2:$B$199,0)),IFERROR(INDEX(Teams!$A$2:$A$9,MATCH(TRIM($B22),Teams!$B$2:$B$9,0)),"?? CHECK NAME")))
C23: =IF(TRIM($B23)="","",IFERROR(INDEX(People!$A$2:$A$199,MATCH(TRIM($B23),People!$B$2:$B$199,0)),IFERROR(INDEX(Teams!$A$2:$A$9,MATCH(TRIM($B23),Teams!$B$2:$B$9,0)),"?? CHECK NAME")))
A24: Creative | C24: =IF(TRIM($B24)="","",IFERROR(INDEX(People!$A$2:$A$199,MATCH(TRIM($B24),People!$B$2:$B$199,0)),IFERROR(INDEX(Teams!$A$2:$A$9,MATCH(TRIM($B24),Teams!$B$2:$B$9,0)),"?? CHECK NAME")))
C25: =IF(TRIM($B25)="","",IFERROR(INDEX(People!$A$2:$A$199,MATCH(TRIM($B25),People!$B$2:$B$199,0)),IFERROR(INDEX(Teams!$A$2:$A$9,MATCH(TRIM($B25),Teams!$B$2:$B$9,0)),"?? CHECK NAME")))
C26: =IF(TRIM($B26)="","",IFERROR(INDEX(People!$A$2:$A$199,MATCH(TRIM($B26),People!$B$2:$B$199,0)),IFERROR(INDEX(Teams!$A$2:$A$9,MATCH(TRIM($B26),Teams!$B$2:$B$9,0)),"?? CHECK NAME")))
C27: =IF(TRIM($B27)="","",IFERROR(INDEX(People!$A$2:$A$199,MATCH(TRIM($B27),People!$B$2:$B$199,0)),IFERROR(INDEX(Teams!$A$2:$A$9,MATCH(TRIM($B27),Teams!$B$2:$B$9,0)),"?? CHECK NAME")))
C28: =IF(TRIM($B28)="","",IFERROR(INDEX(People!$A$2:$A$199,MATCH(TRIM($B28),People!$B$2:$B$199,0)),IFERROR(INDEX(Teams!$A$2:$A$9,MATCH(TRIM($B28),Teams!$B$2:$B$9,0)),"?? CHECK NAME")))
A29: Registration | C29: =IF(TRIM($B29)="","",IFERROR(INDEX(People!$A$2:$A$199,MATCH(TRIM($B29),People!$B$2:$B$199,0)),IFERROR(INDEX(Teams!$A$2:$A$9,MATCH(TRIM($B29),Teams!$B$2:$B$9,0)),"?? CHECK NAME")))
C30: =IF(TRIM($B30)="","",IFERROR(INDEX(People!$A$2:$A$199,MATCH(TRIM($B30),People!$B$2:$B$199,0)),IFERROR(INDEX(Teams!$A$2:$A$9,MATCH(TRIM($B30),Teams!$B$2:$B$9,0)),"?? CHECK NAME")))
C31: =IF(TRIM($B31)="","",IFERROR(INDEX(People!$A$2:$A$199,MATCH(TRIM($B31),People!$B$2:$B$199,0)),IFERROR(INDEX(Teams!$A$2:$A$9,MATCH(TRIM($B31),Teams!$B$2:$B$9,0)),"?? CHECK NAME")))
C32: =IF(TRIM($B32)="","",IFERROR(INDEX(People!$A$2:$A$199,MATCH(TRIM($B32),People!$B$2:$B$199,0)),IFERROR(INDEX(Teams!$A$2:$A$9,MATCH(TRIM($B32),Teams!$B$2:$B$9,0)),"?? CHECK NAME")))
C33: =IF(TRIM($B33)="","",IFERROR(INDEX(People!$A$2:$A$199,MATCH(TRIM($B33),People!$B$2:$B$199,0)),IFERROR(INDEX(Teams!$A$2:$A$9,MATCH(TRIM($B33),Teams!$B$2:$B$9,0)),"?? CHECK NAME")))
A34: Head Liaisons | C34: =IF(TRIM($B34)="","",IFERROR(INDEX(People!$A$2:$A$199,MATCH(TRIM($B34),People!$B$2:$B$199,0)),IFERROR(INDEX(Teams!$A$2:$A$9,MATCH(TRIM($B34),Teams!$B$2:$B$9,0)),"?? CHECK NAME")))
C35: =IF(TRIM($B35)="","",IFERROR(INDEX(People!$A$2:$A$199,MATCH(TRIM($B35),People!$B$2:$B$199,0)),IFERROR(INDEX(Teams!$A$2:$A$9,MATCH(TRIM($B35),Teams!$B$2:$B$9,0)),"?? CHECK NAME")))
C36: =IF(TRIM($B36)="","",IFERROR(INDEX(People!$A$2:$A$199,MATCH(TRIM($B36),People!$B$2:$B$199,0)),IFERROR(INDEX(Teams!$A$2:$A$9,MATCH(TRIM($B36),Teams!$B$2:$B$9,0)),"?? CHECK NAME")))
C37: =IF(TRIM($B37)="","",IFERROR(INDEX(People!$A$2:$A$199,MATCH(TRIM($B37),People!$B$2:$B$199,0)),IFERROR(INDEX(Teams!$A$2:$A$9,MATCH(TRIM($B37),Teams!$B$2:$B$9,0)),"?? CHECK NAME")))
C38: =IF(TRIM($B38)="","",IFERROR(INDEX(People!$A$2:$A$199,MATCH(TRIM($B38),People!$B$2:$B$199,0)),IFERROR(INDEX(Teams!$A$2:$A$9,MATCH(TRIM($B38),Teams!$B$2:$B$9,0)),"?? CHECK NAME")))
A39: PR | C39: =IF(TRIM($B39)="","",IFERROR(INDEX(People!$A$2:$A$199,MATCH(TRIM($B39),People!$B$2:$B$199,0)),IFERROR(INDEX(Teams!$A$2:$A$9,MATCH(TRIM($B39),Teams!$B$2:$B$9,0)),"?? CHECK NAME")))
C40: =IF(TRIM($B40)="","",IFERROR(INDEX(People!$A$2:$A$199,MATCH(TRIM($B40),People!$B$2:$B$199,0)),IFERROR(INDEX(Teams!$A$2:$A$9,MATCH(TRIM($B40),Teams!$B$2:$B$9,0)),"?? CHECK NAME")))
...

Sheet Saturday
A1: Group | B1: Name | C1: ID | D1: =Instructions!$C$14+1 | CH1: =Instructions!$C$14+2
D2: 0.14583333 | E2: 0.15625 | F2: 0.16666667 | G2: 0.17708333 | H2: 0.1875 | I2: 0.19791667 | J2: 0.20833333 | K2: 0.21875 | L2: 0.22916667 | M2: 0.23958333 | N2: 0.25 | O2: 0.26041667 | P2: 0.27083333 | Q2: 0.28125 | R2: 0.29166667 | S2: 0.30208333 | T2: 0.3125 | U2: 0.32291667 | V2: 0.33333333 | W2: 0.34375 | X2: 0.35416667 | Y2: 0.36458333 | Z2: 0.375 | AA2: 0.38541667 | AB2: 0.39583333 | AC2: 0.40625 | AD2: 0.41666667 | AE2: 0.42708333 | AF2: 0.4375 | AG2: 0.44791667 | AH2: 0.45833333 | AI2: 0.46875 | AJ2: 0.47916667 | AK2: 0.48958333 | AL2: 0.5 | AM2: 0.51041667 | AN2: 0.52083333 | AO2: 0.53125 | AP2: 0.54166667 | AQ2: 0.55208333 | AR2: 0.5625 | AS2: 0.57291667 | AT2: 0.58333333 | AU2: 0.59375 | AV2: 0.60416667 | AW2: 0.61458333 | AX2: 0.625 | AY2: 0.63541667 | AZ2: 0.64583333 | BA2: 0.65625 | BB2: 0.66666667 | BC2: 0.67708333 | BD2: 0.6875 | BE2: 0.69791667 | BF2: 0.70833333 | BG2: 0.71875 | BH2: 0.72916667 | BI2: 0.73958333 | BJ2: 0.75 | BK2: 0.76041667 | BL2: 0.77083333 | BM2: 0.78125 | BN2: 0.79166667 | BO2: 0.80208333 | BP2: 0.8125 | BQ2: 0.82291667 | BR2: 0.83333333 | BS2: 0.84375 | BT2: 0.85416667 | BU2: 0.86458333 | BV2: 0.875 | BW2: 0.88541667 | BX2: 0.89583333 | BY2: 0.90625 | BZ2: 0.91666667 | CA2: 0.92708333 | CB2: 0.9375 | CC2: 0.94791667 | CD2: 0.95833333 | CE2: 0.96875 | CF2: 0.97916667 | CG2: 0.98958333 | CH2: 0 | CI2: 0.010416667 | CJ2: 0.020833333 | CK2: 0.03125
A3: BOARD MEMBERS
A4: Directors | C4: =IF(TRIM($B4)="","",IFERROR(INDEX(People!$A$2:$A$199,MATCH(TRIM($B4),People!$B$2:$B$199,0)),IFERROR(INDEX(Teams!$A$2:$A$9,MATCH(TRIM($B4),Teams!$B$2:$B$9,0)),"?? CHECK NAME")))
C5: =IF(TRIM($B5)="","",IFERROR(INDEX(People!$A$2:$A$199,MATCH(TRIM($B5),People!$B$2:$B$199,0)),IFERROR(INDEX(Teams!$A$2:$A$9,MATCH(TRIM($B5),Teams!$B$2:$B$9,0)),"?? CHECK NAME")))
C6: =IF(TRIM($B6)="","",IFERROR(INDEX(People!$A$2:$A$199,MATCH(TRIM($B6),People!$B$2:$B$199,0)),IFERROR(INDEX(Teams!$A$2:$A$9,MATCH(TRIM($B6),Teams!$B$2:$B$9,0)),"?? CHECK NAME")))
C7: =IF(TRIM($B7)="","",IFERROR(INDEX(People!$A$2:$A$199,MATCH(TRIM($B7),People!$B$2:$B$199,0)),IFERROR(INDEX(Teams!$A$2:$A$9,MATCH(TRIM($B7),Teams!$B$2:$B$9,0)),"?? CHECK NAME")))
C8: =IF(TRIM($B8)="","",IFERROR(INDEX(People!$A$2:$A$199,MATCH(TRIM($B8),People!$B$2:$B$199,0)),IFERROR(INDEX(Teams!$A$2:$A$9,MATCH(TRIM($B8),Teams!$B$2:$B$9,0)),"?? CHECK NAME")))
A9: Senior Advisors | C9: =IF(TRIM($B9)="","",IFERROR(INDEX(People!$A$2:$A$199,MATCH(TRIM($B9),People!$B$2:$B$199,0)),IFERROR(INDEX(Teams!$A$2:$A$9,MATCH(TRIM($B9),Teams!$B$2:$B$9,0)),"?? CHECK NAME")))
C10: =IF(TRIM($B10)="","",IFERROR(INDEX(People!$A$2:$A$199,MATCH(TRIM($B10),People!$B$2:$B$199,0)),IFERROR(INDEX(Teams!$A$2:$A$9,MATCH(TRIM($B10),Teams!$B$2:$B$9,0)),"?? CHECK NAME")))
C11: =IF(TRIM($B11)="","",IFERROR(INDEX(People!$A$2:$A$199,MATCH(TRIM($B11),People!$B$2:$B$199,0)),IFERROR(INDEX(Teams!$A$2:$A$9,MATCH(TRIM($B11),Teams!$B$2:$B$9,0)),"?? CHECK NAME")))
C12: =IF(TRIM($B12)="","",IFERROR(INDEX(People!$A$2:$A$199,MATCH(TRIM($B12),People!$B$2:$B$199,0)),IFERROR(INDEX(Teams!$A$2:$A$9,MATCH(TRIM($B12),Teams!$B$2:$B$9,0)),"?? CHECK NAME")))
C13: =IF(TRIM($B13)="","",IFERROR(INDEX(People!$A$2:$A$199,MATCH(TRIM($B13),People!$B$2:$B$199,0)),IFERROR(INDEX(Teams!$A$2:$A$9,MATCH(TRIM($B13),Teams!$B$2:$B$9,0)),"?? CHECK NAME")))
A14: Logistics | C14: =IF(TRIM($B14)="","",IFERROR(INDEX(People!$A$2:$A$199,MATCH(TRIM($B14),People!$B$2:$B$199,0)),IFERROR(INDEX(Teams!$A$2:$A$9,MATCH(TRIM($B14),Teams!$B$2:$B$9,0)),"?? CHECK NAME")))
C15: =IF(TRIM($B15)="","",IFERROR(INDEX(People!$A$2:$A$199,MATCH(TRIM($B15),People!$B$2:$B$199,0)),IFERROR(INDEX(Teams!$A$2:$A$9,MATCH(TRIM($B15),Teams!$B$2:$B$9,0)),"?? CHECK NAME")))
C16: =IF(TRIM($B16)="","",IFERROR(INDEX(People!$A$2:$A$199,MATCH(TRIM($B16),People!$B$2:$B$199,0)),IFERROR(INDEX(Teams!$A$2:$A$9,MATCH(TRIM($B16),Teams!$B$2:$B$9,0)),"?? CHECK NAME")))
C17: =IF(TRIM($B17)="","",IFERROR(INDEX(People!$A$2:$A$199,MATCH(TRIM($B17),People!$B$2:$B$199,0)),IFERROR(INDEX(Teams!$A$2:$A$9,MATCH(TRIM($B17),Teams!$B$2:$B$9,0)),"?? CHECK NAME")))
C18: =IF(TRIM($B18)="","",IFERROR(INDEX(People!$A$2:$A$199,MATCH(TRIM($B18),People!$B$2:$B$199,0)),IFERROR(INDEX(Teams!$A$2:$A$9,MATCH(TRIM($B18),Teams!$B$2:$B$9,0)),"?? CHECK NAME")))
A19: Hospitality | C19: =IF(TRIM($B19)="","",IFERROR(INDEX(People!$A$2:$A$199,MATCH(TRIM($B19),People!$B$2:$B$199,0)),IFERROR(INDEX(Teams!$A$2:$A$9,MATCH(TRIM($B19),Teams!$B$2:$B$9,0)),"?? CHECK NAME")))
C20: =IF(TRIM($B20)="","",IFERROR(INDEX(People!$A$2:$A$199,MATCH(TRIM($B20),People!$B$2:$B$199,0)),IFERROR(INDEX(Teams!$A$2:$A$9,MATCH(TRIM($B20),Teams!$B$2:$B$9,0)),"?? CHECK NAME")))
C21: =IF(TRIM($B21)="","",IFERROR(INDEX(People!$A$2:$A$199,MATCH(TRIM($B21),People!$B$2:$B$199,0)),IFERROR(INDEX(Teams!$A$2:$A$9,MATCH(TRIM($B21),Teams!$B$2:$B$9,0)),"?? CHECK NAME")))
C22: =IF(TRIM($B22)="","",IFERROR(INDEX(People!$A$2:$A$199,MATCH(TRIM($B22),People!$B$2:$B$199,0)),IFERROR(INDEX(Teams!$A$2:$A$9,MATCH(TRIM($B22),Teams!$B$2:$B$9,0)),"?? CHECK NAME")))
C23: =IF(TRIM($B23)="","",IFERROR(INDEX(People!$A$2:$A$199,MATCH(TRIM($B23),People!$B$2:$B$199,0)),IFERROR(INDEX(Teams!$A$2:$A$9,MATCH(TRIM($B23),Teams!$B$2:$B$9,0)),"?? CHECK NAME")))
A24: Creative | C24: =IF(TRIM($B24)="","",IFERROR(INDEX(People!$A$2:$A$199,MATCH(TRIM($B24),People!$B$2:$B$199,0)),IFERROR(INDEX(Teams!$A$2:$A$9,MATCH(TRIM($B24),Teams!$B$2:$B$9,0)),"?? CHECK NAME")))
C25: =IF(TRIM($B25)="","",IFERROR(INDEX(People!$A$2:$A$199,MATCH(TRIM($B25),People!$B$2:$B$199,0)),IFERROR(INDEX(Teams!$A$2:$A$9,MATCH(TRIM($B25),Teams!$B$2:$B$9,0)),"?? CHECK NAME")))
C26: =IF(TRIM($B26)="","",IFERROR(INDEX(People!$A$2:$A$199,MATCH(TRIM($B26),People!$B$2:$B$199,0)),IFERROR(INDEX(Teams!$A$2:$A$9,MATCH(TRIM($B26),Teams!$B$2:$B$9,0)),"?? CHECK NAME")))
C27: =IF(TRIM($B27)="","",IFERROR(INDEX(People!$A$2:$A$199,MATCH(TRIM($B27),People!$B$2:$B$199,0)),IFERROR(INDEX(Teams!$A$2:$A$9,MATCH(TRIM($B27),Teams!$B$2:$B$9,0)),"?? CHECK NAME")))
C28: =IF(TRIM($B28)="","",IFERROR(INDEX(People!$A$2:$A$199,MATCH(TRIM($B28),People!$B$2:$B$199,0)),IFERROR(INDEX(Teams!$A$2:$A$9,MATCH(TRIM($B28),Teams!$B$2:$B$9,0)),"?? CHECK NAME")))
A29: Registration | C29: =IF(TRIM($B29)="","",IFERROR(INDEX(People!$A$2:$A$199,MATCH(TRIM($B29),People!$B$2:$B$199,0)),IFERROR(INDEX(Teams!$A$2:$A$9,MATCH(TRIM($B29),Teams!$B$2:$B$9,0)),"?? CHECK NAME")))
C30: =IF(TRIM($B30)="","",IFERROR(INDEX(People!$A$2:$A$199,MATCH(TRIM($B30),People!$B$2:$B$199,0)),IFERROR(INDEX(Teams!$A$2:$A$9,MATCH(TRIM($B30),Teams!$B$2:$B$9,0)),"?? CHECK NAME")))
C31: =IF(TRIM($B31)="","",IFERROR(INDEX(People!$A$2:$A$199,MATCH(TRIM($B31),People!$B$2:$B$199,0)),IFERROR(INDEX(Teams!$A$2:$A$9,MATCH(TRIM($B31),Teams!$B$2:$B$9,0)),"?? CHECK NAME")))
C32: =IF(TRIM($B32)="","",IFERROR(INDEX(People!$A$2:$A$199,MATCH(TRIM($B32),People!$B$2:$B$199,0)),IFERROR(INDEX(Teams!$A$2:$A$9,MATCH(TRIM($B32),Teams!$B$2:$B$9,0)),"?? CHECK NAME")))
C33: =IF(TRIM($B33)="","",IFERROR(INDEX(People!$A$2:$A$199,MATCH(TRIM($B33),People!$B$2:$B$199,0)),IFERROR(INDEX(Teams!$A$2:$A$9,MATCH(TRIM($B33),Teams!$B$2:$B$9,0)),"?? CHECK NAME")))
A34: Head Liaisons | C34: =IF(TRIM($B34)="","",IFERROR(INDEX(People!$A$2:$A$199,MATCH(TRIM($B34),People!$B$2:$B$199,0)),IFERROR(INDEX(Teams!$A$2:$A$9,MATCH(TRIM($B34),Teams!$B$2:$B$9,0)),"?? CHECK NAME")))
C35: =IF(TRIM($B35)="","",IFERROR(INDEX(People!$A$2:$A$199,MATCH(TRIM($B35),People!$B$2:$B$199,0)),IFERROR(INDEX(Teams!$A$2:$A$9,MATCH(TRIM($B35),Teams!$B$2:$B$9,0)),"?? CHECK NAME")))
C36: =IF(TRIM($B36)="","",IFERROR(INDEX(People!$A$2:$A$199,MATCH(TRIM($B36),People!$B$2:$B$199,0)),IFERROR(INDEX(Teams!$A$2:$A$9,MATCH(TRIM($B36),Teams!$B$2:$B$9,0)),"?? CHECK NAME")))
C37: =IF(TRIM($B37)="","",IFERROR(INDEX(People!$A$2:$A$199,MATCH(TRIM($B37),People!$B$2:$B$199,0)),IFERROR(INDEX(Teams!$A$2:$A$9,MATCH(TRIM($B37),Teams!$B$2:$B$9,0)),"?? CHECK NAME")))
C38: =IF(TRIM($B38)="","",IFERROR(INDEX(People!$A$2:$A$199,MATCH(TRIM($B38),People!$B$2:$B$199,0)),IFERROR(INDEX(Teams!$A$2:$A$9,MATCH(TRIM($B38),Teams!$B$2:$B$9,0)),"?? CHECK NAME")))
A39: PR | C39: =IF(TRIM($B39)="","",IFERROR(INDEX(People!$A$2:$A$199,MATCH(TRIM($B39),People!$B$2:$B$199,0)),IFERROR(INDEX(Teams!$A$2:$A$9,MATCH(TRIM($B39),Teams!$B$2:$B$9,0)),"?? CHECK NAME")))
C40: =IF(TRIM($B40)="","",IFERROR(INDEX(People!$A$2:$A$199,MATCH(TRIM($B40),People!$B$2:$B$199,0)),IFERROR(INDEX(Teams!$A$2:$A$9,MATCH(TRIM($B40),Teams!$B$2:$B$9,0)),"?? CHECK NAME")))
...

Sheet Sunday
A1: Group | B1: Name | C1: ID | D1: =Instructions!$C$14+2
D2: 0.125 | E2: 0.13541667 | F2: 0.14583333 | G2: 0.15625 | H2: 0.16666667 | I2: 0.17708333 | J2: 0.1875 | K2: 0.19791667 | L2: 0.20833333 | M2: 0.21875 | N2: 0.22916667 | O2: 0.23958333 | P2: 0.25 | Q2: 0.26041667 | R2: 0.27083333 | S2: 0.28125 | T2: 0.29166667 | U2: 0.30208333 | V2: 0.3125 | W2: 0.32291667 | X2: 0.33333333 | Y2: 0.34375 | Z2: 0.35416667 | AA2: 0.36458333 | AB2: 0.375 | AC2: 0.38541667 | AD2: 0.39583333 | AE2: 0.40625 | AF2: 0.41666667 | AG2: 0.42708333 | AH2: 0.4375 | AI2: 0.44791667 | AJ2: 0.45833333 | AK2: 0.46875 | AL2: 0.47916667 | AM2: 0.48958333 | AN2: 0.5 | AO2: 0.51041667 | AP2: 0.52083333 | AQ2: 0.53125 | AR2: 0.54166667 | AS2: 0.55208333 | AT2: 0.5625 | AU2: 0.57291667 | AV2: 0.58333333 | AW2: 0.59375 | AX2: 0.60416667 | AY2: 0.61458333 | AZ2: 0.625 | BA2: 0.63541667 | BB2: 0.64583333 | BC2: 0.65625 | BD2: 0.66666667 | BE2: 0.67708333 | BF2: 0.6875 | BG2: 0.69791667 | BH2: 0.70833333 | BI2: 0.71875 | BJ2: 0.72916667 | BK2: 0.73958333 | BL2: 0.75 | BM2: 0.76041667 | BN2: 0.77083333 | BO2: 0.78125 | BP2: 0.79166667 | BQ2: 0.80208333 | BR2: 0.8125 | BS2: 0.82291667 | BT2: 0.83333333 | BU2: 0.84375 | BV2: 0.85416667 | BW2: 0.86458333
A3: BOARD MEMBERS
A4: Directors | C4: =IF(TRIM($B4)="","",IFERROR(INDEX(People!$A$2:$A$199,MATCH(TRIM($B4),People!$B$2:$B$199,0)),IFERROR(INDEX(Teams!$A$2:$A$9,MATCH(TRIM($B4),Teams!$B$2:$B$9,0)),"?? CHECK NAME")))
C5: =IF(TRIM($B5)="","",IFERROR(INDEX(People!$A$2:$A$199,MATCH(TRIM($B5),People!$B$2:$B$199,0)),IFERROR(INDEX(Teams!$A$2:$A$9,MATCH(TRIM($B5),Teams!$B$2:$B$9,0)),"?? CHECK NAME")))
C6: =IF(TRIM($B6)="","",IFERROR(INDEX(People!$A$2:$A$199,MATCH(TRIM($B6),People!$B$2:$B$199,0)),IFERROR(INDEX(Teams!$A$2:$A$9,MATCH(TRIM($B6),Teams!$B$2:$B$9,0)),"?? CHECK NAME")))
C7: =IF(TRIM($B7)="","",IFERROR(INDEX(People!$A$2:$A$199,MATCH(TRIM($B7),People!$B$2:$B$199,0)),IFERROR(INDEX(Teams!$A$2:$A$9,MATCH(TRIM($B7),Teams!$B$2:$B$9,0)),"?? CHECK NAME")))
C8: =IF(TRIM($B8)="","",IFERROR(INDEX(People!$A$2:$A$199,MATCH(TRIM($B8),People!$B$2:$B$199,0)),IFERROR(INDEX(Teams!$A$2:$A$9,MATCH(TRIM($B8),Teams!$B$2:$B$9,0)),"?? CHECK NAME")))
A9: Senior Advisors | C9: =IF(TRIM($B9)="","",IFERROR(INDEX(People!$A$2:$A$199,MATCH(TRIM($B9),People!$B$2:$B$199,0)),IFERROR(INDEX(Teams!$A$2:$A$9,MATCH(TRIM($B9),Teams!$B$2:$B$9,0)),"?? CHECK NAME")))
C10: =IF(TRIM($B10)="","",IFERROR(INDEX(People!$A$2:$A$199,MATCH(TRIM($B10),People!$B$2:$B$199,0)),IFERROR(INDEX(Teams!$A$2:$A$9,MATCH(TRIM($B10),Teams!$B$2:$B$9,0)),"?? CHECK NAME")))
C11: =IF(TRIM($B11)="","",IFERROR(INDEX(People!$A$2:$A$199,MATCH(TRIM($B11),People!$B$2:$B$199,0)),IFERROR(INDEX(Teams!$A$2:$A$9,MATCH(TRIM($B11),Teams!$B$2:$B$9,0)),"?? CHECK NAME")))
C12: =IF(TRIM($B12)="","",IFERROR(INDEX(People!$A$2:$A$199,MATCH(TRIM($B12),People!$B$2:$B$199,0)),IFERROR(INDEX(Teams!$A$2:$A$9,MATCH(TRIM($B12),Teams!$B$2:$B$9,0)),"?? CHECK NAME")))
C13: =IF(TRIM($B13)="","",IFERROR(INDEX(People!$A$2:$A$199,MATCH(TRIM($B13),People!$B$2:$B$199,0)),IFERROR(INDEX(Teams!$A$2:$A$9,MATCH(TRIM($B13),Teams!$B$2:$B$9,0)),"?? CHECK NAME")))
A14: Logistics | C14: =IF(TRIM($B14)="","",IFERROR(INDEX(People!$A$2:$A$199,MATCH(TRIM($B14),People!$B$2:$B$199,0)),IFERROR(INDEX(Teams!$A$2:$A$9,MATCH(TRIM($B14),Teams!$B$2:$B$9,0)),"?? CHECK NAME")))
C15: =IF(TRIM($B15)="","",IFERROR(INDEX(People!$A$2:$A$199,MATCH(TRIM($B15),People!$B$2:$B$199,0)),IFERROR(INDEX(Teams!$A$2:$A$9,MATCH(TRIM($B15),Teams!$B$2:$B$9,0)),"?? CHECK NAME")))
C16: =IF(TRIM($B16)="","",IFERROR(INDEX(People!$A$2:$A$199,MATCH(TRIM($B16),People!$B$2:$B$199,0)),IFERROR(INDEX(Teams!$A$2:$A$9,MATCH(TRIM($B16),Teams!$B$2:$B$9,0)),"?? CHECK NAME")))
C17: =IF(TRIM($B17)="","",IFERROR(INDEX(People!$A$2:$A$199,MATCH(TRIM($B17),People!$B$2:$B$199,0)),IFERROR(INDEX(Teams!$A$2:$A$9,MATCH(TRIM($B17),Teams!$B$2:$B$9,0)),"?? CHECK NAME")))
C18: =IF(TRIM($B18)="","",IFERROR(INDEX(People!$A$2:$A$199,MATCH(TRIM($B18),People!$B$2:$B$199,0)),IFERROR(INDEX(Teams!$A$2:$A$9,MATCH(TRIM($B18),Teams!$B$2:$B$9,0)),"?? CHECK NAME")))
A19: Hospitality | C19: =IF(TRIM($B19)="","",IFERROR(INDEX(People!$A$2:$A$199,MATCH(TRIM($B19),People!$B$2:$B$199,0)),IFERROR(INDEX(Teams!$A$2:$A$9,MATCH(TRIM($B19),Teams!$B$2:$B$9,0)),"?? CHECK NAME")))
C20: =IF(TRIM($B20)="","",IFERROR(INDEX(People!$A$2:$A$199,MATCH(TRIM($B20),People!$B$2:$B$199,0)),IFERROR(INDEX(Teams!$A$2:$A$9,MATCH(TRIM($B20),Teams!$B$2:$B$9,0)),"?? CHECK NAME")))
C21: =IF(TRIM($B21)="","",IFERROR(INDEX(People!$A$2:$A$199,MATCH(TRIM($B21),People!$B$2:$B$199,0)),IFERROR(INDEX(Teams!$A$2:$A$9,MATCH(TRIM($B21),Teams!$B$2:$B$9,0)),"?? CHECK NAME")))
C22: =IF(TRIM($B22)="","",IFERROR(INDEX(People!$A$2:$A$199,MATCH(TRIM($B22),People!$B$2:$B$199,0)),IFERROR(INDEX(Teams!$A$2:$A$9,MATCH(TRIM($B22),Teams!$B$2:$B$9,0)),"?? CHECK NAME")))
C23: =IF(TRIM($B23)="","",IFERROR(INDEX(People!$A$2:$A$199,MATCH(TRIM($B23),People!$B$2:$B$199,0)),IFERROR(INDEX(Teams!$A$2:$A$9,MATCH(TRIM($B23),Teams!$B$2:$B$9,0)),"?? CHECK NAME")))
A24: Creative | C24: =IF(TRIM($B24)="","",IFERROR(INDEX(People!$A$2:$A$199,MATCH(TRIM($B24),People!$B$2:$B$199,0)),IFERROR(INDEX(Teams!$A$2:$A$9,MATCH(TRIM($B24),Teams!$B$2:$B$9,0)),"?? CHECK NAME")))
C25: =IF(TRIM($B25)="","",IFERROR(INDEX(People!$A$2:$A$199,MATCH(TRIM($B25),People!$B$2:$B$199,0)),IFERROR(INDEX(Teams!$A$2:$A$9,MATCH(TRIM($B25),Teams!$B$2:$B$9,0)),"?? CHECK NAME")))
C26: =IF(TRIM($B26)="","",IFERROR(INDEX(People!$A$2:$A$199,MATCH(TRIM($B26),People!$B$2:$B$199,0)),IFERROR(INDEX(Teams!$A$2:$A$9,MATCH(TRIM($B26),Teams!$B$2:$B$9,0)),"?? CHECK NAME")))
C27: =IF(TRIM($B27)="","",IFERROR(INDEX(People!$A$2:$A$199,MATCH(TRIM($B27),People!$B$2:$B$199,0)),IFERROR(INDEX(Teams!$A$2:$A$9,MATCH(TRIM($B27),Teams!$B$2:$B$9,0)),"?? CHECK NAME")))
C28: =IF(TRIM($B28)="","",IFERROR(INDEX(People!$A$2:$A$199,MATCH(TRIM($B28),People!$B$2:$B$199,0)),IFERROR(INDEX(Teams!$A$2:$A$9,MATCH(TRIM($B28),Teams!$B$2:$B$9,0)),"?? CHECK NAME")))
A29: Registration | C29: =IF(TRIM($B29)="","",IFERROR(INDEX(People!$A$2:$A$199,MATCH(TRIM($B29),People!$B$2:$B$199,0)),IFERROR(INDEX(Teams!$A$2:$A$9,MATCH(TRIM($B29),Teams!$B$2:$B$9,0)),"?? CHECK NAME")))
C30: =IF(TRIM($B30)="","",IFERROR(INDEX(People!$A$2:$A$199,MATCH(TRIM($B30),People!$B$2:$B$199,0)),IFERROR(INDEX(Teams!$A$2:$A$9,MATCH(TRIM($B30),Teams!$B$2:$B$9,0)),"?? CHECK NAME")))
C31: =IF(TRIM($B31)="","",IFERROR(INDEX(People!$A$2:$A$199,MATCH(TRIM($B31),People!$B$2:$B$199,0)),IFERROR(INDEX(Teams!$A$2:$A$9,MATCH(TRIM($B31),Teams!$B$2:$B$9,0)),"?? CHECK NAME")))
C32: =IF(TRIM($B32)="","",IFERROR(INDEX(People!$A$2:$A$199,MATCH(TRIM($B32),People!$B$2:$B$199,0)),IFERROR(INDEX(Teams!$A$2:$A$9,MATCH(TRIM($B32),Teams!$B$2:$B$9,0)),"?? CHECK NAME")))
C33: =IF(TRIM($B33)="","",IFERROR(INDEX(People!$A$2:$A$199,MATCH(TRIM($B33),People!$B$2:$B$199,0)),IFERROR(INDEX(Teams!$A$2:$A$9,MATCH(TRIM($B33),Teams!$B$2:$B$9,0)),"?? CHECK NAME")))
A34: Head Liaisons | C34: =IF(TRIM($B34)="","",IFERROR(INDEX(People!$A$2:$A$199,MATCH(TRIM($B34),People!$B$2:$B$199,0)),IFERROR(INDEX(Teams!$A$2:$A$9,MATCH(TRIM($B34),Teams!$B$2:$B$9,0)),"?? CHECK NAME")))
C35: =IF(TRIM($B35)="","",IFERROR(INDEX(People!$A$2:$A$199,MATCH(TRIM($B35),People!$B$2:$B$199,0)),IFERROR(INDEX(Teams!$A$2:$A$9,MATCH(TRIM($B35),Teams!$B$2:$B$9,0)),"?? CHECK NAME")))
C36: =IF(TRIM($B36)="","",IFERROR(INDEX(People!$A$2:$A$199,MATCH(TRIM($B36),People!$B$2:$B$199,0)),IFERROR(INDEX(Teams!$A$2:$A$9,MATCH(TRIM($B36),Teams!$B$2:$B$9,0)),"?? CHECK NAME")))
C37: =IF(TRIM($B37)="","",IFERROR(INDEX(People!$A$2:$A$199,MATCH(TRIM($B37),People!$B$2:$B$199,0)),IFERROR(INDEX(Teams!$A$2:$A$9,MATCH(TRIM($B37),Teams!$B$2:$B$9,0)),"?? CHECK NAME")))
C38: =IF(TRIM($B38)="","",IFERROR(INDEX(People!$A$2:$A$199,MATCH(TRIM($B38),People!$B$2:$B$199,0)),IFERROR(INDEX(Teams!$A$2:$A$9,MATCH(TRIM($B38),Teams!$B$2:$B$9,0)),"?? CHECK NAME")))
A39: PR | C39: =IF(TRIM($B39)="","",IFERROR(INDEX(People!$A$2:$A$199,MATCH(TRIM($B39),People!$B$2:$B$199,0)),IFERROR(INDEX(Teams!$A$2:$A$9,MATCH(TRIM($B39),Teams!$B$2:$B$9,0)),"?? CHECK NAME")))
C40: =IF(TRIM($B40)="","",IFERROR(INDEX(People!$A$2:$A$199,MATCH(TRIM($B40),People!$B$2:$B$199,0)),IFERROR(INDEX(Teams!$A$2:$A$9,MATCH(TRIM($B40),Teams!$B$2:$B$9,0)),"?? CHECK NAME")))
...

Sheet Sequences
A1: Sequence | B1: Step | C1: Wait before | D1: Length (min) | E1: Offset (min) | F1: Applies to | G1: Shared space | H1: How many fit | I1: Break? | J1: Ends at (min) | K1: Venue | L1: Sub-location | M1: Day | N1: Offsets measured from…
A2: Saturday Practice | B2: Report to Lobby | C2: 0 | D2: 5 | E2: =IF($B2="","",$C2) | F2: Team + liaisons | J2: =IF($B2="","",$E2+$D2) | K2: Courtyard Marriott | L2: Lobby | M2: Saturday | N2: when that team reports to the hotel lobby
B3: Load Vans | C3: 0 | D3: 10 | E3: =IF($B3="","",$E2+$D2+$C3) | F3: Team + liaisons | J3: =IF($B3="","",$E3+$D3) | K3: Courtyard Marriott | L3: Garage
B4: Leave Hotel | C4: 0 | D4: 20 | E4: =IF($B4="","",$E3+$D3+$C4) | F4: Team + liaisons | J4: =IF($B4="","",$E4+$D4) | K4: In transit
B5: On-Stage Rehearsal | C5: 0 | D5: 20 | E5: =IF($B5="","",$E4+$D4+$C5) | F5: Team + liaisons | G5: AUD STAGE | H5: 1 | J5: =IF($B5="","",$E5+$D5) | K5: IU Auditorium | L5: Stage
B6: Walk to Viewing | C6: 0 | D6: 10 | E6: =IF($B6="","",$E5+$D5+$C6) | F6: Team + liaisons | J6: =IF($B6="","",$E6+$D6) | K6: IU Auditorium
B7: Viewing Room | C7: 0 | D7: 20 | E7: =IF($B7="","",$E6+$D6+$C7) | F7: Team + liaisons | G7: VIEWING ROOM | H7: 1 | J7: =IF($B7="","",$E7+$D7) | K7: IU Auditorium | L7: Viewing Room
B8: Water + Regroup | C8: 0 | D8: 10 | E8: =IF($B8="","",$E7+$D7+$C8) | F8: Team + liaisons | I8: Y | J8: =IF($B8="","",$E8+$D8) | K8: IU Auditorium | L8: Lobby
B9: Walk to Off-Stage | C9: 0 | D9: 15 | E9: =IF($B9="","",$E8+$D8+$C9) | F9: Team + liaisons | J9: =IF($B9="","",$E9+$D9) | K9: In transit | L9: Walking
B10: Off-Stage Rehearsal | C10: 0 | D10: 20 | E10: =IF($B10="","",$E9+$D9+$C10) | F10: Team + liaisons | G10: FIELDHOUSE FLOOR | H10: 1 | J10: =IF($B10="","",$E10+$D10) | K10: Intramural Fieldhouse
B11: Load Vans (return) | C11: 0 | D11: 10 | E11: =IF($B11="","",$E10+$D10+$C11) | F11: Team + liaisons | J11: =IF($B11="","",$E11+$D11) | K11: Intramural Fieldhouse
B12: Leave Fieldhouse | C12: 0 | D12: 15 | E12: =IF($B12="","",$E11+$D11+$C12) | F12: Team + liaisons | J12: =IF($B12="","",$E12+$D12) | K12: In transit
E13: =IF($B13="","",$E12+$D12+$C13) | J13: =IF($B13="","",$E13+$D13)
E14: =IF($B14="","",$E13+$D13+$C14) | J14: =IF($B14="","",$E14+$D14)
E15: =IF($B15="","",$E14+$D14+$C15) | J15: =IF($B15="","",$E15+$D15)
A16: Saturday Photos | B16: Staircase (Team Boomerang) | C16: 0 | D16: 5 | E16: =IF($B16="","",$C16) | F16: Team + liaisons | G16: STAIRCASE | H16: 1 | J16: =IF($B16="","",$E16+$D16) | K16: IU Auditorium | L16: Staircase | M16: Saturday | N16: that team's staircase photo time
B17: Balcony (Team Photo) | C17: 0 | D17: 5 | E17: =IF($B17="","",$E16+$D16+$C17) | F17: Team + liaisons | G17: BALCONY | H17: 1 | J17: =IF($B17="","",$E17+$D17) | K17: IU Auditorium | L17: Balcony
E18: =IF($B18="","",$E17+$D17+$C18) | J18: =IF($B18="","",$E18+$D18)
E19: =IF($B19="","",$E18+$D18+$C19) | J19: =IF($B19="","",$E19+$D19)
E20: =IF($B20="","",$E19+$D19+$C20) | J20: =IF($B20="","",$E20+$D20)
E21: =IF($B21="","",$E20+$D20+$C21) | J21: =IF($B21="","",$E21+$D21)
E22: =IF($B22="","",$E21+$D21+$C22) | J22: =IF($B22="","",$E22+$D22)
E23: =IF($B23="","",$E22+$D22+$C23) | J23: =IF($B23="","",$E23+$D23)
E24: =IF($B24="","",$E23+$D23+$C24) | J24: =IF($B24="","",$E24+$D24)
E25: =IF($B25="","",$E24+$D24+$C25) | J25: =IF($B25="","",$E25+$D25)
E26: =IF($B26="","",$E25+$D25+$C26) | J26: =IF($B26="","",$E26+$D26)
E27: =IF($B27="","",$E26+$D26+$C27) | J27: =IF($B27="","",$E27+$D27)
E28: =IF($B28="","",$E27+$D27+$C28) | J28: =IF($B28="","",$E28+$D28)
E29: =IF($B29="","",$E28+$D28+$C29) | J29: =IF($B29="","",$E29+$D29)
A30: Show Backstage | B30: Collect from Seats | C30: -50 | D30: 5 | E30: =IF($B30="","",$C30) | F30: Team + liaisons | J30: =IF($B30="","",$E30+$D30) | K30: IU Auditorium | L30: House | M30: Saturday | N30: that team's ON STAGE time (negative offsets happen before it)
B31: Walk to Warm-Up | C31: 0 | D31: 5 | E31: =IF($B31="","",$E30+$D30+$C31) | F31: Team + liaisons | J31: =IF($B31="","",$E31+$D31) | K31: IU Auditorium
B32: WARM-UP | C32: 0 | D32: 20 | E32: =IF($B32="","",$E31+$D31+$C32) | F32: Team + liaisons | G32: WARM-UP ROOM | H32: 2 | I32: Y | J32: =IF($B32="","",$E32+$D32) | K32: IU Auditorium | L32: Warm-Up Room
B33: Dressing / Costume | C33: 0 | D33: 10 | E33: =IF($B33="","",$E32+$D32+$C33) | F33: Team + liaisons | G33: DRESSING ROOM | H33: 2 | J33: =IF($B33="","",$E33+$D33) | K33: IU Auditorium | L33: Dressing Room
B34: Pre-Prop | C34: 0 | D34: 10 | E34: =IF($B34="","",$E33+$D33+$C34) | F34: Team + liaisons | G34: PRE-PROP | H34: 2 | J34: =IF($B34="","",$E34+$D34) | K34: IU Auditorium | L34: Pre-Prop
B35: ON STAGE | C35: 0 | D35: 10 | E35: =IF($B35="","",$E34+$D34+$C35) | F35: Team | G35: SHOW STAGE | H35: 1 | J35: =IF($B35="","",$E35+$D35) | K35: IU Auditorium | L35: Stage
B36: Post-Prop to Audience | C36: 0 | D36: 10 | E36: =IF($B36="","",$E35+$D35+$C36) | F36: Team + liaisons | G36: POST-PROP | H36: 2 | J36: =IF($B36="","",$E36+$D36) | K36: IU Auditorium | L36: Post-Prop
E37: =IF($B37="","",$E36+$D36+$C37) | J37: =IF($B37="","",$E37+$D37)
E38: =IF($B38="","",$E37+$D37+$C38) | J38: =IF($B38="","",$E38+$D38)
E39: =IF($B39="","",$E38+$D38+$C39) | J39: =IF($B39="","",$E39+$D39)
E40: =IF($B40="","",$E39+$D39+$C40) | J40: =IF($B40="","",$E40+$D40)
...

Sheet Slot Times
A1: Sequence | B1: Slot | C1: Anchor | D1: Gap before | E1: Float before | F1: Adjust | G1: Real gap | H1: Reference time | I1: Team (from the draw)
A2: Saturday Practice | B2: 1 | C2: 0.30208333 | H2: =IF($C2="","",$C2+$F2/1440) | I2: =IFERROR(INDEX(Teams!$B$2:$B$9,MATCH($B2,Teams!$D$2:$D$9,0)),"(not drawn)")
B3: 2 | D3: 30 | G3: =IF($D3="","",$D3+IF($E3="",0,$E3)) | H3: =IF(OR($H2="",$D3=""),"",$H2+($G3+IF($F3="",0,$F3))/1440) | I3: =IFERROR(INDEX(Teams!$B$2:$B$9,MATCH($B3,Teams!$D$2:$D$9,0)),"(not drawn)")
B4: 3 | D4: 30 | E4: 15 | G4: =IF($D4="","",$D4+IF($E4="",0,$E4)) | H4: =IF(OR($H3="",$D4=""),"",$H3+($G4+IF($F4="",0,$F4))/1440) | I4: =IFERROR(INDEX(Teams!$B$2:$B$9,MATCH($B4,Teams!$D$2:$D$9,0)),"(not drawn)")
B5: 4 | D5: 30 | G5: =IF($D5="","",$D5+IF($E5="",0,$E5)) | H5: =IF(OR($H4="",$D5=""),"",$H4+($G5+IF($F5="",0,$F5))/1440) | I5: =IFERROR(INDEX(Teams!$B$2:$B$9,MATCH($B5,Teams!$D$2:$D$9,0)),"(not drawn)")
B6: 5 | D6: 30 | E6: 25 | G6: =IF($D6="","",$D6+IF($E6="",0,$E6)) | H6: =IF(OR($H5="",$D6=""),"",$H5+($G6+IF($F6="",0,$F6))/1440) | I6: =IFERROR(INDEX(Teams!$B$2:$B$9,MATCH($B6,Teams!$D$2:$D$9,0)),"(not drawn)")
B7: 6 | D7: 30 | G7: =IF($D7="","",$D7+IF($E7="",0,$E7)) | H7: =IF(OR($H6="",$D7=""),"",$H6+($G7+IF($F7="",0,$F7))/1440) | I7: =IFERROR(INDEX(Teams!$B$2:$B$9,MATCH($B7,Teams!$D$2:$D$9,0)),"(not drawn)")
B8: 7 | D8: 30 | E8: 15 | G8: =IF($D8="","",$D8+IF($E8="",0,$E8)) | H8: =IF(OR($H7="",$D8=""),"",$H7+($G8+IF($F8="",0,$F8))/1440) | I8: =IFERROR(INDEX(Teams!$B$2:$B$9,MATCH($B8,Teams!$D$2:$D$9,0)),"(not drawn)")
B9: 8 | D9: 30 | G9: =IF($D9="","",$D9+IF($E9="",0,$E9)) | H9: =IF(OR($H8="",$D9=""),"",$H8+($G9+IF($F9="",0,$F9))/1440) | I9: =IFERROR(INDEX(Teams!$B$2:$B$9,MATCH($B9,Teams!$D$2:$D$9,0)),"(not drawn)")
A10: Saturday Photos | B10: 1 | C10: 0.59375 | H10: =IF($C10="","",$C10+$F10/1440) | I10: =IFERROR(INDEX(Teams!$B$2:$B$9,MATCH($B10,Teams!$D$2:$D$9,0)),"(not drawn)")
B11: 2 | D11: 10 | G11: =IF($D11="","",$D11+IF($E11="",0,$E11)) | H11: =IF(OR($H10="",$D11=""),"",$H10+($G11+IF($F11="",0,$F11))/1440) | I11: =IFERROR(INDEX(Teams!$B$2:$B$9,MATCH($B11,Teams!$D$2:$D$9,0)),"(not drawn)")
B12: 3 | D12: 10 | G12: =IF($D12="","",$D12+IF($E12="",0,$E12)) | H12: =IF(OR($H11="",$D12=""),"",$H11+($G12+IF($F12="",0,$F12))/1440) | I12: =IFERROR(INDEX(Teams!$B$2:$B$9,MATCH($B12,Teams!$D$2:$D$9,0)),"(not drawn)")
B13: 4 | D13: 10 | G13: =IF($D13="","",$D13+IF($E13="",0,$E13)) | H13: =IF(OR($H12="",$D13=""),"",$H12+($G13+IF($F13="",0,$F13))/1440) | I13: =IFERROR(INDEX(Teams!$B$2:$B$9,MATCH($B13,Teams!$D$2:$D$9,0)),"(not drawn)")
B14: 5 | D14: 10 | G14: =IF($D14="","",$D14+IF($E14="",0,$E14)) | H14: =IF(OR($H13="",$D14=""),"",$H13+($G14+IF($F14="",0,$F14))/1440) | I14: =IFERROR(INDEX(Teams!$B$2:$B$9,MATCH($B14,Teams!$D$2:$D$9,0)),"(not drawn)")
B15: 6 | D15: 10 | G15: =IF($D15="","",$D15+IF($E15="",0,$E15)) | H15: =IF(OR($H14="",$D15=""),"",$H14+($G15+IF($F15="",0,$F15))/1440) | I15: =IFERROR(INDEX(Teams!$B$2:$B$9,MATCH($B15,Teams!$D$2:$D$9,0)),"(not drawn)")
B16: 7 | D16: 10 | G16: =IF($D16="","",$D16+IF($E16="",0,$E16)) | H16: =IF(OR($H15="",$D16=""),"",$H15+($G16+IF($F16="",0,$F16))/1440) | I16: =IFERROR(INDEX(Teams!$B$2:$B$9,MATCH($B16,Teams!$D$2:$D$9,0)),"(not drawn)")
B17: 8 | D17: 10 | G17: =IF($D17="","",$D17+IF($E17="",0,$E17)) | H17: =IF(OR($H16="",$D17=""),"",$H16+($G17+IF($F17="",0,$F17))/1440) | I17: =IFERROR(INDEX(Teams!$B$2:$B$9,MATCH($B17,Teams!$D$2:$D$9,0)),"(not drawn)")
A18: Show Backstage | B18: 1 | C18: =Checks!$B$4 | H18: =IF($C18="","",$C18+$F18/1440) | I18: =IFERROR(INDEX(Teams!$B$2:$B$9,MATCH($B18,Teams!$D$2:$D$9,0)),"(not drawn)")
B19: 2 | D19: 10 | G19: =IF($D19="","",$D19+IF($E19="",0,$E19)) | H19: =IF(OR($H18="",$D19=""),"",$H18+($G19+IF($F19="",0,$F19))/1440) | I19: =IFERROR(INDEX(Teams!$B$2:$B$9,MATCH($B19,Teams!$D$2:$D$9,0)),"(not drawn)")
B20: 3 | D20: 10 | G20: =IF($D20="","",$D20+IF($E20="",0,$E20)) | H20: =IF(OR($H19="",$D20=""),"",$H19+($G20+IF($F20="",0,$F20))/1440) | I20: =IFERROR(INDEX(Teams!$B$2:$B$9,MATCH($B20,Teams!$D$2:$D$9,0)),"(not drawn)")
B21: 4 | D21: 10 | G21: =IF($D21="","",$D21+IF($E21="",0,$E21)) | H21: =IF(OR($H20="",$D21=""),"",$H20+($G21+IF($F21="",0,$F21))/1440) | I21: =IFERROR(INDEX(Teams!$B$2:$B$9,MATCH($B21,Teams!$D$2:$D$9,0)),"(not drawn)")
B22: 5 | D22: 10 | E22: 30 | G22: =IF($D22="","",$D22+IF($E22="",0,$E22)) | H22: =IF(OR($H21="",$D22=""),"",$H21+($G22+IF($F22="",0,$F22))/1440) | I22: =IFERROR(INDEX(Teams!$B$2:$B$9,MATCH($B22,Teams!$D$2:$D$9,0)),"(not drawn)")
B23: 6 | D23: 10 | G23: =IF($D23="","",$D23+IF($E23="",0,$E23)) | H23: =IF(OR($H22="",$D23=""),"",$H22+($G23+IF($F23="",0,$F23))/1440) | I23: =IFERROR(INDEX(Teams!$B$2:$B$9,MATCH($B23,Teams!$D$2:$D$9,0)),"(not drawn)")
B24: 7 | D24: 10 | G24: =IF($D24="","",$D24+IF($E24="",0,$E24)) | H24: =IF(OR($H23="",$D24=""),"",$H23+($G24+IF($F24="",0,$F24))/1440) | I24: =IFERROR(INDEX(Teams!$B$2:$B$9,MATCH($B24,Teams!$D$2:$D$9,0)),"(not drawn)")
B25: 8 | D25: 10 | G25: =IF($D25="","",$D25+IF($E25="",0,$E25)) | H25: =IF(OR($H24="",$D25=""),"",$H24+($G25+IF($F25="",0,$F25))/1440) | I25: =IFERROR(INDEX(Teams!$B$2:$B$9,MATCH($B25,Teams!$D$2:$D$9,0)),"(not drawn)")
A27: Gap before is the normal spacing between teams. Float before is DELIBERATE SPARE TIME — it is how the day absorbs a team running long. Do not delete floats to save time; they are the reason a single overrun does not wreck the afternoon.
A28: If the day runs on time, a float just becomes a longer break. Nothing is wasted.
A29: Show Backstage has no typed anchor — it comes from the curtain time on the Checks tab.
A30: RUNNING LATE? Everyone — change the Anchor. One team ran long — raise the Float before the NEXT slot. Only one team — use its Adjust box.

Sheet Vehicles
A1: Slot | B1: Team | C1: Leg | D1: Vehicle | E1: Starts | F1: Ends | G1: Clashes | H1: Too close | I1: Status
A2: 1 | B2: ='Slot Times'!$I$2 | C2: Hotel -> Venue | D2: SUV pair A | E2: =IF('Slot Times'!$H$2="","",'Slot Times'!$H$2+Sequences!$E$4/1440) | F2: =IF($E2="","",$E2+Sequences!$D$4/1440) | G2: =SUMPRODUCT(($D$2:$D$17=$D2)*($E$2:$E$17<$F2)*($F$2:$F$17>$E2))-1 | H2: =SUMPRODUCT(($D$2:$D$17=$D2)*($E$2:$E$17<$F2+Checks!$B$6/1440)*($F$2:$F$17>$E2))-1 | I2: =IF($G2>0,"CLASH",IF($H2>0,"TIGHT","OK"))
A3: 2 | B3: ='Slot Times'!$I$3 | C3: Hotel -> Venue | D3: SUV pair B | E3: =IF('Slot Times'!$H$3="","",'Slot Times'!$H$3+Sequences!$E$4/1440) | F3: =IF($E3="","",$E3+Sequences!$D$4/1440) | G3: =SUMPRODUCT(($D$2:$D$17=$D3)*($E$2:$E$17<$F3)*($F$2:$F$17>$E3))-1 | H3: =SUMPRODUCT(($D$2:$D$17=$D3)*($E$2:$E$17<$F3+Checks!$B$6/1440)*($F$2:$F$17>$E3))-1 | I3: =IF($G3>0,"CLASH",IF($H3>0,"TIGHT","OK"))
A4: 3 | B4: ='Slot Times'!$I$4 | C4: Hotel -> Venue | D4: SUV pair A | E4: =IF('Slot Times'!$H$4="","",'Slot Times'!$H$4+Sequences!$E$4/1440) | F4: =IF($E4="","",$E4+Sequences!$D$4/1440) | G4: =SUMPRODUCT(($D$2:$D$17=$D4)*($E$2:$E$17<$F4)*($F$2:$F$17>$E4))-1 | H4: =SUMPRODUCT(($D$2:$D$17=$D4)*($E$2:$E$17<$F4+Checks!$B$6/1440)*($F$2:$F$17>$E4))-1 | I4: =IF($G4>0,"CLASH",IF($H4>0,"TIGHT","OK"))
A5: 4 | B5: ='Slot Times'!$I$5 | C5: Hotel -> Venue | D5: SUV pair B | E5: =IF('Slot Times'!$H$5="","",'Slot Times'!$H$5+Sequences!$E$4/1440) | F5: =IF($E5="","",$E5+Sequences!$D$4/1440) | G5: =SUMPRODUCT(($D$2:$D$17=$D5)*($E$2:$E$17<$F5)*($F$2:$F$17>$E5))-1 | H5: =SUMPRODUCT(($D$2:$D$17=$D5)*($E$2:$E$17<$F5+Checks!$B$6/1440)*($F$2:$F$17>$E5))-1 | I5: =IF($G5>0,"CLASH",IF($H5>0,"TIGHT","OK"))
A6: 5 | B6: ='Slot Times'!$I$6 | C6: Hotel -> Venue | D6: SUV pair A | E6: =IF('Slot Times'!$H$6="","",'Slot Times'!$H$6+Sequences!$E$4/1440) | F6: =IF($E6="","",$E6+Sequences!$D$4/1440) | G6: =SUMPRODUCT(($D$2:$D$17=$D6)*($E$2:$E$17<$F6)*($F$2:$F$17>$E6))-1 | H6: =SUMPRODUCT(($D$2:$D$17=$D6)*($E$2:$E$17<$F6+Checks!$B$6/1440)*($F$2:$F$17>$E6))-1 | I6: =IF($G6>0,"CLASH",IF($H6>0,"TIGHT","OK"))
A7: 6 | B7: ='Slot Times'!$I$7 | C7: Hotel -> Venue | D7: SUV pair B | E7: =IF('Slot Times'!$H$7="","",'Slot Times'!$H$7+Sequences!$E$4/1440) | F7: =IF($E7="","",$E7+Sequences!$D$4/1440) | G7: =SUMPRODUCT(($D$2:$D$17=$D7)*($E$2:$E$17<$F7)*($F$2:$F$17>$E7))-1 | H7: =SUMPRODUCT(($D$2:$D$17=$D7)*($E$2:$E$17<$F7+Checks!$B$6/1440)*($F$2:$F$17>$E7))-1 | I7: =IF($G7>0,"CLASH",IF($H7>0,"TIGHT","OK"))
A8: 7 | B8: ='Slot Times'!$I$8 | C8: Hotel -> Venue | D8: SUV pair A | E8: =IF('Slot Times'!$H$8="","",'Slot Times'!$H$8+Sequences!$E$4/1440) | F8: =IF($E8="","",$E8+Sequences!$D$4/1440) | G8: =SUMPRODUCT(($D$2:$D$17=$D8)*($E$2:$E$17<$F8)*($F$2:$F$17>$E8))-1 | H8: =SUMPRODUCT(($D$2:$D$17=$D8)*($E$2:$E$17<$F8+Checks!$B$6/1440)*($F$2:$F$17>$E8))-1 | I8: =IF($G8>0,"CLASH",IF($H8>0,"TIGHT","OK"))
A9: 8 | B9: ='Slot Times'!$I$9 | C9: Hotel -> Venue | D9: SUV pair B | E9: =IF('Slot Times'!$H$9="","",'Slot Times'!$H$9+Sequences!$E$4/1440) | F9: =IF($E9="","",$E9+Sequences!$D$4/1440) | G9: =SUMPRODUCT(($D$2:$D$17=$D9)*($E$2:$E$17<$F9)*($F$2:$F$17>$E9))-1 | H9: =SUMPRODUCT(($D$2:$D$17=$D9)*($E$2:$E$17<$F9+Checks!$B$6/1440)*($F$2:$F$17>$E9))-1 | I9: =IF($G9>0,"CLASH",IF($H9>0,"TIGHT","OK"))
A10: 1 | B10: ='Slot Times'!$I$2 | C10: Fieldhouse -> Hotel | D10: =$D$2 | E10: =IF('Slot Times'!$H$2="","",'Slot Times'!$H$2+Sequences!$E$12/1440) | F10: =IF($E10="","",$E10+Sequences!$D$12/1440) | G10: =SUMPRODUCT(($D$2:$D$17=$D10)*($E$2:$E$17<$F10)*($F$2:$F$17>$E10))-1 | H10: =SUMPRODUCT(($D$2:$D$17=$D10)*($E$2:$E$17<$F10+Checks!$B$6/1440)*($F$2:$F$17>$E10))-1 | I10: =IF($G10>0,"CLASH",IF($H10>0,"TIGHT","OK"))
A11: 2 | B11: ='Slot Times'!$I$3 | C11: Fieldhouse -> Hotel | D11: =$D$3 | E11: =IF('Slot Times'!$H$3="","",'Slot Times'!$H$3+Sequences!$E$12/1440) | F11: =IF($E11="","",$E11+Sequences!$D$12/1440) | G11: =SUMPRODUCT(($D$2:$D$17=$D11)*($E$2:$E$17<$F11)*($F$2:$F$17>$E11))-1 | H11: =SUMPRODUCT(($D$2:$D$17=$D11)*($E$2:$E$17<$F11+Checks!$B$6/1440)*($F$2:$F$17>$E11))-1 | I11: =IF($G11>0,"CLASH",IF($H11>0,"TIGHT","OK"))
A12: 3 | B12: ='Slot Times'!$I$4 | C12: Fieldhouse -> Hotel | D12: =$D$4 | E12: =IF('Slot Times'!$H$4="","",'Slot Times'!$H$4+Sequences!$E$12/1440) | F12: =IF($E12="","",$E12+Sequences!$D$12/1440) | G12: =SUMPRODUCT(($D$2:$D$17=$D12)*($E$2:$E$17<$F12)*($F$2:$F$17>$E12))-1 | H12: =SUMPRODUCT(($D$2:$D$17=$D12)*($E$2:$E$17<$F12+Checks!$B$6/1440)*($F$2:$F$17>$E12))-1 | I12: =IF($G12>0,"CLASH",IF($H12>0,"TIGHT","OK"))
A13: 4 | B13: ='Slot Times'!$I$5 | C13: Fieldhouse -> Hotel | D13: =$D$5 | E13: =IF('Slot Times'!$H$5="","",'Slot Times'!$H$5+Sequences!$E$12/1440) | F13: =IF($E13="","",$E13+Sequences!$D$12/1440) | G13: =SUMPRODUCT(($D$2:$D$17=$D13)*($E$2:$E$17<$F13)*($F$2:$F$17>$E13))-1 | H13: =SUMPRODUCT(($D$2:$D$17=$D13)*($E$2:$E$17<$F13+Checks!$B$6/1440)*($F$2:$F$17>$E13))-1 | I13: =IF($G13>0,"CLASH",IF($H13>0,"TIGHT","OK"))
A14: 5 | B14: ='Slot Times'!$I$6 | C14: Fieldhouse -> Hotel | D14: =$D$6 | E14: =IF('Slot Times'!$H$6="","",'Slot Times'!$H$6+Sequences!$E$12/1440) | F14: =IF($E14="","",$E14+Sequences!$D$12/1440) | G14: =SUMPRODUCT(($D$2:$D$17=$D14)*($E$2:$E$17<$F14)*($F$2:$F$17>$E14))-1 | H14: =SUMPRODUCT(($D$2:$D$17=$D14)*($E$2:$E$17<$F14+Checks!$B$6/1440)*($F$2:$F$17>$E14))-1 | I14: =IF($G14>0,"CLASH",IF($H14>0,"TIGHT","OK"))
A15: 6 | B15: ='Slot Times'!$I$7 | C15: Fieldhouse -> Hotel | D15: =$D$7 | E15: =IF('Slot Times'!$H$7="","",'Slot Times'!$H$7+Sequences!$E$12/1440) | F15: =IF($E15="","",$E15+Sequences!$D$12/1440) | G15: =SUMPRODUCT(($D$2:$D$17=$D15)*($E$2:$E$17<$F15)*($F$2:$F$17>$E15))-1 | H15: =SUMPRODUCT(($D$2:$D$17=$D15)*($E$2:$E$17<$F15+Checks!$B$6/1440)*($F$2:$F$17>$E15))-1 | I15: =IF($G15>0,"CLASH",IF($H15>0,"TIGHT","OK"))
A16: 7 | B16: ='Slot Times'!$I$8 | C16: Fieldhouse -> Hotel | D16: =$D$8 | E16: =IF('Slot Times'!$H$8="","",'Slot Times'!$H$8+Sequences!$E$12/1440) | F16: =IF($E16="","",$E16+Sequences!$D$12/1440) | G16: =SUMPRODUCT(($D$2:$D$17=$D16)*($E$2:$E$17<$F16)*($F$2:$F$17>$E16))-1 | H16: =SUMPRODUCT(($D$2:$D$17=$D16)*($E$2:$E$17<$F16+Checks!$B$6/1440)*($F$2:$F$17>$E16))-1 | I16: =IF($G16>0,"CLASH",IF($H16>0,"TIGHT","OK"))
A17: 8 | B17: ='Slot Times'!$I$9 | C17: Fieldhouse -> Hotel | D17: =$D$9 | E17: =IF('Slot Times'!$H$9="","",'Slot Times'!$H$9+Sequences!$E$12/1440) | F17: =IF($E17="","",$E17+Sequences!$D$12/1440) | G17: =SUMPRODUCT(($D$2:$D$17=$D17)*($E$2:$E$17<$F17)*($F$2:$F$17>$E17))-1 | H17: =SUMPRODUCT(($D$2:$D$17=$D17)*($E$2:$E$17<$F17+Checks!$B$6/1440)*($F$2:$F$17>$E17))-1 | I17: =IF($G17>0,"CLASH",IF($H17>0,"TIGHT","OK"))
A19: Two rows per team — the run out and the run back. A van drops a team and is free again; it is not tied up all morning.
A20: Type the vehicle on the outbound row. The return row follows it unless you change it.
A21: CLASH means that vehicle is booked to be in two places at once. TIGHT means it makes it, but with less than the turnaround you set on Checks.
A22: A late van delays a team that did nothing wrong. Keep these green.

Sheet Windows
A1: Day | B1: Window | C1: Assigned Team/Person | D1: Opens | E1: Closes | F1: Venue | G1: Sub-location | H1: Notes
A2: Saturday | B2: Breakfast | C2: Role: Dancer | D2: 0.25 | E2: 0.41666667 | F2: Courtyard Marriott | G2: Breakfast Room | H2: Grab-and-go from 6:00 for the early slots
A3: Saturday | B3: Lunch | C3: Role: Dancer | D3: 0.45833333 | E3: 0.625 | F3: Courtyard Marriott | G3: Lobby | H3: Eat when your team gets back from practice
A4: Saturday | B4: Pre-show snack | C4: Role: Dancer | D4: 0.64583333 | E4: 0.6875 | F4: IU Auditorium | G4: Green Room | H4: Light only. You are in costume
A5: Saturday | B5: Post-show food | C5: Role: Dancer | D5: 0.85416667 | E5: 0.91666667 | F5: Courtyard Marriott | G5: Lobby
A6: Friday | B6: Dinner | C6: Role: Dancer | D6: 0.66666667 | E6: 0.70833333 | F6: Monroe Convention Center | H6: Pizza — eat at your convenience
